Workbook

Sheet Links
A1: Helpdesk: | B1: https://adapthealthhelpdesk.freshservice.com/support/tickets/
B2: https://hbos.freshdesk.com/support/tickets/new
A3: Dashboard | B3: Performance Dashboard (Revised) (google.com)

Sheet SLA
A1: Count of Days Grouping | B1: Column Labels | N1: 45547 | R1: WORKFLOW | S1: RPH | T1: Hrts | U1: Days to Work | V1: FTE | X1: SLA
A2: Row Labels | B2: 3 or less | C2: 4 to 7 | D2: 7 to 10 | E2: 11 to 14 | F2: 15 to 21 | G2: 22 to 30 | H2: 31 to 60 | I2: 61 to 90 | J2: 91 to 120 | K2: 121 to 180 | L2: 181 plus | M2: Grand Total | R2: DCAH | S2: 15 | T2: 1284 | U2: 2 | V2: 80 | X2: 0.61
A3: Audit Only | B3: 4 | C3: 25 | D3: 5 | E3: 24 | F3: 9 | M3: 67 | N3: 0.4328 | R3: PCAH | S3: 15 | T3: 1021 | U3: 4 | V3: 32 | X3: 0.44
A4: Benefit Verification | B4: 7 | M4: 7 | N4: 1 | R4: Confirmed Sales | S4: 20 | T4: 41 | U4: 1 | V4: 5 | X4: 1
A5: Doctor Call | B5: 11 | C5: 6 | E5: 1 | M5: 18 | N5: 0.9444 | R5: Edocument | S5: 17 | T5: 315 | U5: 2 | V5: 20 | X5: 1
A6: Doctor Denied | B6: 1547 | C6: 1604 | D6: 196 | E6: 348 | F6: 304 | G6: 482 | H6: 976 | I6: 701 | J6: 824 | K6: 470 | L6: 1 | M6: 7453 | N6: 0.4228 | R6: Edocument Exceptions List | S6: 17 | T6: 176 | U6: 2 | V6: 11 | X6: 0.946
A7: Doctor Research | B7: 135 | M7: 135 | N7: 1 | R7: Inbound Call | S7: 10 | T7: 0 | X7: 1% Abandoned Rate
A8: Fax Research | B8: 96 | M8: 96 | N8: 1 | R8: DCAH Scrubs | S8: 20 | T8: 25 | U8: 5 | V8: 1 | W8: 1447 | X8: 1
A9: Patient Follow Up Call | B9: 1776 | C9: 636 | D9: 620 | E9: 242 | F9: 378 | G9: 467 | H9: 824 | I9: 554 | J9: 591 | K9: 375 | M9: 6463 | N9: 0.3732 | R9: ARM/FTP | S9: 25 | T9: 145 | U9: 1 | V9: 18 | X9: 0.93
A10: Rework | B10: 213 | C10: 34 | D10: 9 | E10: 1 | F10: 7 | M10: 264 | N10: 0.9356 | R10: VSA | S10: 10 | T10: 20 | U10: 5 | V10: 1 | X10: 1
A11: Rx Chase | B11: 7060 | C11: 3115 | D11: 3065 | E11: 3913 | F11: 5276 | G11: 2592 | H11: 85 | I11: 23 | J11: 13 | K11: 34 | M11: 25176 | N11: 0.4042 | R11: Benver | S11: 25 | T11: 1 | U11: 5 | V11: 0 | X11: 1
A12: Grand Total | B12: 10849 | C12: 5420 | D12: 3895 | E12: 4529 | F12: 5974 | G12: 3541 | H12: 1885 | I12: 1278 | J12: 1428 | K12: 879 | L12: 1 | M12: 39679 | N12: 0.41 | R12: Rework | S12: 15 | T12: 23 | U12: 5 | V12: 1 | X12: 0.94
R13: Aging 180 days | S13: 6 | T13: 27 | U13: 1 | V13: 3 | X13: Friday
R14: Aging 30 days | S14: 15 | T14: 80 | U14: 1 | V14: 10 | X14: Friday
R15: UHC Special Project | S15: 12 | T15: 167 | U15: 3 | V15: 7 | X15: 0.4
A16: Count of Days Grouping | B16: Column Labels | N16: 45547.208 | R16: CDT review | S16: 12 | T16: 0 | U16: 5 | V16: 1 | W16: 93 | X16: 0.73
A17: Row Labels | B17: 3 or less | C17: 4 to 7 | D17: 7 to 10 | E17: 11 to 14 | F17: 15 to 21 | G17: 22 to 30 | H17: 31 to 60 | I17: 61 to 90 | J17: 91 to 120 | K17: 121 to 180 | L17: 181 plus | M17: Grand Total | R17: FaxRes | T17: 160 | U17: 5 | V17: 4 | X17: 1
A18: Audit Only | B18: 4 | C18: 25 | D18: 5 | E18: 24 | F18: 9 | M18: 67 | N18: 0.4328 | R18: DocRes | T18: 40 | U18: 5 | V18: 1 | X18: 1
A19: Benefit Verification | B19: 14 | M19: 14 | N19: 1 | R19: DocMatch | T19: 40 | U19: 5 | V19: 1 | X19: 1
A20: Doctor Call | B20: 9 | C20: 4 | E20: 1 | M20: 14 | N20: 0.9286 | R20: FaxMap | T20: 160 | U20: 5 | V20: 4 | X20: 1 | Y20: AH DIAB pending
A21: Doctor Denied | B21: 1586 | C21: 1608 | D21: 196 | E21: 348 | F21: 304 | G21: 483 | H21: 976 | I21: 701 | J21: 824 | K21: 468 | L21: 1 | M21: 7495 | N21: 0.4262 | R21: FaxReview | T21: 40 | U21: 5 | V21: 1 | X21: 1
A22: Doctor Research | B22: 132 | M22: 132 | N22: 1 | R22: Email/VM Response | T22: 20 | U22: 5 | V22: 0.5
A23: Fax Research | B23: 89 | M23: 89 | N23: 1 | R23: Blank Held | S23: 10 | T23: 39 | U23: 5 | V23: 1 | X23: 1
A24: Patient Follow Up Call | B24: 1853 | C24: 637 | D24: 620 | E24: 243 | F24: 379 | G24: 466 | H24: 824 | I24: 553 | J24: 591 | K24: 374 | M24: 6540 | N24: 0.3807 | R24: VA MCD | S24: 6 | T24: 89 | U24: 1 | V24: 11 | X24: 1
A25: Rework | B25: 220 | C25: 34 | D25: 9 | E25: 1 | F25: 7 | M25: 271 | N25: 0.9373 | R25: TriCare | S25: 20 | T25: 250 | U25: 22 | V25: 1 | X25: 0.6252
A26: Rx Chase | B26: 7362 | C26: 2900 | D26: 2874 | E26: 3480 | F26: 5134 | G26: 2523 | H26: 84 | I26: 25 | J26: 14 | K26: 45 | M26: 24441 | N26: 0.4199 | R26: AtRisk | S26: 20 | T26: 50 | U26: 1 | V26: 6 | X26: Friday
A27: Grand Total | B27: 11269 | C27: 5208 | D27: 3704 | E27: 4097 | F27: 5833 | G27: 3472 | H27: 1884 | I27: 1279 | J27: 1429 | K27: 887 | L27: 1 | M27: 39063 | N27: 0.4218 | R27: Age Resting Orders Review | S27: 15 | T27: 40 | U27: 1 | V27: 5 | X27: 1
A29: Count of Days Grouping | C29: Days Grouping | O29: 45548 | R29: WKS16
A30: Status | B30: SubStatus | C30: 3 or less | D30: 4 to 7 | E30: 7 to 10 | F30: 11 to 14 | G30: 15 to 21 | H30: 22 to 30 | I30: 31 to 60 | J30: 61 to 90 | K30: 91 to 120 | L30: 121 to 180 | M30: 181 plus | N30: Grand Total | O30: SLA | R30: WORKFLOW | S30: RPH | T30: Hrts | U30: Days to Work | V30: FTE | X30: SLA
A31: Audit Only | D31: 29 | E31: 4 | F31: 25 | G31: 9 | N31: 67 | O31: 0 | R31: DCAH | S31: 15 | T31: 1284 | U31: 2 | V31: 80 | X31: 0.57
A32: Benefit Verification | B32: - | C32: 1 | N32: 1 | O32: 1 | R32: PCAH | S32: 15 | T32: 1021 | U32: 4 | V32: 32 | X32: 0.44
A33: Doctor Research | C33: 184 | N33: 184 | O33: 1 | R33: Confirmed Sales | S33: 20 | T33: 41 | U33: 1 | V33: 5 | X33: 1
A34: Fax Research | C34: 5 | N34: 5 | O34: 1 | R34: Edocument | S34: 17 | T34: 315 | U34: 2 | V34: 20 | X34: 0.95
A35: Doctor Call | C35: 5 | N35: 5 | O35: 1 | R35: Edocument Exceptions List | S35: 17 | T35: 176 | U35: 2 | V35: 11
A36: Doctor Denied | C36: 1116 | D36: 1366 | E36: 955 | F36: 330 | G36: 317 | H36: 447 | I36: 1059 | J36: 669 | K36: 839 | L36: 485 | M36: 1 | N36: 7584 | O36: 0.33 | R36: Inbound Call | S36: 10 | T36: 0
A37: Patient Follow Up Call | C37: 1412 | D37: 915 | E37: 869 | F37: 216 | G37: 375 | H37: 473 | I37: 872 | J37: 533 | K37: 595 | L37: 389 | N37: 6649 | O37: 0.35 | R37: DCAH Scrubs | S37: 20 | T37: 25 | U37: 5 | V37: 1 | W37: 1447
A38: Rework | C38: 184 | D38: 74 | E38: 14 | F38: 2 | G38: 7 | H38: 1 | N38: 282 | O38: 0.91 | R38: ARM/FTP | S38: 25 | T38: 145 | U38: 1 | V38: 18 | X38: 0.77
A39: Rx Chase | B39: - | C39: 319 | D39: 109 | E39: 31 | F39: 106 | G39: 263 | H39: 107 | I39: 19 | N39: 954 | O39: 0.45 | R39: VSA | S39: 10 | T39: 20 | U39: 5 | V39: 1 | X39: 1
B40: Call First | C40: 34 | D40: 2 | E40: 3 | F40: 1 | G40: 2 | H40: 4 | N40: 46 | O40: 0.78 | R40: Benver | S40: 25 | T40: 1 | U40: 5 | V40: 0 | X40: 1
B41: EDocument | C41: 800 | D41: 446 | E41: 83 | F41: 8 | G41: 12 | H41: 7 | I41: 1 | N41: 1357 | O41: 0.92 | R41: Rework | S41: 15 | T41: 23 | U41: 5 | V41: 1
...

Sheet reference
A1: KIm to update the assigned HC right after the planning call
A2: Weng to update the number of completes and actual RPH and actual log in hours
A6: Callshaper campaign | B6: CDP Team | C6: WORKFLOW | D6: Camp+Team | E6: PPH/RPH
A7: AH-AeroHeld-Aging-Prod | C7: Aging | D7: =_xlfn.TEXTJOIN("",TRUE,A7,B7) -> AH-AeroHeld-Aging-Prod | E7: RPH
A8: AH-SnapHeld-Aging-Prod | C8: Aging | D8: =_xlfn.TEXTJOIN("",TRUE,A8,B8) -> AH-SnapHeld-Aging-Prod | E8: RPH
A9: AH-AeroHeld-ARM-Prod | B9: AH-SnapHeld-FTP-Prod | C9: ARM | D9: =_xlfn.TEXTJOIN("",TRUE,A9,B9) -> AH-AeroHeld-ARM-ProdAH-SnapHeld-FTP-Prod | E9: RPH
A10: AH-SnapHeld-ARM-Prod | B10: AH-AeroHeld-FTP-Prod | C10: ARM | D10: =_xlfn.TEXTJOIN("",TRUE,A10,B10) -> AH-SnapHeld-ARM-ProdAH-AeroHeld-FTP-Prod | E10: RPH
A11: AH-AeroHeld-ARM-Prod | B11: AH-SnapHeld-Benver-Prod | C11: BenVer | D11: =_xlfn.TEXTJOIN("",TRUE,A11,B11) -> AH-AeroHeld-ARM-ProdAH-SnapHeld-Benver-Prod | E11: RPH
A12: AH-SnapHeld-ARM-Prod | B12: AH-AeroHeld-Benver-Prod | C12: BenVer | D12: =_xlfn.TEXTJOIN("",TRUE,A12,B12) -> AH-SnapHeld-ARM-ProdAH-AeroHeld-Benver-Prod | E12: RPH
A13: AH-SnapHeld-Special Project - Billable | B13: HBOSS BT Project-Blank Held | C13: Blank Held | D13: =_xlfn.TEXTJOIN("",TRUE,A13,B13) -> AH-SnapHeld-Special Project - BillableHBOSS BT Project-Blank Held | E13: RPH
A14: AH-AeroHeld-Fax Map-Prod | B14: CDT,AddDoctor,GS Escal | C14: CDT Review | D14: =_xlfn.TEXTJOIN("",TRUE,A14,B14) -> AH-AeroHeld-Fax Map-ProdCDT,AddDoctor,GS Escal | E14: PPH
A15: AH-SnapHeld-Special Project - NonBillable | B15: AH-SnapHeld-CS-Prod | C15: Confirmed Sales | D15: =_xlfn.TEXTJOIN("",TRUE,A15,B15) -> AH-SnapHeld-Special Project - NonBillableAH-SnapHeld-CS-Prod | E15: RPH
A16: AH-AeroHeld-Special Project - Billable | B16: AH-AeroHeld-CS-Prod | C16: Confirmed Sales | D16: =_xlfn.TEXTJOIN("",TRUE,A16,B16) -> AH-AeroHeld-Special Project - BillableAH-AeroHeld-CS-Prod | E16: RPH
A17: AH-SnapHeld-CommSurgDCAH-Prod | C17: DCAH | D17: =_xlfn.TEXTJOIN("",TRUE,A17,B17) -> AH-SnapHeld-CommSurgDCAH-Prod | E17: RPH
A18: AH-SnapHeld-DCAH-Prod | C18: DCAH | D18: =_xlfn.TEXTJOIN("",TRUE,A18,B18) -> AH-SnapHeld-DCAH-Prod | E18: RPH
A19: AH-AEROHeld-DCAH-Prod | C19: DCAH | D19: =_xlfn.TEXTJOIN("",TRUE,A19,B19) -> AH-AEROHeld-DCAH-Prod | E19: RPH
A20: AH-SnapHeld-DCScrubs-Prod | C20: DCAH Scrubs | D20: =_xlfn.TEXTJOIN("",TRUE,A20,B20) -> AH-SnapHeld-DCScrubs-Prod | E20: RPH
A21: AH-AEROHeld-DCScrubs-Prod | C21: DCAH Scrubs | D21: =_xlfn.TEXTJOIN("",TRUE,A21,B21) -> AH-AEROHeld-DCScrubs-Prod | E21: RPH
A22: HBOSS Portal Fax Mapping | B22: AH-SnapHeld-DM-Prod | C22: Doctor Match | D22: =_xlfn.TEXTJOIN("",TRUE,A22,B22) -> HBOSS Portal Fax MappingAH-SnapHeld-DM-Prod | E22: PPH
A23: AH-AeroHeld-Fax Map-Prod | B23: AH-AeroHeld-DM-Prod | C23: Doctor Match | D23: =_xlfn.TEXTJOIN("",TRUE,A23,B23) -> AH-AeroHeld-Fax Map-ProdAH-AeroHeld-DM-Prod | E23: PPH
A24: HBOSS Portal Doctor Research | C24: Doctor Research | D24: =_xlfn.TEXTJOIN("",TRUE,A24,B24) -> HBOSS Portal Doctor Research | E24: PPH
A25: AH-AeroHeld-DocRes-Prod | C25: Doctor Research | D25: =_xlfn.TEXTJOIN("",TRUE,A25,B25) -> AH-AeroHeld-DocRes-Prod | E25: RPH
A26: AH-SnapHeld-Edocument-Prod | C26: Edocument | D26: =_xlfn.TEXTJOIN("",TRUE,A26,B26) -> AH-SnapHeld-Edocument-Prod | E26: RPH
A27: AH-AeroHeld-Edocument-Prod | C27: Edocument | D27: =_xlfn.TEXTJOIN("",TRUE,A27,B27) -> AH-AeroHeld-Edocument-Prod | E27: RPH
A28: HBOSS Portal Fax Mapping | B28: AH-SNAPHELD-FM-PROD | C28: Fax Mapping | D28: =_xlfn.TEXTJOIN("",TRUE,A28,B28) -> HBOSS Portal Fax MappingAH-SNAPHELD-FM-PROD | E28: PPH
A29: HBOSS Portal Fax Mapping | B29: Diab FM | C29: Fax Mapping | D29: =_xlfn.TEXTJOIN("",TRUE,A29,B29) -> HBOSS Portal Fax MappingDiab FM | E29: PPH
A30: HBOSS Portal Fax Mapping | B30: AH DiabeticHeld-FaxMap-prod | C30: Fax Mapping | D30: =_xlfn.TEXTJOIN("",TRUE,A30,B30) -> HBOSS Portal Fax MappingAH DiabeticHeld-FaxMap-prod | E30: PPH
A31: AH-AeroHeld-Fax Map-Prod | B31: AH-AeroHeld-FM-Prod | C31: Fax Mapping | D31: =_xlfn.TEXTJOIN("",TRUE,A31,B31) -> AH-AeroHeld-Fax Map-ProdAH-AeroHeld-FM-Prod | E31: PPH
A32: HBOSS Portal Fax Research | B32: AH-SnapHeld-FaxRes-Prod | C32: Fax Research | D32: =_xlfn.TEXTJOIN("",TRUE,A32,B32) -> HBOSS Portal Fax ResearchAH-SnapHeld-FaxRes-Prod | E32: PPH
A33: HBOSS Portal Fax Mapping | B33: AH-SnapHeld-FaxRev-Prod | C33: Fax Review | D33: =_xlfn.TEXTJOIN("",TRUE,A33,B33) -> HBOSS Portal Fax MappingAH-SnapHeld-FaxRev-Prod | E33: PPH
A34: AH-SnapHeld-Special Project - Billable | B34: HBOSS BT Project-No Mask Revie | C34: No Mask | D34: =_xlfn.TEXTJOIN("",TRUE,A34,B34) -> AH-SnapHeld-Special Project - BillableHBOSS BT Project-No Mask Revie | E34: RPH
A35: AH-SnapHeld-PTCall-Prod | C35: PCAH | D35: =_xlfn.TEXTJOIN("",TRUE,A35,B35) -> AH-SnapHeld-PTCall-Prod | E35: RPH
A36: AH-AeroHeld-PTCall-Prod | C36: PCAH | D36: =_xlfn.TEXTJOIN("",TRUE,A36,B36) -> AH-AeroHeld-PTCall-Prod | E36: RPH
A37: AH-SnapHeld-CommSurgRewrk-Prod | C37: Rework | D37: =_xlfn.TEXTJOIN("",TRUE,A37,B37) -> AH-SnapHeld-CommSurgRewrk-Prod | E37: RPH
A38: AH-SnapHeld-Rework-Prod | C38: Rework | D38: =_xlfn.TEXTJOIN("",TRUE,A38,B38) -> AH-SnapHeld-Rework-Prod | E38: RPH
A39: AH-AeroHeld-Rework-Prod | C39: Rework | D39: =_xlfn.TEXTJOIN("",TRUE,A39,B39) -> AH-AeroHeld-Rework-Prod | E39: RPH
A40: AH-SnapHeld-Special Project - Billable | B40: Tricare East RX Review | C40: Tricare East RX Review | D40: =_xlfn.TEXTJOIN("",TRUE,A40,B40) -> AH-SnapHeld-Special Project - BillableTricare East RX Review | E40: RPH
A41: AH-SnapHeld-Special Project - Billable | B41: HBOSS BT Project - UHC | C41: UHC Special Project | D41: =_xlfn.TEXTJOIN("",TRUE,A41,B41) -> AH-SnapHeld-Special Project - BillableHBOSS BT Project - UHC | E41: RPH
A42: AH-SnapHeld-Special Project - Billable | B42: VA MEDICAID HELD | C42: VA Medicaid | D42: =_xlfn.TEXTJOIN("",TRUE,A42,B42) -> AH-SnapHeld-Special Project - BillableVA MEDICAID HELD | E42: RPH
A43: AH-SnapHeld-VSA-Prod | C43: VSA | D43: =_xlfn.TEXTJOIN("",TRUE,A43,B43) -> AH-SnapHeld-VSA-Prod | E43: RPH
...

Sheet Team Report
A1: Team | B1: Agent | C1: Agent Email | D1: Calls | E1: Calls/Hr | F1: Talk | G1: Wrap Up | H1: Conv | I1: Conv % | J1: Conv/Hr | K1: Points | L1: Points/Hr | M1: Logged In | N1: Eff % | O1: AAT | P1: AHT | Q1: ATT | R1: AWT | S1: Administrative | T1: Break | U1: Coaching | V1: Unavailable | W1: QA Score | X1: Scorecards | Y1: Passed | Z1: Auto Fails | AA1: Holds | AB1: Hold | AC1: Hold/Call | AD1: Rings Tot | AE1: Rings Ans | AF1: Rings Decl | AG1: Rings Timeout | AH1: Rings Miss | AI1: Rings Aban | AJ1: Site | AK1: AgentName | AL1: Campaign2 | AM1: Camp+Team | AN1: Workflow
A2: AH DiabeticHeld-FaxMap-prod | B2: BCD Jeshurun Corpus | C2: jeshurun.corpus@company.com | D2: 9 | E2: 2.7761498 | F2: 0.0336 | G2: 0.012777778 | H2: 9 | I2: 1 | J2: 2.7761498 | K2: 89 | L2: 27.453037 | M2: 3.2419 | N2: 0.010364293 | O2: 21:11 | P2: 0:18 | Q2: 0:13 | R2: 0:05 | S2: 0:00 | T2: 0:00 | U2: 0:00 | V2: 0:00 | W2: 0 | X2: 0 | Y2: 0 | Z2: 0 | AA2: 0 | AB2: 0:00 | AC2: 0:00 | AD2: 0 | AE2: 0 | AF2: 0 | AG2: 0 | AH2: 0 | AI2: 0 | AJ2: =LEFT(B2,3) -> BCD | AK2: =TRIM(RIGHT(B2, LEN(B2)-3)) -> Jeshurun Corpus | AL2: =_xlfn.XLOOKUP(Team_Report[[#This Row],[Team]],reference!B:B,reference!A:A) -> HBOSS Portal Fax Mapping | AM2: =_xlfn.CONCAT(AL2,A2) -> HBOSS Portal Fax MappingAH DiabeticHeld-FaxMap-prod | AN2: =IFERROR(_xlfn.XLOOKUP(Team_Report[[#This Row],[Camp+Team]],reference!D:D,reference!C:C),"") -> Fax Mapping
A3: AH DiabeticHeld-FaxMap-prod | B3: BCD Gabrielle Angela Alcala | C3: gabrielle.alcala@company.com | D3: 6 | E3: 1.508599 | F3: 0.0336 | G3: 0.075 | H3: 6 | I3: 1 | J3: 1.508599 | K3: 57 | L3: 14.331691 | M3: 3.9772 | N3: 0.0084481545 | O3: 38:31 | P3: 1:05 | Q3: 0:20 | R3: 0:45 | S3: 0:00 | T3: 0:00 | U3: 0:00 | V3: 0:00 | W3: 0 | X3: 0 | Y3: 0 | Z3: 0 | AA3: 0 | AB3: 0:00 | AC3: 0:00 | AD3: 0 | AE3: 0 | AF3: 0 | AG3: 0 | AH3: 0 | AI3: 0 | AJ3: =LEFT(B3,3) -> BCD | AK3: =TRIM(RIGHT(B3, LEN(B3)-3)) -> Gabrielle Angela Alcala | AL3: =_xlfn.XLOOKUP(Team_Report[[#This Row],[Team]],reference!B:B,reference!A:A) -> HBOSS Portal Fax Mapping | AM3: =_xlfn.CONCAT(AL3,A3) -> HBOSS Portal Fax MappingAH DiabeticHeld-FaxMap-prod | AN3: =IFERROR(_xlfn.XLOOKUP(Team_Report[[#This Row],[Camp+Team]],reference!D:D,reference!C:C),"") -> Fax Mapping
A4: AH DiabeticHeld-FaxMap-prod | B4: BCD Julius Canasares | C4: julius.canasares@company.com | D4: 2 | E4: 0.65359477 | F4: 0.0031 | G4: 0.010833333 | H4: 2 | I4: 1 | J4: 0.65359477 | K4: 19 | L4: 6.2091503 | M4: 3.06 | N4: 0.0010130719 | O4: 70:57 | P4: 0:25 | Q4: 0:05 | R4: 0:19 | S4: 0:00 | T4: 0:04 | U4: 0:00 | V4: 0:00 | W4: 0 | X4: 0 | Y4: 0 | Z4: 0 | AA4: 0 | AB4: 0:00 | AC4: 0:00 | AD4: 0 | AE4: 0 | AF4: 0 | AG4: 0 | AH4: 0 | AI4: 0 | AJ4: =LEFT(B4,3) -> BCD | AK4: =TRIM(RIGHT(B4, LEN(B4)-3)) -> Julius Canasares | AL4: =_xlfn.XLOOKUP(Team_Report[[#This Row],[Team]],reference!B:B,reference!A:A) -> HBOSS Portal Fax Mapping | AM4: =_xlfn.CONCAT(AL4,A4) -> HBOSS Portal Fax MappingAH DiabeticHeld-FaxMap-prod | AN4: =IFERROR(_xlfn.XLOOKUP(Team_Report[[#This Row],[Camp+Team]],reference!D:D,reference!C:C),"") -> Fax Mapping
A5: AH DiabeticHeld-FaxMap-prod | B5: BCD Maria Amalia Endrinal | C5: maria.endrinal@company.com | D5: 7 | E5: 2.1116139 | F5: 0.0247 | G5: 0.011666667 | H5: 7 | I5: 1 | J5: 2.1116139 | K5: 36 | L5: 10.859729 | M5: 3.315 | N5: 0.0074509804 | O5: 27:58 | P5: 0:18 | Q5: 0:12 | R5: 0:06 | S5: 0:00 | T5: 36:04 | U5: 0:00 | V5: 0:00 | W5: 0 | X5: 0 | Y5: 0 | Z5: 0 | AA5: 0 | AB5: 0:00 | AC5: 0:00 | AD5: 0 | AE5: 0 | AF5: 0 | AG5: 0 | AH5: 0 | AI5: 0 | AJ5: =LEFT(B5,3) -> BCD | AK5: =TRIM(RIGHT(B5, LEN(B5)-3)) -> Maria Amalia Endrinal | AL5: =_xlfn.XLOOKUP(Team_Report[[#This Row],[Team]],reference!B:B,reference!A:A) -> HBOSS Portal Fax Mapping | AM5: =_xlfn.CONCAT(AL5,A5) -> HBOSS Portal Fax MappingAH DiabeticHeld-FaxMap-prod | AN5: =IFERROR(_xlfn.XLOOKUP(Team_Report[[#This Row],[Camp+Team]],reference!D:D,reference!C:C),"") -> Fax Mapping
A6: AH DiabeticHeld-FaxMap-prod | B6: BTG Jairo Enriquez | C6: jairo.enriquez@company.com | D6: 0 | E6: 0 | F6: 0 | G6: 0 | H6: 0 | I6: 0 | J6: 0 | K6: 0 | L6: 0 | M6: 1.7894 | N6: 0 | O6: 0:00 | P6: 0:00 | Q6: 0:00 | R6: 0:00 | S6: 0:00 | T6: 0:00 | U6: 0:00 | V6: 0:00 | W6: 0 | X6: 0 | Y6: 0 | Z6: 0 | AA6: 0 | AB6: 0:00 | AC6: 0:00 | AD6: 0 | AE6: 0 | AF6: 0 | AG6: 0 | AH6: 0 | AI6: 0 | AJ6: =LEFT(B6,3) -> BTG | AK6: =TRIM(RIGHT(B6, LEN(B6)-3)) -> Jairo Enriquez | AL6: =_xlfn.XLOOKUP(Team_Report[[#This Row],[Team]],reference!B:B,reference!A:A) -> HBOSS Portal Fax Mapping | AM6: =_xlfn.CONCAT(AL6,A6) -> HBOSS Portal Fax MappingAH DiabeticHeld-FaxMap-prod | AN6: =IFERROR(_xlfn.XLOOKUP(Team_Report[[#This Row],[Camp+Team]],reference!D:D,reference!C:C),"") -> Fax Mapping
A7: AH DiabeticHeld-FaxMap-prod | B7: BTG Aldrin Toledo | C7: aldrin.toledo@company.com | D7: 4 | E7: 2.3860654 | F7: 0.0231 | G7: 0.0072222222 | H7: 4 | I7: 1 | J7: 2.3860654 | K7: 4 | L7: 2.3860654 | M7: 1.6764 | N7: 0.013779528 | O7: 24:27 | P7: 0:27 | Q7: 0:20 | R7: 0:06 | S7: 0:00 | T7: 0:00 | U7: 0:00 | V7: 0:00 | W7: 0 | X7: 0 | Y7: 0 | Z7: 0 | AA7: 0 | AB7: 0:00 | AC7: 0:00 | AD7: 0 | AE7: 0 | AF7: 0 | AG7: 0 | AH7: 0 | AI7: 0 | AJ7: =LEFT(B7,3) -> BTG | AK7: =TRIM(RIGHT(B7, LEN(B7)-3)) -> Aldrin Toledo | AL7: =_xlfn.XLOOKUP(Team_Report[[#This Row],[Team]],reference!B:B,reference!A:A) -> HBOSS Portal Fax Mapping | AM7: =_xlfn.CONCAT(AL7,A7) -> HBOSS Portal Fax MappingAH DiabeticHeld-FaxMap-prod | AN7: =IFERROR(_xlfn.XLOOKUP(Team_Report[[#This Row],[Camp+Team]],reference!D:D,reference!C:C),"") -> Fax Mapping
A8: AH DiabeticHeld-FaxMap-prod | B8: BTG Bemilyn Vinas | C8: bemilyn.vinas@company.com | D8: 1 | E8: 0.58630394 | F8: 0.0158 | G8: 0.0013888889 | H8: 1 | I8: 1 | J8: 0.58630394 | K8: 5 | L8: 2.9315197 | M8: 1.7056 | N8: 0.0092636023 | O8: 100:34 | P8: 1:02 | Q8: 0:57 | R8: 0:05 | S8: 0:00 | T8: 0:00 | U8: 0:00 | V8: 0:00 | W8: 0 | X8: 0 | Y8: 0 | Z8: 0 | AA8: 0 | AB8: 0:00 | AC8: 0:00 | AD8: 0 | AE8: 0 | AF8: 0 | AG8: 0 | AH8: 0 | AI8: 0 | AJ8: =LEFT(B8,3) -> BTG | AK8: =TRIM(RIGHT(B8, LEN(B8)-3)) -> Bemilyn Vinas | AL8: =_xlfn.XLOOKUP(Team_Report[[#This Row],[Team]],reference!B:B,reference!A:A) -> HBOSS Portal Fax Mapping | AM8: =_xlfn.CONCAT(AL8,A8) -> HBOSS Portal Fax MappingAH DiabeticHeld-FaxMap-prod | AN8: =IFERROR(_xlfn.XLOOKUP(Team_Report[[#This Row],[Camp+Team]],reference!D:D,reference!C:C),"") -> Fax Mapping
A9: AH DiabeticHeld-FaxMap-prod | B9: BTG Darwin Llanto | C9: darwin.llanto@company.com | D9: 1 | E9: 0.58699225 | F9: 0.0303 | G9: 0.0022222222 | H9: 1 | I9: 1 | J9: 0.58699225 | K9: 10 | L9: 5.8699225 | M9: 1.7036 | N9: 0.017785865 | O9: 99:43 | P9: 1:57 | Q9: 1:49 | R9: 0:08 | S9: 0:00 | T9: 0:00 | U9: 0:00 | V9: 0:00 | W9: 0 | X9: 0 | Y9: 0 | Z9: 0 | AA9: 0 | AB9: 0:00 | AC9: 0:00 | AD9: 0 | AE9: 0 | AF9: 0 | AG9: 0 | AH9: 0 | AI9: 0 | AJ9: =LEFT(B9,3) -> BTG | AK9: =TRIM(RIGHT(B9, LEN(B9)-3)) -> Darwin Llanto | AL9: =_xlfn.XLOOKUP(Team_Report[[#This Row],[Team]],reference!B:B,reference!A:A) -> HBOSS Portal Fax Mapping | AM9: =_xlfn.CONCAT(AL9,A9) -> HBOSS Portal Fax MappingAH DiabeticHeld-FaxMap-prod | AN9: =IFERROR(_xlfn.XLOOKUP(Team_Report[[#This Row],[Camp+Team]],reference!D:D,reference!C:C),"") -> Fax Mapping
A10: AH DiabeticHeld-FaxMap-prod | B10: BTG Daryl Baque | C10: daryl.baque@company.com | D10: 2 | E10: 2.7262814 | F10: 0.0236 | G10: 0.0027777778 | H10: 2 | I10: 1 | J10: 2.7262814 | K10: 10 | L10: 13.631407 | M10: 0.7336 | N10: 0.03217012 | O10: 21:06 | P10: 0:47 | Q10: 0:42 | R10: 0:05 | S10: 0:00 | T10: 0:00 | U10: 0:00 | V10: 0:00 | W10: 0 | X10: 0 | Y10: 0 | Z10: 0 | AA10: 0 | AB10: 0:00 | AC10: 0:00 | AD10: 0 | AE10: 0 | AF10: 0 | AG10: 0 | AH10: 0 | AI10: 0 | AJ10: =LEFT(B10,3) -> BTG | AK10: =TRIM(RIGHT(B10, LEN(B10)-3)) -> Daryl Baque | AL10: =_xlfn.XLOOKUP(Team_Report[[#This Row],[Team]],reference!B:B,reference!A:A) -> HBOSS Portal Fax Mapping | AM10: =_xlfn.CONCAT(AL10,A10) -> HBOSS Portal Fax MappingAH DiabeticHeld-FaxMap-prod | AN10: =IFERROR(_xlfn.XLOOKUP(Team_Report[[#This Row],[Camp+Team]],reference!D:D,reference!C:C),"") -> Fax Mapping
A11: AH DiabeticHeld-FaxMap-prod | B11: BTG Edgardo Pasahol | C11: edgardo.pasahol@company.com | D11: 5 | E11: 3.0010203 | F11: 0.0369 | G11: 0.0030555556 | H11: 5 | I11: 1 | J11: 3.0010203 | K11: 5 | L11: 3.0010203 | M11: 1.6661 | N11: 0.02214753 | O11: 19:19 | P11: 0:28 | Q11: 0:26 | R11: 0:02 | S11: 0:00 | T11: 0:00 | U11: 0:00 | V11: 0:00 | W11: 0 | X11: 0 | Y11: 0 | Z11: 0 | AA11: 0 | AB11: 0:00 | AC11: 0:00 | AD11: 0 | AE11: 0 | AF11: 0 | AG11: 0 | AH11: 0 | AI11: 0 | AJ11: =LEFT(B11,3) -> BTG | AK11: =TRIM(RIGHT(B11, LEN(B11)-3)) -> Edgardo Pasahol | AL11: =_xlfn.XLOOKUP(Team_Report[[#This Row],[Team]],reference!B:B,reference!A:A) -> HBOSS Portal Fax Mapping | AM11: =_xlfn.CONCAT(AL11,A11) -> HBOSS Portal Fax MappingAH DiabeticHeld-FaxMap-prod | AN11: =IFERROR(_xlfn.XLOOKUP(Team_Report[[#This Row],[Camp+Team]],reference!D:D,reference!C:C),"") -> Fax Mapping
A12: AH DiabeticHeld-FaxMap-prod | B12: BTG Faith Larissa Montablan | C12: faith.montablan@company.com | D12: 7 | E12: 5.9813723 | F12: 0.0833 | G12: 0.0058333333 | H12: 7 | I12: 1 | J12: 5.9813723 | K12: 7 | L12: 5.9813723 | M12: 1.1703 | N12: 0.07117833 | O12: 9:04 | P12: 0:45 | Q12: 0:42 | R12: 0:03 | S12: 0:00 | T12: 0:52 | U12: 0:00 | V12: 0:00 | W12: 0 | X12: 0 | Y12: 0 | Z12: 0 | AA12: 0 | AB12: 0:00 | AC12: 0:00 | AD12: 0 | AE12: 0 | AF12: 0 | AG12: 0 | AH12: 0 | AI12: 0 | AJ12: =LEFT(B12,3) -> BTG | AK12: =TRIM(RIGHT(B12, LEN(B12)-3)) -> Faith Larissa Montablan | AL12: =_xlfn.XLOOKUP(Team_Report[[#This Row],[Team]],reference!B:B,reference!A:A) -> HBOSS Portal Fax Mapping | AM12: =_xlfn.CONCAT(AL12,A12) -> HBOSS Portal Fax MappingAH DiabeticHeld-FaxMap-prod | AN12: =IFERROR(_xlfn.XLOOKUP(Team_Report[[#This Row],[Camp+Team]],reference!D:D,reference!C:C),"") -> Fax Mapping
A13: AH DiabeticHeld-FaxMap-prod | B13: BTG Ian James Ricero | C13: ian.ricero@company.com | D13: 3 | E13: 1.7241379 | F13: 0.0664 | G13: 0.0013888889 | H13: 3 | I13: 1 | J13: 1.7241379 | K13: 43 | L13: 24.712644 | M13: 1.74 | N13: 0.03816092 | O13: 33:16 | P13: 1:21 | Q13: 1:19 | R13: 0:01 | S13: 0:00 | T13: 0:00 | U13: 0:00 | V13: 0:00 | W13: 0 | X13: 0 | Y13: 0 | Z13: 0 | AA13: 0 | AB13: 0:00 | AC13: 0:00 | AD13: 0 | AE13: 0 | AF13: 0 | AG13: 0 | AH13: 0 | AI13: 0 | AJ13: =LEFT(B13,3) -> BTG | AK13: =TRIM(RIGHT(B13, LEN(B13)-3)) -> Ian James Ricero | AL13: =_xlfn.XLOOKUP(Team_Report[[#This Row],[Team]],reference!B:B,reference!A:A) -> HBOSS Portal Fax Mapping | AM13: =_xlfn.CONCAT(AL13,A13) -> HBOSS Portal Fax MappingAH DiabeticHeld-FaxMap-prod | AN13: =IFERROR(_xlfn.XLOOKUP(Team_Report[[#This Row],[Camp+Team]],reference!D:D,reference!C:C),"") -> Fax Mapping
... A61: HBOSS BT Project-Blank Held | B61: BCD Ron Jacob Balquin | C61: jacob.balquin@company.com | D61: 38 | E61: 9.6623271 | F61: 0.7597 | G61: 0.077777778 | H61: 31 | I61: 0.81578947 | J61: 7.8824247 | K61: 31 | L61: 7.8824247 | M61: 3.9328 | N61: 0.19317026 | O61: 4:47 | P61: 1:19 | Q61: 1:11 | R61: 0:07 | S61: 0:00 | T61: 0:00 | U61: 0:00 | V61: 0:00 | W61: 0 | X61: 0 | Y61: 0 | Z61: 0 | AA61: 0 | AB61: 0:00 | AC61: 0:00 | AD61: 0 | AE61: 0 | AF61: 0 | AG61: 0 | AH61: 0 | AI61: 0 | AJ61: =LEFT(B61,3) -> BCD | AK61: =TRIM(RIGHT(B61, LEN(B61)-3)) -> Ron Jacob Balquin | AL61: =_xlfn.XLOOKUP(Team_Report[[#This Row],[Team]],reference!B:B,reference!A:A) -> AH-SnapHeld-Special Project - Billable | AM61: =_xlfn.CONCAT(AL61,A61) -> AH-SnapHeld-Special Project - BillableHBOSS BT Project-Blank Held | AN61: =IFERROR(_xlfn.XLOOKUP(Team_Report[[#This Row],[Camp+Team]],reference!D:D,reference!C:C),"") -> Blank Held

Sheet Campaign Report
A1: Campaign | B1: Agent | C1: Agent Email | D1: Calls | E1: Calls/Hr | F1: Talk | G1: Wrap Up | H1: Conv | I1: Conv % | J1: Conv/Hr | K1: Points | L1: Points/Hr | M1: Logged In | N1: Eff % | O1: AAT | P1: AHT | Q1: ATT | R1: AWT | S1: Administrative | T1: Break | U1: Coaching | V1: Unavailable | W1: QA Score | X1: Scorecards | Y1: Passed | Z1: Auto Fails | AA1: Holds | AB1: Hold | AC1: Hold/Call | AD1: Rings Tot | AE1: Rings Ans | AF1: Rings Decl | AG1: Rings Timeout | AH1: Rings Miss | AI1: Rings Aban | AJ1: Site | AK1: AgentName | AL1: CampMatch | AM1: Workflow
A2: AH-SnapHeld-Aging-Prod | B2: BCD Geron Poda | C2: geron.poda@company.com | D2: 54 | E2: 16.110266 | F2: 0.1244 | G2: 0.22416667 | H2: 12 | I2: 0.22222222 | J2: 3.5800591 | K2: 12 | L2: 3.5800591 | M2: 3.3519 | N2: 0.037113279 | O2: 0:02 | P2: 0:23 | Q2: 0:08 | R2: 0:14 | S2: 0:00 | T2: 40:01 | U2: 0:00 | V2: 0:00 | W2: 0 | X2: 0 | Y2: 0 | Z2: 0 | AA2: 0 | AB2: 0:00 | AC2: 0:00 | AD2: 0 | AE2: 0 | AF2: 0 | AG2: 0 | AH2: 0 | AI2: 0 | AJ2: =LEFT(B2,3) -> BCD | AK2: =TRIM(RIGHT(B2, LEN(B2)-3)) -> Geron Poda | AL2: =_xlfn.XLOOKUP(A2,reference!A:A,reference!D:D) -> AH-SnapHeld-Aging-Prod | AM2: =IF(A2="AH-SnapHeld-Special Project - B",_xlfn.XLOOKUP(AK2,BP:BP,BO:BO),IF(_xlfn.XLOOKUP(AL2,reference!D:D,reference!C:C)=0,"",_xlfn.XLOOKUP(AL2,reference!D:D,reference!C:C))) -> Aging
A3: AH-SnapHeld-Aging-Prod | B3: BTG Airel Tumambing | C3: airel.tumambing@company.com | D3: 32 | E3: 12.006153 | F3: 0.5403 | G3: 0.055833333 | H3: 8 | I3: 0.25 | J3: 3.0015383 | K3: 8 | L3: 3.0015383 | M3: 2.6653 | N3: 0.20271639 | O3: 0:03 | P3: 1:07 | Q3: 1:00 | R3: 0:06 | S3: 0:00 | T3: 30:18 | U3: 0:00 | V3: 0:00 | W3: 0 | X3: 0 | Y3: 0 | Z3: 0 | AA3: 0 | AB3: 0:00 | AC3: 0:00 | AD3: 0 | AE3: 0 | AF3: 0 | AG3: 0 | AH3: 0 | AI3: 0 | AJ3: =LEFT(B3,3) -> BTG | AK3: =TRIM(RIGHT(B3, LEN(B3)-3)) -> Airel Tumambing | AL3: =_xlfn.XLOOKUP(A3,reference!A:A,reference!D:D) -> AH-SnapHeld-Aging-Prod | AM3: =IF(A3="AH-SnapHeld-Special Project - B",_xlfn.XLOOKUP(AK3,BP:BP,BO:BO),IF(_xlfn.XLOOKUP(AL3,reference!D:D,reference!C:C)=0,"",_xlfn.XLOOKUP(AL3,reference!D:D,reference!C:C))) -> Aging
A4: AH-SnapHeld-Aging-Prod | B4: ILO Shara Marie Baler | C4: shara.baler@company.com | D4: 53 | E4: 16.982825 | F4: 0.6153 | G4: 0.28416667 | H4: 9 | I4: 0.16981132 | J4: 2.8838759 | K4: 9 | L4: 2.8838759 | M4: 3.1208 | N4: 0.19716098 | O4: 0:01 | P4: 1:01 | Q4: 0:41 | R4: 0:19 | S4: 0:00 | T4: 54:38 | U4: 0:00 | V4: 0:00 | W4: 0 | X4: 0 | Y4: 0 | Z4: 0 | AA4: 0 | AB4: 0:00 | AC4: 0:00 | AD4: 0 | AE4: 0 | AF4: 0 | AG4: 0 | AH4: 0 | AI4: 0 | AJ4: =LEFT(B4,3) -> ILO | AK4: =TRIM(RIGHT(B4, LEN(B4)-3)) -> Shara Marie Baler | AL4: =_xlfn.XLOOKUP(A4,reference!A:A,reference!D:D) -> AH-SnapHeld-Aging-Prod | AM4: =IF(A4="AH-SnapHeld-Special Project - B",_xlfn.XLOOKUP(AK4,BP:BP,BO:BO),IF(_xlfn.XLOOKUP(AL4,reference!D:D,reference!C:C)=0,"",_xlfn.XLOOKUP(AL4,reference!D:D,reference!C:C))) -> Aging
A5: AH-SnapHeld-ARM-Prod | B5: ILO Arabella Joy Borromeo | C5: arabella.borromeo@company.com | D5: 22 | E5: 11.407238 | F5: 0.5186 | G5: 1.1016667 | H5: 7 | I5: 0.31818182 | J5: 3.6295759 | K5: 7 | L5: 3.6295759 | M5: 1.9286 | N5: 0.26889972 | O5: 0:01 | P5: 4:25 | Q5: 1:24 | R5: 3:00 | S5: 0:00 | T5: 0:00 | U5: 0:00 | V5: 0:00 | W5: 0 | X5: 0 | Y5: 0 | Z5: 0 | AA5: 0 | AB5: 0:00 | AC5: 0:00 | AD5: 0 | AE5: 0 | AF5: 0 | AG5: 0 | AH5: 0 | AI5: 0 | AJ5: =LEFT(B5,3) -> ILO | AK5: =TRIM(RIGHT(B5, LEN(B5)-3)) -> Arabella Joy Borromeo | AL5: =_xlfn.XLOOKUP(A5,reference!A:A,reference!D:D) -> AH-SnapHeld-ARM-ProdAH-AeroHeld-FTP-Prod | AM5: =IF(A5="AH-SnapHeld-Special Project - B",_xlfn.XLOOKUP(AK5,BP:BP,BO:BO),IF(_xlfn.XLOOKUP(AL5,reference!D:D,reference!C:C)=0,"",_xlfn.XLOOKUP(AL5,reference!D:D,reference!C:C))) -> ARM
A6: AH-SnapHeld-ARM-Prod | B6: ILO Cherryl Rose Gabinera | C6: cherryl.gabinera@company.com | D6: 24 | E6: 10.523546 | F6: 1.7442 | G6: 0.10111111 | H6: 1 | I6: 0.041666667 | J6: 0.4384811 | K6: 1 | L6: 0.4384811 | M6: 2.2806 | N6: 0.76479874 | O6: 0:01 | P6: 4:36 | Q6: 4:21 | R6: 0:15 | S6: 0:00 | T6: 52:16 | U6: 0:00 | V6: 0:00 | W6: 0 | X6: 0 | Y6: 0 | Z6: 0 | AA6: 0 | AB6: 0:00 | AC6: 0:00 | AD6: 0 | AE6: 0 | AF6: 0 | AG6: 0 | AH6: 0 | AI6: 0 | AJ6: =LEFT(B6,3) -> ILO | AK6: =TRIM(RIGHT(B6, LEN(B6)-3)) -> Cherryl Rose Gabinera | AL6: =_xlfn.XLOOKUP(A6,reference!A:A,reference!D:D) -> AH-SnapHeld-ARM-ProdAH-AeroHeld-FTP-Prod | AM6: =IF(A6="AH-SnapHeld-Special Project - B",_xlfn.XLOOKUP(AK6,BP:BP,BO:BO),IF(_xlfn.XLOOKUP(AL6,reference!D:D,reference!C:C)=0,"",_xlfn.XLOOKUP(AL6,reference!D:D,reference!C:C))) -> ARM
A7: AH-SnapHeld-ARM-Prod | B7: ILO Geric Perlas | C7: geric.perlas@company.com | D7: 25 | E7: 11.319388 | F7: 1.88 | G7: 0.049166667 | H7: 2 | I7: 0.08 | J7: 0.90555103 | K7: 2 | L7: 0.90555103 | M7: 2.2086 | N7: 0.85121797 | O7: 0:01 | P7: 4:37 | Q7: 4:30 | R7: 0:07 | S7: 0:00 | T7: 52:43 | U7: 0:00 | V7: 0:00 | W7: 0 | X7: 0 | Y7: 0 | Z7: 0 | AA7: 0 | AB7: 0:00 | AC7: 0:00 | AD7: 0 | AE7: 0 | AF7: 0 | AG7: 0 | AH7: 0 | AI7: 0 | AJ7: =LEFT(B7,3) -> ILO | AK7: =TRIM(RIGHT(B7, LEN(B7)-3)) -> Geric Perlas | AL7: =_xlfn.XLOOKUP(A7,reference!A:A,reference!D:D) -> AH-SnapHeld-ARM-ProdAH-AeroHeld-FTP-Prod | AM7: =IF(A7="AH-SnapHeld-Special Project - B",_xlfn.XLOOKUP(AK7,BP:BP,BO:BO),IF(_xlfn.XLOOKUP(AL7,reference!D:D,reference!C:C)=0,"",_xlfn.XLOOKUP(AL7,reference!D:D,reference!C:C))) -> ARM
A8: AH-SnapHeld-ARM-Prod | B8: ILO Kaixen Gail Arceta | C8: kaixen.arceta@company.com | D8: 20 | E8: 12.286522 | F8: 1.2297 | G8: 0.29472222 | H8: 6 | I8: 0.3 | J8: 3.6859565 | K8: 6 | L8: 3.6859565 | M8: 1.6278 | N8: 0.75543679 | O8: 0:00 | P8: 4:34 | Q8: 3:41 | R8: 0:53 | S8: 0:00 | T8: 0:00 | U8: 0:00 | V8: 0:00 | W8: 0 | X8: 0 | Y8: 0 | Z8: 0 | AA8: 0 | AB8: 0:00 | AC8: 0:00 | AD8: 0 | AE8: 0 | AF8: 0 | AG8: 0 | AH8: 0 | AI8: 0 | AJ8: =LEFT(B8,3) -> ILO | AK8: =TRIM(RIGHT(B8, LEN(B8)-3)) -> Kaixen Gail Arceta | AL8: =_xlfn.XLOOKUP(A8,reference!A:A,reference!D:D) -> AH-SnapHeld-ARM-ProdAH-AeroHeld-FTP-Prod | AM8: =IF(A8="AH-SnapHeld-Special Project - B",_xlfn.XLOOKUP(AK8,BP:BP,BO:BO),IF(_xlfn.XLOOKUP(AL8,reference!D:D,reference!C:C)=0,"",_xlfn.XLOOKUP(AL8,reference!D:D,reference!C:C))) -> ARM
A9: AH-SnapHeld-ARM-Prod | B9: ILO Reynald Jomadiao | C9: reynald.jomadiao@company.com | D9: 70 | E9: 25.333864 | F9: 2.295 | G9: 0.13277778 | H9: 8 | I9: 0.11428571 | J9: 2.8952988 | K9: 8 | L9: 2.8952988 | M9: 2.7631 | N9: 0.83058883 | O9: 0:00 | P9: 2:04 | Q9: 1:58 | R9: 0:06 | S9: 0:00 | T9: 46:40 | U9: 0:00 | V9: 0:00 | W9: 0 | X9: 0 | Y9: 0 | Z9: 0 | AA9: 0 | AB9: 0:00 | AC9: 0:00 | AD9: 0 | AE9: 0 | AF9: 0 | AG9: 0 | AH9: 0 | AI9: 0 | AJ9: =LEFT(B9,3) -> ILO | AK9: =TRIM(RIGHT(B9, LEN(B9)-3)) -> Reynald Jomadiao | AL9: =_xlfn.XLOOKUP(A9,reference!A:A,reference!D:D) -> AH-SnapHeld-ARM-ProdAH-AeroHeld-FTP-Prod | AM9: =IF(A9="AH-SnapHeld-Special Project - B",_xlfn.XLOOKUP(AK9,BP:BP,BO:BO),IF(_xlfn.XLOOKUP(AL9,reference!D:D,reference!C:C)=0,"",_xlfn.XLOOKUP(AL9,reference!D:D,reference!C:C))) -> ARM
A10: AH-SnapHeld-ARM-Prod | B10: ILO Aliyaah Bianca Candoleza | C10: aliyaah.candoleza@company.com | D10: 39 | E10: 15.209422 | F10: 1.8022 | G10: 0.11805556 | H10: 0 | I10: 0 | J10: 0 | K10: 0 | L10: 0 | M10: 2.5642 | N10: 0.70283129 | O10: 0:01 | P10: 2:57 | Q10: 2:46 | R10: 0:10 | S10: 0:00 | T10: 36:32 | U10: 0:00 | V10: 0:00 | W10: 0 | X10: 0 | Y10: 0 | Z10: 0 | AA10: 0 | AB10: 0:00 | AC10: 0:00 | AD10: 0 | AE10: 0 | AF10: 0 | AG10: 0 | AH10: 0 | AI10: 0 | AJ10: =LEFT(B10,3) -> ILO | AK10: =TRIM(RIGHT(B10, LEN(B10)-3)) -> Aliyaah Bianca Candoleza | AL10: =_xlfn.XLOOKUP(A10,reference!A:A,reference!D:D) -> AH-SnapHeld-ARM-ProdAH-AeroHeld-FTP-Prod | AM10: =IF(A10="AH-SnapHeld-Special Project - B",_xlfn.XLOOKUP(AK10,BP:BP,BO:BO),IF(_xlfn.XLOOKUP(AL10,reference!D:D,reference!C:C)=0,"",_xlfn.XLOOKUP(AL10,reference!D:D,reference!C:C))) -> ARM
A11: AH-SnapHeld-ARM-Prod | B11: ILO Deimple Jolo | C11: deimple.jolo@company.com | D11: 39 | E11: 15.206457 | F11: 1.9094 | G11: 0.16111111 | H11: 0 | I11: 0 | J11: 0 | K11: 0 | L11: 0 | M11: 2.5647 | N11: 0.74449253 | O11: 0:00 | P11: 3:11 | Q11: 2:56 | R11: 0:14 | S11: 0:00 | T11: 27:44 | U11: 0:00 | V11: 0:00 | W11: 0 | X11: 0 | Y11: 0 | Z11: 0 | AA11: 0 | AB11: 0:00 | AC11: 0:00 | AD11: 0 | AE11: 0 | AF11: 0 | AG11: 0 | AH11: 0 | AI11: 0 | AJ11: =LEFT(B11,3) -> ILO | AK11: =TRIM(RIGHT(B11, LEN(B11)-3)) -> Deimple Jolo | AL11: =_xlfn.XLOOKUP(A11,reference!A:A,reference!D:D) -> AH-SnapHeld-ARM-ProdAH-AeroHeld-FTP-Prod | AM11: =IF(A11="AH-SnapHeld-Special Project - B",_xlfn.XLOOKUP(AK11,BP:BP,BO:BO),IF(_xlfn.XLOOKUP(AL11,reference!D:D,reference!C:C)=0,"",_xlfn.XLOOKUP(AL11,reference!D:D,reference!C:C))) -> ARM
A12: AH-SnapHeld-ARM-Prod | B12: ILO Hanz Kimcy Esing | C12: hanz.esing@company.com | D12: 71 | E12: 20.167017 | F12: 1.0892 | G12: 1.8166667 | H12: 10 | I12: 0.14084507 | J12: 2.8404249 | K12: 10 | L12: 2.8404249 | M12: 3.5206 | N12: 0.30937908 | O12: 0:00 | P12: 2:27 | Q12: 0:55 | R12: 1:32 | S12: 0:00 | T12: 12:27 | U12: 0:00 | V12: 0:00 | W12: 0 | X12: 0 | Y12: 0 | Z12: 0 | AA12: 0 | AB12: 0:00 | AC12: 0:00 | AD12: 0 | AE12: 0 | AF12: 0 | AG12: 0 | AH12: 0 | AI12: 0 | AJ12: =LEFT(B12,3) -> ILO | AK12: =TRIM(RIGHT(B12, LEN(B12)-3)) -> Hanz Kimcy Esing | AL12: =_xlfn.XLOOKUP(A12,reference!A:A,reference!D:D) -> AH-SnapHeld-ARM-ProdAH-AeroHeld-FTP-Prod | AM12: =IF(A12="AH-SnapHeld-Special Project - B",_xlfn.XLOOKUP(AK12,BP:BP,BO:BO),IF(_xlfn.XLOOKUP(AL12,reference!D:D,reference!C:C)=0,"",_xlfn.XLOOKUP(AL12,reference!D:D,reference!C:C))) -> ARM
A13: AH-SnapHeld-ARM-Prod | B13: ILO Rovy Belarmino | C13: rovy.belarmino@company.com | D13: 17 | E13: 8.3366026 | F13: 0.8108 | G13: 0.92027778 | H13: 3 | I13: 0.17647059 | J13: 1.4711652 | K13: 3 | L13: 1.4711652 | M13: 2.0392 | N13: 0.3976069 | O13: 0:00 | P13: 6:06 | Q13: 2:51 | R13: 3:14 | S13: 0:00 | T13: 49:52 | U13: 0:00 | V13: 0:00 | W13: 0 | X13: 0 | Y13: 0 | Z13: 0 | AA13: 0 | AB13: 0:00 | AC13: 0:00 | AD13: 0 | AE13: 0 | AF13: 0 | AG13: 0 | AH13: 0 | AI13: 0 | AJ13: =LEFT(B13,3) -> ILO | AK13: =TRIM(RIGHT(B13, LEN(B13)-3)) -> Rovy Belarmino | AL13: =_xlfn.XLOOKUP(A13,reference!A:A,reference!D:D) -> AH-SnapHeld-ARM-ProdAH-AeroHeld-FTP-Prod | AM13: =IF(A13="AH-SnapHeld-Special Project - B",_xlfn.XLOOKUP(AK13,BP:BP,BO:BO),IF(_xlfn.XLOOKUP(AL13,reference!D:D,reference!C:C)=0,"",_xlfn.XLOOKUP(AL13,reference!D:D,reference!C:C))) -> ARM
... A164: HBOSS Portal Fax Research | B164: ILO Ricky Mendiro | C164: ricky.mendiro@company.com | D164: 8 | E164: 20.423794 | F164: 0.0992 | G164: 0.13583333 | H164: 3 | I164: 0.375 | J164: 7.6589226 | K164: 15 | L164: 38.294613 | M164: 0.3917 | N164: 0.25325504 | O164: 0:26 | P164: 1:45 | Q164: 0:44 | R164: 1:01 | S164: 0:00 | T164: 0:00 | U164: 0:00 | V164: 0:00 | W164: 0 | X164: 0 | Y164: 0 | Z164: 0 | AA164: 0 | AB164: 0:00 | AC164: 0:00 | AD164: 0 | AE164: 0 | AF164: 0 | AG164: 0 | AH164: 0 | AI164: 0 | AJ164: =LEFT(B164,3) -> ILO | AK164: =TRIM(RIGHT(B164, LEN(B164)-3)) -> Ricky Mendiro | AL164: =_xlfn.XLOOKUP(A164,reference!A:A,reference!D:D) -> HBOSS Portal Fax ResearchAH-SnapHeld-FaxRes-Prod | AM164: =IF(A164="AH-SnapHeld-Special Project - B",_xlfn.XLOOKUP(AK164,BP:BP,BO:BO),IF(_xlfn.XLOOKUP(AL164,reference!D:D,reference!C:C)=0,"",_xlfn.XLOOKUP(AL164,reference!D:D,reference!C:C))) -> Fax Research

Sheet Pivots
B1: BCD | C1: Hours | D1: Completes | E1: Points | F1: RPH/PPH | H1: ILO | I1: Hours | J1: Completes | K1: Points | L1: RPH/PPH | N1: BTG | O1: Hours | P1: Completes | Q1: Points | R1: RPH/PPH | T1: CAMPAIGN BASE | U1: Site | V1: Workflow | W1: Sum of Calls | X1: Sum of Points | Y1: Sum of Logged In | Z1: Sum of RPH | AA1: Sum of PPH | AC1: TEAM BASE | AD1: Site | AE1: Workflow | AF1: AgentName | AG1: Sum of Calls | AH1: Sum of Points | AI1: Sum of Logged In | AJ1: Sum of RPH | AK1: Sum of PPH | AM1: Team Report | AN1: Sum of Calls | AO1: Sum of Points | AP1: Sum of Logged In | AQ1: Sum of RPH | AR1: Sum of PPH
B2: BCD-Confirmed Sales | C2: =IF(IFERROR(_xlfn.XLOOKUP($B2,$T:$T,$Y:$Y),"")="",IFERROR(IF(SUMIF($AC:$AC,$B2,$AI:$AI)=0,"",SUMIF($AC:$AC,$B2,$AI:$AI)),""),IFERROR(_xlfn.XLOOKUP($B2,$T:$T,$Y:$Y),"")) -> 2.2756 | D2: =IF(IFERROR(_xlfn.XLOOKUP($B2,$T:$T,$W:$W),"")="",IFERROR(IF(SUMIF($AC:$AC,$B2,$AG:$AG)=0,"",SUMIF($AC:$AC,$B2,$AG:$AG)),""),IFERROR(_xlfn.XLOOKUP($B2,$T:$T,$W:$W),"")) -> 29 | E2: =IF(IFERROR(_xlfn.XLOOKUP($B2,$T:$T,$X:$X),"")="",IFERROR(IF(SUMIF($AC:$AC,$B2,$AH:$AH)=0,"",SUMIF($AC:$AC,$B2,$AH:$AH)),""),IFERROR(_xlfn.XLOOKUP($B2,$T:$T,$X:$X),"")) -> 12 | F2: =IFERROR(D2/C2,"") -> 12.743892 | H2: ILO-Confirmed Sales | I2: =IF(IFERROR(_xlfn.XLOOKUP($H2,$T:$T,$Y:$Y),"")="",IFERROR(IF(SUMIF($AC:$AC,$H2,$AI:$AI)=0,"",SUMIF($AC:$AC,$H2,$AI:$AI)),""),IFERROR(_xlfn.XLOOKUP($H2,$T:$T,$Y:$Y),"")) -> 0.7397 | J2: =IF(IFERROR(_xlfn.XLOOKUP($H2,$T:$T,$W:$W),"")="",IFERROR(IF(SUMIF($AC:$AC,$H2,$AG:$AG)=0,"",SUMIF($AC:$AC,$H2,$AG:$AG)),""),IFERROR(_xlfn.XLOOKUP($H2,$T:$T,$W:$W),"")) -> 9 | K2: =IF(IFERROR(_xlfn.XLOOKUP($H2,$T:$T,$X:$X),"")="",IFERROR(IF(SUMIF($AC:$AC,$H2,$AH:$AH)=0,"",SUMIF($AC:$AC,$H2,$AH:$AH)),""),IFERROR(_xlfn.XLOOKUP($H2,$T:$T,$X:$X),"")) -> 5 | L2: =IFERROR(J2/I2,"") -> 12.167095 | N2: BTG-Confirmed Sales | O2: =IF(IFERROR(_xlfn.XLOOKUP($N2,$T:$T,$Y:$Y),"")="",IFERROR(IF(SUMIF($AC:$AC,$N2,$AI:$AI)=0,"",SUMIF($AC:$AC,$N2,$AI:$AI)),""),IFERROR(_xlfn.XLOOKUP($N2,$T:$T,$Y:$Y),"")) -> 11.7687 | P2: =IF(IFERROR(_xlfn.XLOOKUP($N2,$T:$T,$W:$W),"")="",IFERROR(IF(SUMIF($AC:$AC,$N2,$AG:$AG)=0,"",SUMIF($AC:$AC,$N2,$AG:$AG)),""),IFERROR(_xlfn.XLOOKUP($N2,$T:$T,$W:$W),"")) -> 224 | Q2: =IF(IFERROR(_xlfn.XLOOKUP($N2,$T:$T,$X:$X),"")="",IFERROR(IF(SUMIF($AC:$AC,$N2,$AH:$AH)=0,"",SUMIF($AC:$AC,$N2,$AH:$AH)),""),IFERROR(_xlfn.XLOOKUP($N2,$T:$T,$X:$X),"")) -> 104 | R2: =IFERROR(P2/O2,"") -> 19.033538 | T2: =_xlfn.CONCAT(U2,"-",V2) -> BCD-DCAH Scrubs | U2: BCD | V2: DCAH Scrubs | W2: 133 | X2: 15 | Y2: 11.1638 | Z2: 11.913506 | AA2: 1.3436285 | AC2: =_xlfn.CONCAT(AD2,"-",AE2) -> BCD-Fax Mapping | AD2: BCD | AE2: Fax Mapping | AF2: Jeshurun Corpus | AG2: 11 | AH2: 102 | AI2: 3.8619 | AJ2: 2.8483389 | AK2: 26.41187 | AM2: BCD-0 | AN2: =SUMIF(AC:AC,AM2,AG:AG) -> 0 | AO2: =SUMIF(AC:AC,AM2,AH:AH) -> 0 | AP2: =SUMIF(AC:AC,AM2,AI:AI) -> 0 | AQ2: =AVERAGEIF(AC:AC,AM2,AI:AI) -> #DIV/0! | AR2: =AVERAGEIF(AC:AC,AM2,AJ:AJ) -> #DIV/0!
B3: BCD-Edocument | C3: =IF(IFERROR(_xlfn.XLOOKUP($B3,$T:$T,$Y:$Y),"")="",IFERROR(IF(SUMIF($AC:$AC,$B3,$AI:$AI)=0,"",SUMIF($AC:$AC,$B3,$AI:$AI)),""),IFERROR(_xlfn.XLOOKUP($B3,$T:$T,$Y:$Y),"")) -> 34.3005 | D3: =IF(IFERROR(_xlfn.XLOOKUP($B3,$T:$T,$W:$W),"")="",IFERROR(IF(SUMIF($AC:$AC,$B3,$AG:$AG)=0,"",SUMIF($AC:$AC,$B3,$AG:$AG)),""),IFERROR(_xlfn.XLOOKUP($B3,$T:$T,$W:$W),"")) -> 162 | E3: =IF(IFERROR(_xlfn.XLOOKUP($B3,$T:$T,$X:$X),"")="",IFERROR(IF(SUMIF($AC:$AC,$B3,$AH:$AH)=0,"",SUMIF($AC:$AC,$B3,$AH:$AH)),""),IFERROR(_xlfn.XLOOKUP($B3,$T:$T,$X:$X),"")) -> 41 | F3: =IFERROR(D3/C3,"") -> 4.7229632 | H3: ILO-Edocument | I3: =IF(IFERROR(_xlfn.XLOOKUP($H3,$T:$T,$Y:$Y),"")="",IFERROR(IF(SUMIF($AC:$AC,$H3,$AI:$AI)=0,"",SUMIF($AC:$AC,$H3,$AI:$AI)),""),IFERROR(_xlfn.XLOOKUP($H3,$T:$T,$Y:$Y),"")) | J3: =IF(IFERROR(_xlfn.XLOOKUP($H3,$T:$T,$W:$W),"")="",IFERROR(IF(SUMIF($AC:$AC,$H3,$AG:$AG)=0,"",SUMIF($AC:$AC,$H3,$AG:$AG)),""),IFERROR(_xlfn.XLOOKUP($H3,$T:$T,$W:$W),"")) | K3: =IF(IFERROR(_xlfn.XLOOKUP($H3,$T:$T,$X:$X),"")="",IFERROR(IF(SUMIF($AC:$AC,$H3,$AH:$AH)=0,"",SUMIF($AC:$AC,$H3,$AH:$AH)),""),IFERROR(_xlfn.XLOOKUP($H3,$T:$T,$X:$X),"")) | L3: =IFERROR(J3/I3,"") | N3: BTG-Edocument | O3: =IF(IFERROR(_xlfn.XLOOKUP($N3,$T:$T,$Y:$Y),"")="",IFERROR(IF(SUMIF($AC:$AC,$N3,$AI:$AI)=0,"",SUMIF($AC:$AC,$N3,$AI:$AI)),""),IFERROR(_xlfn.XLOOKUP($N3,$T:$T,$Y:$Y),"")) | P3: =IF(IFERROR(_xlfn.XLOOKUP($N3,$T:$T,$W:$W),"")="",IFERROR(IF(SUMIF($AC:$AC,$N3,$AG:$AG)=0,"",SUMIF($AC:$AC,$N3,$AG:$AG)),""),IFERROR(_xlfn.XLOOKUP($N3,$T:$T,$W:$W),"")) | Q3: =IF(IFERROR(_xlfn.XLOOKUP($N3,$T:$T,$X:$X),"")="",IFERROR(IF(SUMIF($AC:$AC,$N3,$AH:$AH)=0,"",SUMIF($AC:$AC,$N3,$AH:$AH)),""),IFERROR(_xlfn.XLOOKUP($N3,$T:$T,$X:$X),"")) | R3: =IFERROR(P3/O3,"") | T3: =_xlfn.CONCAT(U3,"-",V3) -> BCD-Edocument | U3: BCD | V3: Edocument | W3: 162 | X3: 41 | Y3: 34.3005 | Z3: 4.7229632 | AA3: 1.1953179 | AC3: =_xlfn.CONCAT(AD3,"-",AE3) -> BCD-Fax Mapping | AD3: BCD | AE3: Fax Mapping | AF3: Gabrielle Angela Alcala | AG3: 6 | AH3: 57 | AI3: 4.0153 | AJ3: 1.4942844 | AK3: 14.195701 | AM3: BCD-Tricare East RX Review | AN3: =SUMIF(AC:AC,AM3,AG:AG) -> 0 | AO3: =SUMIF(AC:AC,AM3,AH:AH) -> 0 | AP3: =SUMIF(AC:AC,AM3,AI:AI) -> 0 | AQ3: =AVERAGEIF(AC:AC,AM3,AI:AI) -> #DIV/0! | AR3: =AVERAGEIF(AC:AC,AM3,AJ:AJ) -> #DIV/0!
B4: BCD-Edocument Prio | C4: =IF(IFERROR(_xlfn.XLOOKUP($B4,$T:$T,$Y:$Y),"")="",IFERROR(IF(SUMIF($AC:$AC,$B4,$AI:$AI)=0,"",SUMIF($AC:$AC,$B4,$AI:$AI)),""),IFERROR(_xlfn.XLOOKUP($B4,$T:$T,$Y:$Y),"")) | D4: =IF(IFERROR(_xlfn.XLOOKUP($B4,$T:$T,$W:$W),"")="",IFERROR(IF(SUMIF($AC:$AC,$B4,$AG:$AG)=0,"",SUMIF($AC:$AC,$B4,$AG:$AG)),""),IFERROR(_xlfn.XLOOKUP($B4,$T:$T,$W:$W),"")) | E4: =IF(IFERROR(_xlfn.XLOOKUP($B4,$T:$T,$X:$X),"")="",IFERROR(IF(SUMIF($AC:$AC,$B4,$AH:$AH)=0,"",SUMIF($AC:$AC,$B4,$AH:$AH)),""),IFERROR(_xlfn.XLOOKUP($B4,$T:$T,$X:$X),"")) | F4: =IFERROR(D4/C4,"") | H4: ILO-Edocument Prio | I4: =IF(IFERROR(_xlfn.XLOOKUP($H4,$T:$T,$Y:$Y),"")="",IFERROR(IF(SUMIF($AC:$AC,$H4,$AI:$AI)=0,"",SUMIF($AC:$AC,$H4,$AI:$AI)),""),IFERROR(_xlfn.XLOOKUP($H4,$T:$T,$Y:$Y),"")) | J4: =IF(IFERROR(_xlfn.XLOOKUP($H4,$T:$T,$W:$W),"")="",IFERROR(IF(SUMIF($AC:$AC,$H4,$AG:$AG)=0,"",SUMIF($AC:$AC,$H4,$AG:$AG)),""),IFERROR(_xlfn.XLOOKUP($H4,$T:$T,$W:$W),"")) | K4: =IF(IFERROR(_xlfn.XLOOKUP($H4,$T:$T,$X:$X),"")="",IFERROR(IF(SUMIF($AC:$AC,$H4,$AH:$AH)=0,"",SUMIF($AC:$AC,$H4,$AH:$AH)),""),IFERROR(_xlfn.XLOOKUP($H4,$T:$T,$X:$X),"")) | L4: =IFERROR(J4/I4,"") | N4: BTG-Edocument Prio | O4: =IF(IFERROR(_xlfn.XLOOKUP($N4,$T:$T,$Y:$Y),"")="",IFERROR(IF(SUMIF($AC:$AC,$N4,$AI:$AI)=0,"",SUMIF($AC:$AC,$N4,$AI:$AI)),""),IFERROR(_xlfn.XLOOKUP($N4,$T:$T,$Y:$Y),"")) | P4: =IF(IFERROR(_xlfn.XLOOKUP($N4,$T:$T,$W:$W),"")="",IFERROR(IF(SUMIF($AC:$AC,$N4,$AG:$AG)=0,"",SUMIF($AC:$AC,$N4,$AG:$AG)),""),IFERROR(_xlfn.XLOOKUP($N4,$T:$T,$W:$W),"")) | Q4: =IF(IFERROR(_xlfn.XLOOKUP($N4,$T:$T,$X:$X),"")="",IFERROR(IF(SUMIF($AC:$AC,$N4,$AH:$AH)=0,"",SUMIF($AC:$AC,$N4,$AH:$AH)),""),IFERROR(_xlfn.XLOOKUP($N4,$T:$T,$X:$X),"")) | R4: =IFERROR(P4/O4,"") | T4: =_xlfn.CONCAT(U4,"-",V4) -> BCD-VSA | U4: BCD | V4: VSA | W4: 165 | X4: 107 | Y4: 6.6852 | Z4: 24.681386 | AA4: 16.005505 | AC4: =_xlfn.CONCAT(AD4,"-",AE4) -> BCD-Fax Mapping | AD4: BCD | AE4: Fax Mapping | AF4: Nicole Amador | AG4: 1 | AH4: 20 | AI4: 0.9211 | AJ4: 1.0856585 | AK4: 21.713169 | AM4: BCD-UHC Special Project | AN4: =SUMIF(AC:AC,AM4,AG:AG) -> 0 | AO4: =SUMIF(AC:AC,AM4,AH:AH) -> 0 | AP4: =SUMIF(AC:AC,AM4,AI:AI) -> 0 | AQ4: =AVERAGEIF(AC:AC,AM4,AI:AI) -> #DIV/0! | AR4: =AVERAGEIF(AC:AC,AM4,AJ:AJ) -> #DIV/0!
B5: BCD-DCAH scrubs | C5: =IF(IFERROR(_xlfn.XLOOKUP($B5,$T:$T,$Y:$Y),"")="",IFERROR(IF(SUMIF($AC:$AC,$B5,$AI:$AI)=0,"",SUMIF($AC:$AC,$B5,$AI:$AI)),""),IFERROR(_xlfn.XLOOKUP($B5,$T:$T,$Y:$Y),"")) -> 11.1638 | D5: =IF(IFERROR(_xlfn.XLOOKUP($B5,$T:$T,$W:$W),"")="",IFERROR(IF(SUMIF($AC:$AC,$B5,$AG:$AG)=0,"",SUMIF($AC:$AC,$B5,$AG:$AG)),""),IFERROR(_xlfn.XLOOKUP($B5,$T:$T,$W:$W),"")) -> 133 | E5: =IF(IFERROR(_xlfn.XLOOKUP($B5,$T:$T,$X:$X),"")="",IFERROR(IF(SUMIF($AC:$AC,$B5,$AH:$AH)=0,"",SUMIF($AC:$AC,$B5,$AH:$AH)),""),IFERROR(_xlfn.XLOOKUP($B5,$T:$T,$X:$X),"")) -> 15 | F5: =IFERROR(D5/C5,"") -> 11.913506 | H5: ILO-DCAH scrubs | I5: =IF(IFERROR(_xlfn.XLOOKUP($H5,$T:$T,$Y:$Y),"")="",IFERROR(IF(SUMIF($AC:$AC,$H5,$AI:$AI)=0,"",SUMIF($AC:$AC,$H5,$AI:$AI)),""),IFERROR(_xlfn.XLOOKUP($H5,$T:$T,$Y:$Y),"")) | J5: =IF(IFERROR(_xlfn.XLOOKUP($H5,$T:$T,$W:$W),"")="",IFERROR(IF(SUMIF($AC:$AC,$H5,$AG:$AG)=0,"",SUMIF($AC:$AC,$H5,$AG:$AG)),""),IFERROR(_xlfn.XLOOKUP($H5,$T:$T,$W:$W),"")) | K5: =IF(IFERROR(_xlfn.XLOOKUP($H5,$T:$T,$X:$X),"")="",IFERROR(IF(SUMIF($AC:$AC,$H5,$AH:$AH)=0,"",SUMIF($AC:$AC,$H5,$AH:$AH)),""),IFERROR(_xlfn.XLOOKUP($H5,$T:$T,$X:$X),"")) | L5: =IFERROR(J5/I5,"") | N5: BTG-DCAH scrubs | O5: =IF(IFERROR(_xlfn.XLOOKUP($N5,$T:$T,$Y:$Y),"")="",IFERROR(IF(SUMIF($AC:$AC,$N5,$AI:$AI)=0,"",SUMIF($AC:$AC,$N5,$AI:$AI)),""),IFERROR(_xlfn.XLOOKUP($N5,$T:$T,$Y:$Y),"")) -> 42.2065 | P5: =IF(IFERROR(_xlfn.XLOOKUP($N5,$T:$T,$W:$W),"")="",IFERROR(IF(SUMIF($AC:$AC,$N5,$AG:$AG)=0,"",SUMIF($AC:$AC,$N5,$AG:$AG)),""),IFERROR(_xlfn.XLOOKUP($N5,$T:$T,$W:$W),"")) -> 42 | Q5: =IF(IFERROR(_xlfn.XLOOKUP($N5,$T:$T,$X:$X),"")="",IFERROR(IF(SUMIF($AC:$AC,$N5,$AH:$AH)=0,"",SUMIF($AC:$AC,$N5,$AH:$AH)),""),IFERROR(_xlfn.XLOOKUP($N5,$T:$T,$X:$X),"")) -> 6 | R5: =IFERROR(P5/O5,"") -> 0.99510739 | T5: =_xlfn.CONCAT(U5,"-",V5) -> BCD-Doctor Research | U5: BCD | V5: Doctor Research | W5: 22 | X5: 22 | Y5: 3.3831 | Z5: 6.5029115 | AA5: 6.5029115 | AC5: =_xlfn.CONCAT(AD5,"-",AE5) -> BCD-Fax Mapping | AD5: BCD | AE5: Fax Mapping | AF5: Julius Canasares | AG5: 2 | AH5: 19 | AI5: 3.06 | AJ5: 0.65359477 | AK5: 6.2091503 | AM5: BCD-VA Medicaid | AN5: =SUMIF(AC:AC,AM5,AG:AG) -> 0 | AO5: =SUMIF(AC:AC,AM5,AH:AH) -> 0 | AP5: =SUMIF(AC:AC,AM5,AI:AI) -> 0 | AQ5: =AVERAGEIF(AC:AC,AM5,AI:AI) -> #DIV/0! | AR5: =AVERAGEIF(AC:AC,AM5,AJ:AJ) -> #DIV/0!
B6: BCD-DCAH | C6: =IF(IFERROR(_xlfn.XLOOKUP($B6,$T:$T,$Y:$Y),"")="",IFERROR(IF(SUMIF($AC:$AC,$B6,$AI:$AI)=0,"",SUMIF($AC:$AC,$B6,$AI:$AI)),""),IFERROR(_xlfn.XLOOKUP($B6,$T:$T,$Y:$Y),"")) | D6: =IF(IFERROR(_xlfn.XLOOKUP($B6,$T:$T,$W:$W),"")="",IFERROR(IF(SUMIF($AC:$AC,$B6,$AG:$AG)=0,"",SUMIF($AC:$AC,$B6,$AG:$AG)),""),IFERROR(_xlfn.XLOOKUP($B6,$T:$T,$W:$W),"")) | E6: =IF(IFERROR(_xlfn.XLOOKUP($B6,$T:$T,$X:$X),"")="",IFERROR(IF(SUMIF($AC:$AC,$B6,$AH:$AH)=0,"",SUMIF($AC:$AC,$B6,$AH:$AH)),""),IFERROR(_xlfn.XLOOKUP($B6,$T:$T,$X:$X),"")) | F6: =IFERROR(D6/C6,"") | H6: ILO-DCAH | I6: =IF(IFERROR(_xlfn.XLOOKUP($H6,$T:$T,$Y:$Y),"")="",IFERROR(IF(SUMIF($AC:$AC,$H6,$AI:$AI)=0,"",SUMIF($AC:$AC,$H6,$AI:$AI)),""),IFERROR(_xlfn.XLOOKUP($H6,$T:$T,$Y:$Y),"")) -> 4.8122 | J6: =IF(IFERROR(_xlfn.XLOOKUP($H6,$T:$T,$W:$W),"")="",IFERROR(IF(SUMIF($AC:$AC,$H6,$AG:$AG)=0,"",SUMIF($AC:$AC,$H6,$AG:$AG)),""),IFERROR(_xlfn.XLOOKUP($H6,$T:$T,$W:$W),"")) -> 41 | K6: =IF(IFERROR(_xlfn.XLOOKUP($H6,$T:$T,$X:$X),"")="",IFERROR(IF(SUMIF($AC:$AC,$H6,$AH:$AH)=0,"",SUMIF($AC:$AC,$H6,$AH:$AH)),""),IFERROR(_xlfn.XLOOKUP($H6,$T:$T,$X:$X),"")) -> 2 | L6: =IFERROR(J6/I6,"") -> 8.5200116 | N6: BTG-DCAH | O6: =IF(IFERROR(_xlfn.XLOOKUP($N6,$T:$T,$Y:$Y),"")="",IFERROR(IF(SUMIF($AC:$AC,$N6,$AI:$AI)=0,"",SUMIF($AC:$AC,$N6,$AI:$AI)),""),IFERROR(_xlfn.XLOOKUP($N6,$T:$T,$Y:$Y),"")) -> 61.5991 | P6: =IF(IFERROR(_xlfn.XLOOKUP($N6,$T:$T,$W:$W),"")="",IFERROR(IF(SUMIF($AC:$AC,$N6,$AG:$AG)=0,"",SUMIF($AC:$AC,$N6,$AG:$AG)),""),IFERROR(_xlfn.XLOOKUP($N6,$T:$T,$W:$W),"")) -> 640 | Q6: =IF(IFERROR(_xlfn.XLOOKUP($N6,$T:$T,$X:$X),"")="",IFERROR(IF(SUMIF($AC:$AC,$N6,$AH:$AH)=0,"",SUMIF($AC:$AC,$N6,$AH:$AH)),""),IFERROR(_xlfn.XLOOKUP($N6,$T:$T,$X:$X),"")) -> 31 | R6: =IFERROR(P6/O6,"") -> 10.389762 | T6: =_xlfn.CONCAT(U6,"-",V6) -> BCD-Doctor Match | U6: BCD | V6: Doctor Match | W6: 28 | X6: 239 | Y6: 21.0973 | Z6: 1.327184 | AA6: 11.328464 | AC6: =_xlfn.CONCAT(AD6,"-",AE6) -> BCD-Fax Mapping | AD6: BCD | AE6: Fax Mapping | AF6: Maria Amalia Endrinal | AG6: 7 | AH6: 36 | AI6: 3.315 | AJ6: 2.1116139 | AK6: 10.859729 | AM6: BTG-Tricare East RX Review | AN6: =SUMIF(AC:AC,AM6,AG:AG) -> 0 | AO6: =SUMIF(AC:AC,AM6,AH:AH) -> 0 | AP6: =SUMIF(AC:AC,AM6,AI:AI) -> 0 | AQ6: =AVERAGEIF(AC:AC,AM6,AI:AI) -> #DIV/0! | AR6: =AVERAGEIF(AC:AC,AM6,AJ:AJ) -> #DIV/0!
B7: BCD-ARM | C7: =IF(IFERROR(_xlfn.XLOOKUP($B7,$T:$T,$Y:$Y),"")="",IFERROR(IF(SUMIF($AC:$AC,$B7,$AI:$AI)=0,"",SUMIF($AC:$AC,$B7,$AI:$AI)),""),IFERROR(_xlfn.XLOOKUP($B7,$T:$T,$Y:$Y),"")) | D7: =IF(IFERROR(_xlfn.XLOOKUP($B7,$T:$T,$W:$W),"")="",IFERROR(IF(SUMIF($AC:$AC,$B7,$AG:$AG)=0,"",SUMIF($AC:$AC,$B7,$AG:$AG)),""),IFERROR(_xlfn.XLOOKUP($B7,$T:$T,$W:$W),"")) | E7: =IF(IFERROR(_xlfn.XLOOKUP($B7,$T:$T,$X:$X),"")="",IFERROR(IF(SUMIF($AC:$AC,$B7,$AH:$AH)=0,"",SUMIF($AC:$AC,$B7,$AH:$AH)),""),IFERROR(_xlfn.XLOOKUP($B7,$T:$T,$X:$X),"")) | F7: =IFERROR(D7/C7,"") | H7: ILO-ARM | I7: =IF(IFERROR(_xlfn.XLOOKUP($H7,$T:$T,$Y:$Y),"")="",IFERROR(IF(SUMIF($AC:$AC,$H7,$AI:$AI)=0,"",SUMIF($AC:$AC,$H7,$AI:$AI)),""),IFERROR(_xlfn.XLOOKUP($H7,$T:$T,$Y:$Y),"")) -> 26.2502 | J7: =IF(IFERROR(_xlfn.XLOOKUP($H7,$T:$T,$W:$W),"")="",IFERROR(IF(SUMIF($AC:$AC,$H7,$AG:$AG)=0,"",SUMIF($AC:$AC,$H7,$AG:$AG)),""),IFERROR(_xlfn.XLOOKUP($H7,$T:$T,$W:$W),"")) -> 405 | K7: =IF(IFERROR(_xlfn.XLOOKUP($H7,$T:$T,$X:$X),"")="",IFERROR(IF(SUMIF($AC:$AC,$H7,$AH:$AH)=0,"",SUMIF($AC:$AC,$H7,$AH:$AH)),""),IFERROR(_xlfn.XLOOKUP($H7,$T:$T,$X:$X),"")) -> 52 | L7: =IFERROR(J7/I7,"") -> 15.428454 | N7: BTG-ARM | O7: =IF(IFERROR(_xlfn.XLOOKUP($N7,$T:$T,$Y:$Y),"")="",IFERROR(IF(SUMIF($AC:$AC,$N7,$AI:$AI)=0,"",SUMIF($AC:$AC,$N7,$AI:$AI)),""),IFERROR(_xlfn.XLOOKUP($N7,$T:$T,$Y:$Y),"")) | P7: =IF(IFERROR(_xlfn.XLOOKUP($N7,$T:$T,$W:$W),"")="",IFERROR(IF(SUMIF($AC:$AC,$N7,$AG:$AG)=0,"",SUMIF($AC:$AC,$N7,$AG:$AG)),""),IFERROR(_xlfn.XLOOKUP($N7,$T:$T,$W:$W),"")) | Q7: =IF(IFERROR(_xlfn.XLOOKUP($N7,$T:$T,$X:$X),"")="",IFERROR(IF(SUMIF($AC:$AC,$N7,$AH:$AH)=0,"",SUMIF($AC:$AC,$N7,$AH:$AH)),""),IFERROR(_xlfn.XLOOKUP($N7,$T:$T,$X:$X),"")) | R7: =IFERROR(P7/O7,"") | T7: =_xlfn.CONCAT(U7,"-",V7) -> BCD-Aging | U7: BCD | V7: Aging | W7: 54 | X7: 12 | Y7: 3.3519 | Z7: 16.110266 | AA7: 3.5800591 | AC7: =_xlfn.CONCAT(AD7,"-",AE7) -> BCD-Confirmed Sales | AD7: BCD | AE7: Confirmed Sales | AF7: Nelrose Saguire | AG7: 13 | AH7: 9 | AI7: 1.16 | AJ7: 11.206897 | AK7: 7.7586207 | AM7: Grand Total- | AN7: =SUMIF(AC:AC,AM7,AG:AG) -> 818 | AO7: =SUMIF(AC:AC,AM7,AH:AH) -> 961 | AP7: =SUMIF(AC:AC,AM7,AI:AI) -> 113.5978 | AQ7: =AVERAGEIF(AC:AC,AM7,AI:AI) -> 113.5978 | AR7: =AVERAGEIF(AC:AC,AM7,AJ:AJ) -> 7.2008437
B8: BCD-PCAH | C8: =IF(IFERROR(_xlfn.XLOOKUP($B8,$T:$T,$Y:$Y),"")="",IFERROR(IF(SUMIF($AC:$AC,$B8,$AI:$AI)=0,"",SUMIF($AC:$AC,$B8,$AI:$AI)),""),IFERROR(_xlfn.XLOOKUP($B8,$T:$T,$Y:$Y),"")) | D8: =IF(IFERROR(_xlfn.XLOOKUP($B8,$T:$T,$W:$W),"")="",IFERROR(IF(SUMIF($AC:$AC,$B8,$AG:$AG)=0,"",SUMIF($AC:$AC,$B8,$AG:$AG)),""),IFERROR(_xlfn.XLOOKUP($B8,$T:$T,$W:$W),"")) | E8: =IF(IFERROR(_xlfn.XLOOKUP($B8,$T:$T,$X:$X),"")="",IFERROR(IF(SUMIF($AC:$AC,$B8,$AH:$AH)=0,"",SUMIF($AC:$AC,$B8,$AH:$AH)),""),IFERROR(_xlfn.XLOOKUP($B8,$T:$T,$X:$X),"")) | F8: =IFERROR(D8/C8,"") | H8: ILO-PCAH | I8: =IF(IFERROR(_xlfn.XLOOKUP($H8,$T:$T,$Y:$Y),"")="",IFERROR(IF(SUMIF($AC:$AC,$H8,$AI:$AI)=0,"",SUMIF($AC:$AC,$H8,$AI:$AI)),""),IFERROR(_xlfn.XLOOKUP($H8,$T:$T,$Y:$Y),"")) -> 28.121 | J8: =IF(IFERROR(_xlfn.XLOOKUP($H8,$T:$T,$W:$W),"")="",IFERROR(IF(SUMIF($AC:$AC,$H8,$AG:$AG)=0,"",SUMIF($AC:$AC,$H8,$AG:$AG)),""),IFERROR(_xlfn.XLOOKUP($H8,$T:$T,$W:$W),"")) -> 400 | K8: =IF(IFERROR(_xlfn.XLOOKUP($H8,$T:$T,$X:$X),"")="",IFERROR(IF(SUMIF($AC:$AC,$H8,$AH:$AH)=0,"",SUMIF($AC:$AC,$H8,$AH:$AH)),""),IFERROR(_xlfn.XLOOKUP($H8,$T:$T,$X:$X),"")) -> 56 | L8: =IFERROR(J8/I8,"") -> 14.224245 | N8: BTG-PCAH | O8: =IF(IFERROR(_xlfn.XLOOKUP($N8,$T:$T,$Y:$Y),"")="",IFERROR(IF(SUMIF($AC:$AC,$N8,$AI:$AI)=0,"",SUMIF($AC:$AC,$N8,$AI:$AI)),""),IFERROR(_xlfn.XLOOKUP($N8,$T:$T,$Y:$Y),"")) -> 38.6792 | P8: =IF(IFERROR(_xlfn.XLOOKUP($N8,$T:$T,$W:$W),"")="",IFERROR(IF(SUMIF($AC:$AC,$N8,$AG:$AG)=0,"",SUMIF($AC:$AC,$N8,$AG:$AG)),""),IFERROR(_xlfn.XLOOKUP($N8,$T:$T,$W:$W),"")) -> 446 | Q8: =IF(IFERROR(_xlfn.XLOOKUP($N8,$T:$T,$X:$X),"")="",IFERROR(IF(SUMIF($AC:$AC,$N8,$AH:$AH)=0,"",SUMIF($AC:$AC,$N8,$AH:$AH)),""),IFERROR(_xlfn.XLOOKUP($N8,$T:$T,$X:$X),"")) -> 58 | R8: =IFERROR(P8/O8,"") -> 11.530745 | T8: =_xlfn.CONCAT(U8,"-",V8) -> BTG-DCAH Scrubs | U8: BTG | V8: DCAH Scrubs | W8: 42 | X8: 6 | Y8: 42.2065 | Z8: 0.99510739 | AA8: 0.1421582 | AC8: =_xlfn.CONCAT(AD8,"-",AE8) -> BCD-Confirmed Sales | AD8: BCD | AE8: Confirmed Sales | AF8: LA Blessed Ann Gonzales | AG8: 16 | AH8: 3 | AI8: 1.1156 | AJ8: 14.342058 | AK8: 2.6891359 | AM8: ILO-0 | AN8: =SUMIF(AC:AC,AM8,AG:AG) -> 0 | AO8: =SUMIF(AC:AC,AM8,AH:AH) -> 0 | AP8: =SUMIF(AC:AC,AM8,AI:AI) -> 0.0256 | AQ8: =AVERAGEIF(AC:AC,AM8,AI:AI) -> 0.0256 | AR8: =AVERAGEIF(AC:AC,AM8,AJ:AJ) -> 0
B9: BCD-VSA | C9: =IF(IFERROR(_xlfn.XLOOKUP($B9,$T:$T,$Y:$Y),"")="",IFERROR(IF(SUMIF($AC:$AC,$B9,$AI:$AI)=0,"",SUMIF($AC:$AC,$B9,$AI:$AI)),""),IFERROR(_xlfn.XLOOKUP($B9,$T:$T,$Y:$Y),"")) -> 6.6852 | D9: =IF(IFERROR(_xlfn.XLOOKUP($B9,$T:$T,$W:$W),"")="",IFERROR(IF(SUMIF($AC:$AC,$B9,$AG:$AG)=0,"",SUMIF($AC:$AC,$B9,$AG:$AG)),""),IFERROR(_xlfn.XLOOKUP($B9,$T:$T,$W:$W),"")) -> 165 | E9: =IF(IFERROR(_xlfn.XLOOKUP($B9,$T:$T,$X:$X),"")="",IFERROR(IF(SUMIF($AC:$AC,$B9,$AH:$AH)=0,"",SUMIF($AC:$AC,$B9,$AH:$AH)),""),IFERROR(_xlfn.XLOOKUP($B9,$T:$T,$X:$X),"")) -> 107 | F9: =IFERROR(D9/C9,"") -> 24.681386 | H9: ILO-VSA | I9: =IF(IFERROR(_xlfn.XLOOKUP($H9,$T:$T,$Y:$Y),"")="",IFERROR(IF(SUMIF($AC:$AC,$H9,$AI:$AI)=0,"",SUMIF($AC:$AC,$H9,$AI:$AI)),""),IFERROR(_xlfn.XLOOKUP($H9,$T:$T,$Y:$Y),"")) -> 17.5144 | J9: =IF(IFERROR(_xlfn.XLOOKUP($H9,$T:$T,$W:$W),"")="",IFERROR(IF(SUMIF($AC:$AC,$H9,$AG:$AG)=0,"",SUMIF($AC:$AC,$H9,$AG:$AG)),""),IFERROR(_xlfn.XLOOKUP($H9,$T:$T,$W:$W),"")) -> 359 | K9: =IF(IFERROR(_xlfn.XLOOKUP($H9,$T:$T,$X:$X),"")="",IFERROR(IF(SUMIF($AC:$AC,$H9,$AH:$AH)=0,"",SUMIF($AC:$AC,$H9,$AH:$AH)),""),IFERROR(_xlfn.XLOOKUP($H9,$T:$T,$X:$X),"")) -> 63 | L9: =IFERROR(J9/I9,"") -> 20.497419 | N9: BTG-VSA | O9: =IF(IFERROR(_xlfn.XLOOKUP($N9,$T:$T,$Y:$Y),"")="",IFERROR(IF(SUMIF($AC:$AC,$N9,$AI:$AI)=0,"",SUMIF($AC:$AC,$N9,$AI:$AI)),""),IFERROR(_xlfn.XLOOKUP($N9,$T:$T,$Y:$Y),"")) -> 1.5139 | P9: =IF(IFERROR(_xlfn.XLOOKUP($N9,$T:$T,$W:$W),"")="",IFERROR(IF(SUMIF($AC:$AC,$N9,$AG:$AG)=0,"",SUMIF($AC:$AC,$N9,$AG:$AG)),""),IFERROR(_xlfn.XLOOKUP($N9,$T:$T,$W:$W),"")) -> 23 | Q9: =IF(IFERROR(_xlfn.XLOOKUP($N9,$T:$T,$X:$X),"")="",IFERROR(IF(SUMIF($AC:$AC,$N9,$AH:$AH)=0,"",SUMIF($AC:$AC,$N9,$AH:$AH)),""),IFERROR(_xlfn.XLOOKUP($N9,$T:$T,$X:$X),"")) -> 3 | R9: =IFERROR(P9/O9,"") -> 15.192549 | T9: =_xlfn.CONCAT(U9,"-",V9) -> BTG-PCAH | U9: BTG | V9: PCAH | W9: 446 | X9: 58 | Y9: 38.6792 | Z9: 11.530745 | AA9: 1.499514 | AC9: =_xlfn.CONCAT(AD9,"-",AE9) -> BCD-Blank Held | AD9: BCD | AE9: Blank Held | AF9: Ron Jacob Balquin | AG9: 38 | AH9: 31 | AI9: 3.9328 | AJ9: 9.6623271 | AK9: 7.8824247 | AM9: ILO-ARM | AN9: =SUMIF(AC:AC,AM9,AG:AG) -> 376 | AO9: =SUMIF(AC:AC,AM9,AH:AH) -> 43 | AP9: =SUMIF(AC:AC,AM9,AI:AI) -> 24.2567 | AQ9: =AVERAGEIF(AC:AC,AM9,AI:AI) -> 2.6951889 | AR9: =AVERAGEIF(AC:AC,AM9,AJ:AJ) -> 14.594418
B10: BCD-Benver | C10: =IF(IFERROR(_xlfn.XLOOKUP($B10,$T:$T,$Y:$Y),"")="",IFERROR(IF(SUMIF($AC:$AC,$B10,$AI:$AI)=0,"",SUMIF($AC:$AC,$B10,$AI:$AI)),""),IFERROR(_xlfn.XLOOKUP($B10,$T:$T,$Y:$Y),"")) | D10: =IF(IFERROR(_xlfn.XLOOKUP($B10,$T:$T,$W:$W),"")="",IFERROR(IF(SUMIF($AC:$AC,$B10,$AG:$AG)=0,"",SUMIF($AC:$AC,$B10,$AG:$AG)),""),IFERROR(_xlfn.XLOOKUP($B10,$T:$T,$W:$W),"")) | E10: =IF(IFERROR(_xlfn.XLOOKUP($B10,$T:$T,$X:$X),"")="",IFERROR(IF(SUMIF($AC:$AC,$B10,$AH:$AH)=0,"",SUMIF($AC:$AC,$B10,$AH:$AH)),""),IFERROR(_xlfn.XLOOKUP($B10,$T:$T,$X:$X),"")) | F10: =IFERROR(D10/C10,"") | H10: ILO-Benver | I10: =IF(IFERROR(_xlfn.XLOOKUP($H10,$T:$T,$Y:$Y),"")="",IFERROR(IF(SUMIF($AC:$AC,$H10,$AI:$AI)=0,"",SUMIF($AC:$AC,$H10,$AI:$AI)),""),IFERROR(_xlfn.XLOOKUP($H10,$T:$T,$Y:$Y),"")) | J10: =IF(IFERROR(_xlfn.XLOOKUP($H10,$T:$T,$W:$W),"")="",IFERROR(IF(SUMIF($AC:$AC,$H10,$AG:$AG)=0,"",SUMIF($AC:$AC,$H10,$AG:$AG)),""),IFERROR(_xlfn.XLOOKUP($H10,$T:$T,$W:$W),"")) | K10: =IF(IFERROR(_xlfn.XLOOKUP($H10,$T:$T,$X:$X),"")="",IFERROR(IF(SUMIF($AC:$AC,$H10,$AH:$AH)=0,"",SUMIF($AC:$AC,$H10,$AH:$AH)),""),IFERROR(_xlfn.XLOOKUP($H10,$T:$T,$X:$X),"")) | L10: =IFERROR(J10/I10,"") | N10: BTG-Benver | O10: =IF(IFERROR(_xlfn.XLOOKUP($N10,$T:$T,$Y:$Y),"")="",IFERROR(IF(SUMIF($AC:$AC,$N10,$AI:$AI)=0,"",SUMIF($AC:$AC,$N10,$AI:$AI)),""),IFERROR(_xlfn.XLOOKUP($N10,$T:$T,$Y:$Y),"")) | P10: =IF(IFERROR(_xlfn.XLOOKUP($N10,$T:$T,$W:$W),"")="",IFERROR(IF(SUMIF($AC:$AC,$N10,$AG:$AG)=0,"",SUMIF($AC:$AC,$N10,$AG:$AG)),""),IFERROR(_xlfn.XLOOKUP($N10,$T:$T,$W:$W),"")) | Q10: =IF(IFERROR(_xlfn.XLOOKUP($N10,$T:$T,$X:$X),"")="",IFERROR(IF(SUMIF($AC:$AC,$N10,$AH:$AH)=0,"",SUMIF($AC:$AC,$N10,$AH:$AH)),""),IFERROR(_xlfn.XLOOKUP($N10,$T:$T,$X:$X),"")) | R10: =IFERROR(P10/O10,"") | T10: =_xlfn.CONCAT(U10,"-",V10) -> BTG-VSA | U10: BTG | V10: VSA | W10: 23 | X10: 3 | Y10: 1.5139 | Z10: 15.192549 | AA10: 1.9816368 | AC10: =_xlfn.CONCAT(AD10,"-",AE10) -> ILO-0 | AD10: ILO | AE10: 0 | AF10: Kirk Daniel Cautivar | AG10: 0 | AH10: 0 | AI10: 0.0256 | AJ10: 0 | AK10: 0 | AM10: ILO-BenVer | AN10: =SUMIF(AC:AC,AM10,AG:AG) -> 0 | AO10: =SUMIF(AC:AC,AM10,AH:AH) -> 0 | AP10: =SUMIF(AC:AC,AM10,AI:AI) -> 0 | AQ10: =AVERAGEIF(AC:AC,AM10,AI:AI) -> #DIV/0! | AR10: =AVERAGEIF(AC:AC,AM10,AJ:AJ) -> #DIV/0!
B11: BCD-Rework | C11: =IF(IFERROR(_xlfn.XLOOKUP($B11,$T:$T,$Y:$Y),"")="",IFERROR(IF(SUMIF($AC:$AC,$B11,$AI:$AI)=0,"",SUMIF($AC:$AC,$B11,$AI:$AI)),""),IFERROR(_xlfn.XLOOKUP($B11,$T:$T,$Y:$Y),"")) | D11: =IF(IFERROR(_xlfn.XLOOKUP($B11,$T:$T,$W:$W),"")="",IFERROR(IF(SUMIF($AC:$AC,$B11,$AG:$AG)=0,"",SUMIF($AC:$AC,$B11,$AG:$AG)),""),IFERROR(_xlfn.XLOOKUP($B11,$T:$T,$W:$W),"")) | E11: =IF(IFERROR(_xlfn.XLOOKUP($B11,$T:$T,$X:$X),"")="",IFERROR(IF(SUMIF($AC:$AC,$B11,$AH:$AH)=0,"",SUMIF($AC:$AC,$B11,$AH:$AH)),""),IFERROR(_xlfn.XLOOKUP($B11,$T:$T,$X:$X),"")) | F11: =IFERROR(D11/C11,"") | H11: ILO-Rework | I11: =IF(IFERROR(_xlfn.XLOOKUP($H11,$T:$T,$Y:$Y),"")="",IFERROR(IF(SUMIF($AC:$AC,$H11,$AI:$AI)=0,"",SUMIF($AC:$AC,$H11,$AI:$AI)),""),IFERROR(_xlfn.XLOOKUP($H11,$T:$T,$Y:$Y),"")) -> 2.145 | J11: =IF(IFERROR(_xlfn.XLOOKUP($H11,$T:$T,$W:$W),"")="",IFERROR(IF(SUMIF($AC:$AC,$H11,$AG:$AG)=0,"",SUMIF($AC:$AC,$H11,$AG:$AG)),""),IFERROR(_xlfn.XLOOKUP($H11,$T:$T,$W:$W),"")) -> 22 | K11: =IF(IFERROR(_xlfn.XLOOKUP($H11,$T:$T,$X:$X),"")="",IFERROR(IF(SUMIF($AC:$AC,$H11,$AH:$AH)=0,"",SUMIF($AC:$AC,$H11,$AH:$AH)),""),IFERROR(_xlfn.XLOOKUP($H11,$T:$T,$X:$X),"")) -> 4 | L11: =IFERROR(J11/I11,"") -> 10.25641 | N11: BTG-Rework | O11: =IF(IFERROR(_xlfn.XLOOKUP($N11,$T:$T,$Y:$Y),"")="",IFERROR(IF(SUMIF($AC:$AC,$N11,$AI:$AI)=0,"",SUMIF($AC:$AC,$N11,$AI:$AI)),""),IFERROR(_xlfn.XLOOKUP($N11,$T:$T,$Y:$Y),"")) | P11: =IF(IFERROR(_xlfn.XLOOKUP($N11,$T:$T,$W:$W),"")="",IFERROR(IF(SUMIF($AC:$AC,$N11,$AG:$AG)=0,"",SUMIF($AC:$AC,$N11,$AG:$AG)),""),IFERROR(_xlfn.XLOOKUP($N11,$T:$T,$W:$W),"")) | Q11: =IF(IFERROR(_xlfn.XLOOKUP($N11,$T:$T,$X:$X),"")="",IFERROR(IF(SUMIF($AC:$AC,$N11,$AH:$AH)=0,"",SUMIF($AC:$AC,$N11,$AH:$AH)),""),IFERROR(_xlfn.XLOOKUP($N11,$T:$T,$X:$X),"")) | R11: =IFERROR(P11/O11,"") | T11: =_xlfn.CONCAT(U11,"-",V11) -> BTG-Doctor Match | U11: BTG | V11: Doctor Match | W11: 67 | X11: 240 | Y11: 36.0406 | Z11: 1.8590146 | AA11: 6.6591566 | AC11: =_xlfn.CONCAT(AD11,"-",AE11) -> ILO-Fax Mapping | AD11: ILO | AE11: Fax Mapping | AF11: Lara De Tomas | AG11: 6 | AH11: 72 | AI11: 3.1106 | AJ11: 1.9288883 | AK11: 23.14666 | AM11: ILO-CDT Review | AN11: =SUMIF(AC:AC,AM11,AG:AG) -> 8 | AO11: =SUMIF(AC:AC,AM11,AH:AH) -> 40 | AP11: =SUMIF(AC:AC,AM11,AI:AI) -> 3.2728 | AQ11: =AVERAGEIF(AC:AC,AM11,AI:AI) -> 3.2728 | AR11: =AVERAGEIF(AC:AC,AM11,AJ:AJ) -> 2.4443901
