Workbook

Sheet Links
A1: Helpdesk: | B1: https://adapthealthhelpdesk.freshservice.com/support/tickets/
B2: https://hbos.freshdesk.com/support/tickets/new
A3: Dashboard | B3: Performance Dashboard (Revised) (google.com)

Sheet SLA
A1: Count of Days Grouping | B1: Column Labels | N1: 45547 | R1: WORKFLOW | S1: RPH | T1: Hrts | U1: Days to Work | V1: FTE | X1: SLA
A2: Row Labels | B2: 3 or less | C2: 4 to 7 | D2: 7 to 10 | E2: 11 to 14 | F2: 15 to 21 | G2: 22 to 30 | H2: 31 to 60 | I2: 61 to 90 | J2: 91 to 120 | K2: 121 to 180 | L2: 181 plus | M2: Grand Total | R2: DCAH | S2: 15 | T2: 1284 | U2: 2 | V2: 80 | X2: 0.61
A3: Audit Only | B3: 4 | C3: 25 | D3: 5 | E3: 24 | F3: 9 | M3: 67 | N3: 0.4328 | R3: PCAH | S3: 15 | T3: 1021 | U3: 4 | V3: 32 | X3: 0.44
A4: Benefit Verification | B4: 7 | M4: 7 | N4: 1 | R4: Confirmed Sales | S4: 20 | T4: 41 | U4: 1 | V4: 5 | X4: 1
A5: Doctor Call | B5: 11 | C5: 6 | E5: 1 | M5: 18 | N5: 0.9444 | R5: Edocument | S5: 17 | T5: 315 | U5: 2 | V5: 20 | X5: 1
A6: Doctor Denied | B6: 1547 | C6: 1604 | D6: 196 | E6: 348 | F6: 304 | G6: 482 | H6: 976 | I6: 701 | J6: 824 | K6: 470 | L6: 1 | M6: 7453 | N6: 0.4228 | R6: Edocument Exceptions List | S6: 17 | T6: 176 | U6: 2 | V6: 11 | X6: 0.946
A7: Doctor Research | B7: 135 | M7: 135 | N7: 1 | R7: Inbound Call | S7: 10 | T7: 0 | X7: 1% Abandoned Rate
A8: Fax Research | B8: 96 | M8: 96 | N8: 1 | R8: DCAH Scrubs | S8: 20 | T8: 25 | U8: 5 | V8: 1 | W8: 1447 | X8: 1
A9: Patient Follow Up Call | B9: 1776 | C9: 636 | D9: 620 | E9: 242 | F9: 378 | G9: 467 | H9: 824 | I9: 554 | J9: 591 | K9: 375 | M9: 6463 | N9: 0.3732 | R9: ARM/FTP | S9: 25 | T9: 145 | U9: 1 | V9: 18 | X9: 0.93
A10: Rework | B10: 213 | C10: 34 | D10: 9 | E10: 1 | F10: 7 | M10: 264 | N10: 0.9356 | R10: VSA | S10: 10 | T10: 20 | U10: 5 | V10: 1 | X10: 1
A11: Rx Chase | B11: 7060 | C11: 3115 | D11: 3065 | E11: 3913 | F11: 5276 | G11: 2592 | H11: 85 | I11: 23 | J11: 13 | K11: 34 | M11: 25176 | N11: 0.4042 | R11: Benver | S11: 25 | T11: 1 | U11: 5 | V11: 0 | X11: 1
A12: Grand Total | B12: 10849 | C12: 5420 | D12: 3895 | E12: 4529 | F12: 5974 | G12: 3541 | H12: 1885 | I12: 1278 | J12: 1428 | K12: 879 | L12: 1 | M12: 39679 | N12: 0.41 | R12: Rework | S12: 15 | T12: 23 | U12: 5 | V12: 1 | X12: 0.94
R13: Aging 180 days | S13: 6 | T13: 27 | U13: 1 | V13: 3 | X13: Friday
R14: Aging 30 days | S14: 15 | T14: 80 | U14: 1 | V14: 10 | X14: Friday
R15: UHC Special Project | S15: 12 | T15: 167 | U15: 3 | V15: 7 | X15: 0.4
A16: Count of Days Grouping | B16: Column Labels | N16: 45547.208 | R16: CDT review | S16: 12 | T16: 0 | U16: 5 | V16: 1 | W16: 93 | X16: 0.73
A17: Row Labels | B17: 3 or less | C17: 4 to 7 | D17: 7 to 10 | E17: 11 to 14 | F17: 15 to 21 | G17: 22 to 30 | H17: 31 to 60 | I17: 61 to 90 | J17: 91 to 120 | K17: 121 to 180 | L17: 181 plus | M17: Grand Total | R17: FaxRes | T17: 160 | U17: 5 | V17: 4 | X17: 1
A18: Audit Only | B18: 4 | C18: 25 | D18: 5 | E18: 24 | F18: 9 | M18: 67 | N18: 0.4328 | R18: DocRes | T18: 40 | U18: 5 | V18: 1 | X18: 1
A19: Benefit Verification | B19: 14 | M19: 14 | N19: 1 | R19: DocMatch | T19: 40 | U19: 5 | V19: 1 | X19: 1
A20: Doctor Call | B20: 9 | C20: 4 | E20: 1 | M20: 14 | N20: 0.9286 | R20: FaxMap | T20: 160 | U20: 5 | V20: 4 | X20: 1 | Y20: AH DIAB pending
A21: Doctor Denied | B21: 1586 | C21: 1608 | D21: 196 | E21: 348 | F21: 304 | G21: 483 | H21: 976 | I21: 701 | J21: 824 | K21: 468 | L21: 1 | M21: 7495 | N21: 0.4262 | R21: FaxReview | T21: 40 | U21: 5 | V21: 1 | X21: 1
A22: Doctor Research | B22: 132 | M22: 132 | N22: 1 | R22: Email/VM Response | T22: 20 | U22: 5 | V22: 0.5
A23: Fax Research | B23: 89 | M23: 89 | N23: 1 | R23: Blank Held | S23: 10 | T23: 39 | U23: 5 | V23: 1 | X23: 1
A24: Patient Follow Up Call | B24: 1853 | C24: 637 | D24: 620 | E24: 243 | F24: 379 | G24: 466 | H24: 824 | I24: 553 | J24: 591 | K24: 374 | M24: 6540 | N24: 0.3807 | R24: VA MCD | S24: 6 | T24: 89 | U24: 1 | V24: 11 | X24: 1
A25: Rework | B25: 220 | C25: 34 | D25: 9 | E25: 1 | F25: 7 | M25: 271 | N25: 0.9373 | R25: TriCare | S25: 20 | T25: 250 | U25: 22 | V25: 1 | X25: 0.6252
A26: Rx Chase | B26: 7362 | C26: 2900 | D26: 2874 | E26: 3480 | F26: 5134 | G26: 2523 | H26: 84 | I26: 25 | J26: 14 | K26: 45 | M26: 24441 | N26: 0.4199 | R26: AtRisk | S26: 20 | T26: 50 | U26: 1 | V26: 6 | X26: Friday
A27: Grand Total | B27: 11269 | C27: 5208 | D27: 3704 | E27: 4097 | F27: 5833 | G27: 3472 | H27: 1884 | I27: 1279 | J27: 1429 | K27: 887 | L27: 1 | M27: 39063 | N27: 0.4218 | R27: Age Resting Orders Review | S27: 15 | T27: 40 | U27: 1 | V27: 5 | X27: 1
A29: Count of Days Grouping | C29: Days Grouping | O29: 45548 | R29: WKS16
A30: Status | B30: SubStatus | C30: 3 or less | D30: 4 to 7 | E30: 7 to 10 | F30: 11 to 14 | G30: 15 to 21 | H30: 22 to 30 | I30: 31 to 60 | J30: 61 to 90 | K30: 91 to 120 | L30: 121 to 180 | M30: 181 plus | N30: Grand Total | O30: SLA | R30: WORKFLOW | S30: RPH | T30: Hrts | U30: Days to Work | V30: FTE | X30: SLA
A31: Audit Only | D31: 29 | E31: 4 | F31: 25 | G31: 9 | N31: 67 | O31: 0 | R31: DCAH | S31: 15 | T31: 1284 | U31: 2 | V31: 80 | X31: 0.57
A32: Benefit Verification | B32: - | C32: 1 | N32: 1 | O32: 1 | R32: PCAH | S32: 15 | T32: 1021 | U32: 4 | V32: 32 | X32: 0.44
A33: Doctor Research | C33: 184 | N33: 184 | O33: 1 | R33: Confirmed Sales | S33: 20 | T33: 41 | U33: 1 | V33: 5 | X33: 1
A34: Fax Research | C34: 5 | N34: 5 | O34: 1 | R34: Edocument | S34: 17 | T34: 315 | U34: 2 | V34: 20 | X34: 0.95
A35: Doctor Call | C35: 5 | N35: 5 | O35: 1 | R35: Edocument Exceptions List | S35: 17 | T35: 176 | U35: 2 | V35: 11
A36: Doctor Denied | C36: 1116 | D36: 1366 | E36: 955 | F36: 330 | G36: 317 | H36: 447 | I36: 1059 | J36: 669 | K36: 839 | L36: 485 | M36: 1 | N36: 7584 | O36: 0.33 | R36: Inbound Call | S36: 10 | T36: 0
A37: Patient Follow Up Call | C37: 1412 | D37: 915 | E37: 869 | F37: 216 | G37: 375 | H37: 473 | I37: 872 | J37: 533 | K37: 595 | L37: 389 | N37: 6649 | O37: 0.35 | R37: DCAH Scrubs | S37: 20 | T37: 25 | U37: 5 | V37: 1 | W37: 1447
A38: Rework | C38: 184 | D38: 74 | E38: 14 | F38: 2 | G38: 7 | H38: 1 | N38: 282 | O38: 0.91 | R38: ARM/FTP | S38: 25 | T38: 145 | U38: 1 | V38: 18 | X38: 0.77
A39: Rx Chase | B39: - | C39: 319 | D39: 109 | E39: 31 | F39: 106 | G39: 263 | H39: 107 | I39: 19 | N39: 954 | O39: 0.45 | R39: VSA | S39: 10 | T39: 20 | U39: 5 | V39: 1 | X39: 1
B40: Call First | C40: 34 | D40: 2 | E40: 3 | F40: 1 | G40: 2 | H40: 4 | N40: 46 | O40: 0.78 | R40: Benver | S40: 25 | T40: 1 | U40: 5 | V40: 0 | X40: 1
B41: EDocument | C41: 800 | D41: 446 | E41: 83 | F41: 8 | G41: 12 | H41: 7 | I41: 1 | N41: 1357 | O41: 0.92 | R41: Rework | S41: 15 | T41: 23 | U41: 5 | V41: 1
...

Sheet reference
A1: DIAB
A5: Callshaper campaign | B5: WORKFLOW | C5: PPH/RPH
A6: AH Diabetic - Parachute | B6: Parachute | C6: RPH
A7: AH Diabetic - VSA | B7: VSA | C7: RPH
A8: AH Diabetic Held - Billtrain | B8: Billtrain | C8: RPH
A9: AH Diabetic Held - BTLOAD | B9: BTLOAD | C9: RPH
A10: AH Diabetic Held - Medical Note | B10: Medical Note | C10: RPH
A11: AH Diabetic Held - Non-Billable | B11: Non-Billable | C11: RPH
A12: AH Diabetic Held - Patient Call | B12: Patient Call | C12: RPH
A13: AH Diabetic Held Aging-Prod | B13: Aging | C13: RPH
A14: AH Diabetic Held – Rework | B14: Rework | C14: RPH

Sheet Campaign Report
A1: Campaign | B1: Agent | C1: Agent Email | D1: Calls | E1: Calls/Hr | F1: Talk | G1: Wrap Up | H1: Conv | I1: Conv % | J1: Conv/Hr | K1: Points | L1: Points/Hr | M1: Logged In | N1: Eff % | O1: AAT | P1: AHT | Q1: ATT | R1: AWT | S1: Administrative | T1: Break | U1: Coaching | V1: Unavailable | W1: QA Score | X1: Scorecards | Y1: Passed | Z1: Auto Fails | AA1: Holds | AB1: Hold | AC1: Hold/Call | AD1: Rings Tot | AE1: Rings Ans | AF1: Rings Decl | AG1: Rings Timeout | AH1: Rings Miss | AI1: Rings Aban | AJ1: Site | AK1: AgentName | AL1: Workflow
A2: AH Diabetic - Parachute | B2: BTG Amiel Maray | C2: amiel.maray@company.com | D2: 59 | E2: 16.809117 | F2: 0.815 | G2: 0.091944444 | H2: 7 | I2: 0.11864407 | J2: 1.994302 | K2: 7 | L2: 1.994302 | M2: 3.51 | N2: 0.23219373 | O2: 2:30 | P2: 0:55 | Q2: 0:49 | R2: 0:05 | S2: 0:00 | T2: 28:43 | U2: 0:00 | V2: 0:00 | W2: 0 | X2: 0 | Y2: 0 | Z2: 0 | AA2: 0 | AB2: 0:00 | AC2: 0:00 | AD2: 0 | AE2: 0 | AF2: 0 | AG2: 0 | AH2: 0 | AI2: 0 | AJ2: =LEFT(B2,3) -> BTG | AK2: =TRIM(RIGHT(B2, LEN(B2)-3)) -> Amiel Maray | AL2: =_xlfn.XLOOKUP(Campaign_Report[[#This Row],[Campaign]],reference!A:A,reference!B:B) -> Parachute
A3: AH Diabetic - Parachute | B3: BTG Christian Navarro | C3: christian.navarro@company.com | D3: 25 | E3: 17.149129 | F3: 0.3239 | G3: 0.048055556 | H3: 0 | I3: 0 | J3: 0 | K3: 0 | L3: 0 | M3: 1.4578 | N3: 0.22218411 | O3: 2:32 | P3: 0:53 | Q3: 0:46 | R3: 0:06 | S3: 0:00 | T3: 7:22 | U3: 0:00 | V3: 0:00 | W3: 0 | X3: 0 | Y3: 0 | Z3: 0 | AA3: 0 | AB3: 0:00 | AC3: 0:00 | AD3: 0 | AE3: 0 | AF3: 0 | AG3: 0 | AH3: 0 | AI3: 0 | AJ3: =LEFT(B3,3) -> BTG | AK3: =TRIM(RIGHT(B3, LEN(B3)-3)) -> Christian Navarro | AL3: =_xlfn.XLOOKUP(Campaign_Report[[#This Row],[Campaign]],reference!A:A,reference!B:B) -> Parachute
A4: AH Diabetic - Parachute | B4: BTG Joy Aguilar | C4: joy.aguilar@company.com | D4: 40 | E4: 12.279355 | F4: 0.5303 | G4: 0.043055556 | H4: 0 | I4: 0 | J4: 0 | K4: 0 | L4: 0 | M4: 3.2575 | N4: 0.16279355 | O4: 3:45 | P4: 0:51 | Q4: 0:47 | R4: 0:03 | S4: 0:00 | T4: 43:08 | U4: 0:00 | V4: 0:00 | W4: 0 | X4: 0 | Y4: 0 | Z4: 0 | AA4: 0 | AB4: 0:00 | AC4: 0:00 | AD4: 0 | AE4: 0 | AF4: 0 | AG4: 0 | AH4: 0 | AI4: 0 | AJ4: =LEFT(B4,3) -> BTG | AK4: =TRIM(RIGHT(B4, LEN(B4)-3)) -> Joy Aguilar | AL4: =_xlfn.XLOOKUP(Campaign_Report[[#This Row],[Campaign]],reference!A:A,reference!B:B) -> Parachute
A5: AH Diabetic - Parachute | B5: BTG Marinel Mendoza | C5: marinel.mendoza@company.com | D5: 49 | E5: 15.63148 | F5: 0.4956 | G5: 0.057222222 | H5: 2 | I5: 0.040816327 | J5: 0.63801959 | K5: 2 | L5: 0.63801959 | M5: 3.1347 | N5: 0.15810125 | O5: 3:02 | P5: 0:40 | Q5: 0:36 | R5: 0:04 | S5: 0:00 | T5: 51:40 | U5: 0:00 | V5: 0:00 | W5: 0 | X5: 0 | Y5: 0 | Z5: 0 | AA5: 0 | AB5: 0:00 | AC5: 0:00 | AD5: 0 | AE5: 0 | AF5: 0 | AG5: 0 | AH5: 0 | AI5: 0 | AJ5: =LEFT(B5,3) -> BTG | AK5: =TRIM(RIGHT(B5, LEN(B5)-3)) -> Marinel Mendoza | AL5: =_xlfn.XLOOKUP(Campaign_Report[[#This Row],[Campaign]],reference!A:A,reference!B:B) -> Parachute
A6: AH Diabetic - Parachute | B6: BTG Mark Jericho Postilos | C6: mark.postilos@company.com | D6: 62 | E6: 18.117001 | F6: 0.6031 | G6: 0.071111111 | H6: 0 | I6: 0 | J6: 0 | K6: 0 | L6: 0 | M6: 3.4222 | N6: 0.17623166 | O6: 2:30 | P6: 0:39 | Q6: 0:35 | R6: 0:04 | S6: 0:00 | T6: 33:57 | U6: 0:00 | V6: 0:00 | W6: 0 | X6: 0 | Y6: 0 | Z6: 0 | AA6: 0 | AB6: 0:00 | AC6: 0:00 | AD6: 0 | AE6: 0 | AF6: 0 | AG6: 0 | AH6: 0 | AI6: 0 | AJ6: =LEFT(B6,3) -> BTG | AK6: =TRIM(RIGHT(B6, LEN(B6)-3)) -> Mark Jericho Postilos | AL6: =_xlfn.XLOOKUP(Campaign_Report[[#This Row],[Campaign]],reference!A:A,reference!B:B) -> Parachute
A7: AH Diabetic - Parachute | B7: BTG Michael Mike Capili | C7: michael.capili@company.com | D7: 71 | E7: 20.726296 | F7: 0.7189 | G7: 0.062777778 | H7: 0 | I7: 0 | J7: 0 | K7: 0 | L7: 0 | M7: 3.4256 | N7: 0.20986105 | O7: 2:09 | P7: 0:39 | Q7: 0:36 | R7: 0:03 | S7: 0:00 | T7: 29:51 | U7: 0:00 | V7: 0:00 | W7: 0 | X7: 0 | Y7: 0 | Z7: 0 | AA7: 0 | AB7: 0:00 | AC7: 0:00 | AD7: 0 | AE7: 0 | AF7: 0 | AG7: 0 | AH7: 0 | AI7: 0 | AJ7: =LEFT(B7,3) -> BTG | AK7: =TRIM(RIGHT(B7, LEN(B7)-3)) -> Michael Mike Capili | AL7: =_xlfn.XLOOKUP(Campaign_Report[[#This Row],[Campaign]],reference!A:A,reference!B:B) -> Parachute
A8: AH Diabetic - Parachute | B8: BTG Rhey Asicate | C8: rhey.asicate@company.com | D8: 53 | E8: 15.503422 | F8: 0.7947 | G8: 0.22055556 | H8: 3 | I8: 0.056603774 | J8: 0.87755221 | K8: 3 | L8: 0.87755221 | M8: 3.4186 | N8: 0.23246358 | O8: 2:34 | P8: 1:08 | Q8: 0:53 | R8: 0:14 | S8: 0:00 | T8: 34:16 | U8: 0:00 | V8: 0:00 | W8: 0 | X8: 0 | Y8: 0 | Z8: 0 | AA8: 0 | AB8: 0:00 | AC8: 0:00 | AD8: 0 | AE8: 0 | AF8: 0 | AG8: 0 | AH8: 0 | AI8: 0 | AJ8: =LEFT(B8,3) -> BTG | AK8: =TRIM(RIGHT(B8, LEN(B8)-3)) -> Rhey Asicate | AL8: =_xlfn.XLOOKUP(Campaign_Report[[#This Row],[Campaign]],reference!A:A,reference!B:B) -> Parachute
A9: AH Diabetic - VSA | B9: ILO Anthony Escoyala | C9: anthony.escoyala@company.com | D9: 12 | E9: 4.4536817 | F9: 0.0319 | G9: 0.015277778 | H9: 7 | I9: 0.58333333 | J9: 2.597981 | K9: 9 | L9: 3.3402613 | M9: 2.6944 | N9: 0.011839371 | O9: 13:02 | P9: 0:14 | Q9: 0:09 | R9: 0:04 | S9: 0:00 | T9: 45:16 | U9: 0:00 | V9: 0:00 | W9: 0 | X9: 0 | Y9: 0 | Z9: 0 | AA9: 0 | AB9: 0:00 | AC9: 0:00 | AD9: 0 | AE9: 0 | AF9: 0 | AG9: 0 | AH9: 0 | AI9: 0 | AJ9: =LEFT(B9,3) -> ILO | AK9: =TRIM(RIGHT(B9, LEN(B9)-3)) -> Anthony Escoyala | AL9: =_xlfn.XLOOKUP(Campaign_Report[[#This Row],[Campaign]],reference!A:A,reference!B:B) -> VSA
A10: AH Diabetic - VSA | B10: ILO Jackie Bacting | C10: jackie.bacting@company.com | D10: 3 | E10: 1.2302141 | F10: 0.0008 | G10: 0.025277778 | H10: 1 | I10: 0.33333333 | J10: 0.41007135 | K10: 1 | L10: 0.41007135 | M10: 2.4386 | N10: 0.00032805708 | O10: 47:31 | P10: 0:31 | Q10: 0:01 | R10: 0:30 | S10: 0:00 | T10: 47:24 | U10: 0:00 | V10: 0:00 | W10: 0 | X10: 0 | Y10: 0 | Z10: 0 | AA10: 0 | AB10: 0:00 | AC10: 0:00 | AD10: 0 | AE10: 0 | AF10: 0 | AG10: 0 | AH10: 0 | AI10: 0 | AJ10: =LEFT(B10,3) -> ILO | AK10: =TRIM(RIGHT(B10, LEN(B10)-3)) -> Jackie Bacting | AL10: =_xlfn.XLOOKUP(Campaign_Report[[#This Row],[Campaign]],reference!A:A,reference!B:B) -> VSA
A11: AH Diabetic - VSA | B11: ILO Precy Mae Jaruda | C11: precy.jaruda@company.com | D11: 3 | E11: 1.0533338 | F11: 0.0153 | G11: 0.022222222 | H11: 0 | I11: 0 | J11: 0 | K11: 0 | L11: 0 | M11: 2.8481 | N11: 0.0053720024 | O11: 55:11 | P11: 0:45 | Q11: 0:18 | R11: 0:26 | S11: 0:00 | T11: 35:25 | U11: 0:00 | V11: 0:00 | W11: 0 | X11: 0 | Y11: 0 | Z11: 0 | AA11: 0 | AB11: 0:00 | AC11: 0:00 | AD11: 0 | AE11: 0 | AF11: 0 | AG11: 0 | AH11: 0 | AI11: 0 | AJ11: =LEFT(B11,3) -> ILO | AK11: =TRIM(RIGHT(B11, LEN(B11)-3)) -> Precy Mae Jaruda | AL11: =_xlfn.XLOOKUP(Campaign_Report[[#This Row],[Campaign]],reference!A:A,reference!B:B) -> VSA
A12: AH Diabetic - VSA | B12: ILO Reyna Mae Torado | C12: reyna.torado@company.com | D12: 5 | E12: 1.4904462 | F12: 0.0117 | G12: 0.0072222222 | H12: 0 | I12: 0 | J12: 0 | K12: 0 | L12: 0 | M12: 3.3547 | N12: 0.0034876442 | O12: 39:35 | P12: 0:13 | Q12: 0:08 | R12: 0:05 | S12: 0:00 | T12: 5:31 | U12: 0:00 | V12: 0:00 | W12: 0 | X12: 0 | Y12: 0 | Z12: 0 | AA12: 0 | AB12: 0:00 | AC12: 0:00 | AD12: 0 | AE12: 0 | AF12: 0 | AG12: 0 | AH12: 0 | AI12: 0 | AJ12: =LEFT(B12,3) -> ILO | AK12: =TRIM(RIGHT(B12, LEN(B12)-3)) -> Reyna Mae Torado | AL12: =_xlfn.XLOOKUP(Campaign_Report[[#This Row],[Campaign]],reference!A:A,reference!B:B) -> VSA
A13: AH Diabetic - VSA | B13: ILO Jeboy Castanaday | C13: jeboy.castanaday@company.com | D13: 5 | E13: 1.9251502 | F13: 0.0328 | G13: 0.0025 | H13: 0 | I13: 0 | J13: 0 | K13: 1 | L13: 0.38503003 | M13: 2.5972 | N13: 0.012628985 | O13: 30:26 | P13: 0:25 | Q13: 0:23 | R13: 0:01 | S13: 0:00 | T13: 50:58 | U13: 0:00 | V13: 0:00 | W13: 0 | X13: 0 | Y13: 0 | Z13: 0 | AA13: 0 | AB13: 0:00 | AC13: 0:00 | AD13: 0 | AE13: 0 | AF13: 0 | AG13: 0 | AH13: 0 | AI13: 0 | AJ13: =LEFT(B13,3) -> ILO | AK13: =TRIM(RIGHT(B13, LEN(B13)-3)) -> Jeboy Castanaday | AL13: =_xlfn.XLOOKUP(Campaign_Report[[#This Row],[Campaign]],reference!A:A,reference!B:B) -> VSA
... A79: AH Diabetic Held – Rework | B79: ILO Bon Mark Gonzales | C79: bon.gonzales@company.com | D79: 17 | E79: 8.9135906 | F79: 1.5947 | G79: 0.10638889 | H79: 0 | I79: 0 | J79: 0 | K79: 0 | L79: 0 | M79: 1.9072 | N79: 0.83614723 | O79: 0:01 | P79: 6:00 | Q79: 5:37 | R79: 0:22 | S79: 0:00 | T79: 53:50 | U79: 0:00 | V79: 0:00 | W79: 0 | X79: 0 | Y79: 0 | Z79: 0 | AA79: 0 | AB79: 0:00 | AC79: 0:00 | AD79: 0 | AE79: 0 | AF79: 0 | AG79: 0 | AH79: 0 | AI79: 0 | AJ79: =LEFT(B79,3) -> ILO | AK79: =TRIM(RIGHT(B79, LEN(B79)-3)) -> Bon Mark Gonzales | AL79: =_xlfn.XLOOKUP(Campaign_Report[[#This Row],[Campaign]],reference!A:A,reference!B:B) -> Rework

Sheet Pivot
A1: BCD | B1: Hours | C1: Completes | D1: Sum of Points | E1: RPH/PPH | G1: ILO | H1: Hours | I1: Completes | J1: Sum of Points | K1: RPH/PPH | M1: BTG | N1: Hours | O1: Completes | P1: Sum of Points | Q1: RPH/PPH | S1: CAMPAIGN BASE | T1: Site | U1: Workflow | V1: Sum of Calls | W1: Sum of Points | X1: Sum of Logged In | Y1: Sum of RPH | Z1: Sum of PPH
A2: BCD-Parachute | B2: =IF(IFERROR(_xlfn.XLOOKUP($A2,$S:$S,$X:$X),"")="",IFERROR(IF(SUMIF(#REF!,$A2,#REF!)=0,"",SUMIF(#REF!,$A2,#REF!)),""),IFERROR(_xlfn.XLOOKUP($A2,$S:$S,$X:$X),"")) | C2: =IF(IFERROR(_xlfn.XLOOKUP($A2,$S:$S,$V:$V),"")="",IFERROR(IF(SUMIF(#REF!,$A2,#REF!)=0,"",SUMIF(#REF!,$A2,#REF!)),""),IFERROR(_xlfn.XLOOKUP($A2,$S:$S,$V:$V),"")) | D2: =IF(IFERROR(_xlfn.XLOOKUP($A2,$S:$S,$W:$W),"")="",IFERROR(IF(SUMIF(#REF!,$A2,#REF!)=0,"",SUMIF(#REF!,$A2,#REF!)),""),IFERROR(_xlfn.XLOOKUP($A2,$S:$S,$W:$W),"")) | E2: =IFERROR(C2/B2,"") | G2: ILO-Parachute | H2: =IF(IFERROR(_xlfn.XLOOKUP($G2,$S:$S,$X:$X),"")="",IFERROR(IF(SUMIF(#REF!,$G2,#REF!)=0,"",SUMIF(#REF!,$G2,#REF!)),""),IFERROR(_xlfn.XLOOKUP($G2,$S:$S,$X:$X),"")) | I2: =IF(IFERROR(_xlfn.XLOOKUP($G2,$S:$S,$V:$V),"")="",IFERROR(IF(SUMIF(#REF!,$G2,#REF!)=0,"",SUMIF(#REF!,$G2,#REF!)),""),IFERROR(_xlfn.XLOOKUP($G2,$S:$S,$V:$V),"")) | J2: =IF(IFERROR(_xlfn.XLOOKUP($G2,$S:$S,$W:$W),"")="",IFERROR(IF(SUMIF(#REF!,$G2,#REF!)=0,"",SUMIF(#REF!,$G2,#REF!)),""),IFERROR(_xlfn.XLOOKUP($G2,$S:$S,$W:$W),"")) | K2: =IFERROR(I2/H2,"") | M2: BTG-Parachute | N2: =IF(IFERROR(_xlfn.XLOOKUP($M2,$S:$S,$X:$X),"")="",IFERROR(IF(SUMIF(#REF!,$M2,#REF!)=0,"",SUMIF(#REF!,$M2,#REF!)),""),IFERROR(_xlfn.XLOOKUP($M2,$S:$S,$X:$X),"")) -> 21.6264 | O2: =IF(IFERROR(_xlfn.XLOOKUP($M2,$S:$S,$V:$V),"")="",IFERROR(IF(SUMIF(#REF!,$M2,#REF!)=0,"",SUMIF(#REF!,$M2,#REF!)),""),IFERROR(_xlfn.XLOOKUP($M2,$S:$S,$V:$V),"")) -> 359 | P2: =IF(IFERROR(_xlfn.XLOOKUP($M2,$S:$S,$W:$W),"")="",IFERROR(IF(SUMIF(#REF!,$M2,#REF!)=0,"",SUMIF(#REF!,$M2,#REF!)),""),IFERROR(_xlfn.XLOOKUP($M2,$S:$S,$W:$W),"")) -> 12 | Q2: =IFERROR(O2/N2,"") -> 16.600081 | S2: =_xlfn.CONCAT(T2,"-",U2) -> BTG-Patient Call | T2: BTG | U2: Patient Call | V2: 346 | W2: 0 | X2: 25.8116 | Y2: 13.404826 | Z2: 0
A3: BCD-VSA | B3: =IF(IFERROR(_xlfn.XLOOKUP($A3,$S:$S,$X:$X),"")="",IFERROR(IF(SUMIF(#REF!,$A3,#REF!)=0,"",SUMIF(#REF!,$A3,#REF!)),""),IFERROR(_xlfn.XLOOKUP($A3,$S:$S,$X:$X),"")) | C3: =IF(IFERROR(_xlfn.XLOOKUP($A3,$S:$S,$V:$V),"")="",IFERROR(IF(SUMIF(#REF!,$A3,#REF!)=0,"",SUMIF(#REF!,$A3,#REF!)),""),IFERROR(_xlfn.XLOOKUP($A3,$S:$S,$V:$V),"")) | D3: =IF(IFERROR(_xlfn.XLOOKUP($A3,$S:$S,$W:$W),"")="",IFERROR(IF(SUMIF(#REF!,$A3,#REF!)=0,"",SUMIF(#REF!,$A3,#REF!)),""),IFERROR(_xlfn.XLOOKUP($A3,$S:$S,$W:$W),"")) | E3: =IFERROR(C3/B3,"") | G3: ILO-VSA | H3: =IF(IFERROR(_xlfn.XLOOKUP($G3,$S:$S,$X:$X),"")="",IFERROR(IF(SUMIF(#REF!,$G3,#REF!)=0,"",SUMIF(#REF!,$G3,#REF!)),""),IFERROR(_xlfn.XLOOKUP($G3,$S:$S,$X:$X),"")) -> 21.9614 | I3: =IF(IFERROR(_xlfn.XLOOKUP($G3,$S:$S,$V:$V),"")="",IFERROR(IF(SUMIF(#REF!,$G3,#REF!)=0,"",SUMIF(#REF!,$G3,#REF!)),""),IFERROR(_xlfn.XLOOKUP($G3,$S:$S,$V:$V),"")) -> 45 | J3: =IF(IFERROR(_xlfn.XLOOKUP($G3,$S:$S,$W:$W),"")="",IFERROR(IF(SUMIF(#REF!,$G3,#REF!)=0,"",SUMIF(#REF!,$G3,#REF!)),""),IFERROR(_xlfn.XLOOKUP($G3,$S:$S,$W:$W),"")) -> 18 | K3: =IFERROR(I3/H3,"") -> 2.0490497 | M3: BTG-VSA | N3: =IF(IFERROR(_xlfn.XLOOKUP($M3,$S:$S,$X:$X),"")="",IFERROR(IF(SUMIF(#REF!,$M3,#REF!)=0,"",SUMIF(#REF!,$M3,#REF!)),""),IFERROR(_xlfn.XLOOKUP($M3,$S:$S,$X:$X),"")) | O3: =IF(IFERROR(_xlfn.XLOOKUP($M3,$S:$S,$V:$V),"")="",IFERROR(IF(SUMIF(#REF!,$M3,#REF!)=0,"",SUMIF(#REF!,$M3,#REF!)),""),IFERROR(_xlfn.XLOOKUP($M3,$S:$S,$V:$V),"")) | P3: =IF(IFERROR(_xlfn.XLOOKUP($M3,$S:$S,$W:$W),"")="",IFERROR(IF(SUMIF(#REF!,$M3,#REF!)=0,"",SUMIF(#REF!,$M3,#REF!)),""),IFERROR(_xlfn.XLOOKUP($M3,$S:$S,$W:$W),"")) | Q3: =IFERROR(O3/N3,"") | S3: =_xlfn.CONCAT(T3,"-",U3) -> BTG-Parachute | T3: BTG | U3: Parachute | V3: 359 | W3: 12 | X3: 21.6264 | Y3: 16.600081 | Z3: 0.55487737
A4: BCD-Billtrain | B4: =IF(IFERROR(_xlfn.XLOOKUP($A4,$S:$S,$X:$X),"")="",IFERROR(IF(SUMIF(#REF!,$A4,#REF!)=0,"",SUMIF(#REF!,$A4,#REF!)),""),IFERROR(_xlfn.XLOOKUP($A4,$S:$S,$X:$X),"")) | C4: =IF(IFERROR(_xlfn.XLOOKUP($A4,$S:$S,$V:$V),"")="",IFERROR(IF(SUMIF(#REF!,$A4,#REF!)=0,"",SUMIF(#REF!,$A4,#REF!)),""),IFERROR(_xlfn.XLOOKUP($A4,$S:$S,$V:$V),"")) | D4: =IF(IFERROR(_xlfn.XLOOKUP($A4,$S:$S,$W:$W),"")="",IFERROR(IF(SUMIF(#REF!,$A4,#REF!)=0,"",SUMIF(#REF!,$A4,#REF!)),""),IFERROR(_xlfn.XLOOKUP($A4,$S:$S,$W:$W),"")) | E4: =IFERROR(C4/B4,"") | G4: ILO-Billtrain | H4: =IF(IFERROR(_xlfn.XLOOKUP($G4,$S:$S,$X:$X),"")="",IFERROR(IF(SUMIF(#REF!,$G4,#REF!)=0,"",SUMIF(#REF!,$G4,#REF!)),""),IFERROR(_xlfn.XLOOKUP($G4,$S:$S,$X:$X),"")) | I4: =IF(IFERROR(_xlfn.XLOOKUP($G4,$S:$S,$V:$V),"")="",IFERROR(IF(SUMIF(#REF!,$G4,#REF!)=0,"",SUMIF(#REF!,$G4,#REF!)),""),IFERROR(_xlfn.XLOOKUP($G4,$S:$S,$V:$V),"")) | J4: =IF(IFERROR(_xlfn.XLOOKUP($G4,$S:$S,$W:$W),"")="",IFERROR(IF(SUMIF(#REF!,$G4,#REF!)=0,"",SUMIF(#REF!,$G4,#REF!)),""),IFERROR(_xlfn.XLOOKUP($G4,$S:$S,$W:$W),"")) | K4: =IFERROR(I4/H4,"") | M4: BTG-Billtrain | N4: =IF(IFERROR(_xlfn.XLOOKUP($M4,$S:$S,$X:$X),"")="",IFERROR(IF(SUMIF(#REF!,$M4,#REF!)=0,"",SUMIF(#REF!,$M4,#REF!)),""),IFERROR(_xlfn.XLOOKUP($M4,$S:$S,$X:$X),"")) | O4: =IF(IFERROR(_xlfn.XLOOKUP($M4,$S:$S,$V:$V),"")="",IFERROR(IF(SUMIF(#REF!,$M4,#REF!)=0,"",SUMIF(#REF!,$M4,#REF!)),""),IFERROR(_xlfn.XLOOKUP($M4,$S:$S,$V:$V),"")) | P4: =IF(IFERROR(_xlfn.XLOOKUP($M4,$S:$S,$W:$W),"")="",IFERROR(IF(SUMIF(#REF!,$M4,#REF!)=0,"",SUMIF(#REF!,$M4,#REF!)),""),IFERROR(_xlfn.XLOOKUP($M4,$S:$S,$W:$W),"")) | Q4: =IFERROR(O4/N4,"") | S4: =_xlfn.CONCAT(T4,"-",U4) -> BTG-BTLOAD | T4: BTG | U4: BTLOAD | V4: 137 | W4: 0 | X4: 14.6793 | Y4: 9.3328701 | Z4: 0
A5: BCD-BTLOAD | B5: =IF(IFERROR(_xlfn.XLOOKUP($A5,$S:$S,$X:$X),"")="",IFERROR(IF(SUMIF(#REF!,$A5,#REF!)=0,"",SUMIF(#REF!,$A5,#REF!)),""),IFERROR(_xlfn.XLOOKUP($A5,$S:$S,$X:$X),"")) | C5: =IF(IFERROR(_xlfn.XLOOKUP($A5,$S:$S,$V:$V),"")="",IFERROR(IF(SUMIF(#REF!,$A5,#REF!)=0,"",SUMIF(#REF!,$A5,#REF!)),""),IFERROR(_xlfn.XLOOKUP($A5,$S:$S,$V:$V),"")) | D5: =IF(IFERROR(_xlfn.XLOOKUP($A5,$S:$S,$W:$W),"")="",IFERROR(IF(SUMIF(#REF!,$A5,#REF!)=0,"",SUMIF(#REF!,$A5,#REF!)),""),IFERROR(_xlfn.XLOOKUP($A5,$S:$S,$W:$W),"")) | E5: =IFERROR(C5/B5,"") | G5: ILO-BTLOAD | H5: =IF(IFERROR(_xlfn.XLOOKUP($G5,$S:$S,$X:$X),"")="",IFERROR(IF(SUMIF(#REF!,$G5,#REF!)=0,"",SUMIF(#REF!,$G5,#REF!)),""),IFERROR(_xlfn.XLOOKUP($G5,$S:$S,$X:$X),"")) -> 16.7278 | I5: =IF(IFERROR(_xlfn.XLOOKUP($G5,$S:$S,$V:$V),"")="",IFERROR(IF(SUMIF(#REF!,$G5,#REF!)=0,"",SUMIF(#REF!,$G5,#REF!)),""),IFERROR(_xlfn.XLOOKUP($G5,$S:$S,$V:$V),"")) -> 217 | J5: =IF(IFERROR(_xlfn.XLOOKUP($G5,$S:$S,$W:$W),"")="",IFERROR(IF(SUMIF(#REF!,$G5,#REF!)=0,"",SUMIF(#REF!,$G5,#REF!)),""),IFERROR(_xlfn.XLOOKUP($G5,$S:$S,$W:$W),"")) -> 0 | K5: =IFERROR(I5/H5,"") -> 12.972417 | M5: BTG-BTLOAD | N5: =IF(IFERROR(_xlfn.XLOOKUP($M5,$S:$S,$X:$X),"")="",IFERROR(IF(SUMIF(#REF!,$M5,#REF!)=0,"",SUMIF(#REF!,$M5,#REF!)),""),IFERROR(_xlfn.XLOOKUP($M5,$S:$S,$X:$X),"")) -> 14.6793 | O5: =IF(IFERROR(_xlfn.XLOOKUP($M5,$S:$S,$V:$V),"")="",IFERROR(IF(SUMIF(#REF!,$M5,#REF!)=0,"",SUMIF(#REF!,$M5,#REF!)),""),IFERROR(_xlfn.XLOOKUP($M5,$S:$S,$V:$V),"")) -> 137 | P5: =IF(IFERROR(_xlfn.XLOOKUP($M5,$S:$S,$W:$W),"")="",IFERROR(IF(SUMIF(#REF!,$M5,#REF!)=0,"",SUMIF(#REF!,$M5,#REF!)),""),IFERROR(_xlfn.XLOOKUP($M5,$S:$S,$W:$W),"")) -> 0 | Q5: =IFERROR(O5/N5,"") -> 9.3328701 | S5: =_xlfn.CONCAT(T5,"-",U5) -> BTG-Non-Billable | T5: BTG | U5: Non-Billable | V5: 0 | W5: 0 | X5: 2.6569 | Y5: 0 | Z5: 0
A6: BCD-Medical Note | B6: =IF(IFERROR(_xlfn.XLOOKUP($A6,$S:$S,$X:$X),"")="",IFERROR(IF(SUMIF(#REF!,$A6,#REF!)=0,"",SUMIF(#REF!,$A6,#REF!)),""),IFERROR(_xlfn.XLOOKUP($A6,$S:$S,$X:$X),"")) | C6: =IF(IFERROR(_xlfn.XLOOKUP($A6,$S:$S,$V:$V),"")="",IFERROR(IF(SUMIF(#REF!,$A6,#REF!)=0,"",SUMIF(#REF!,$A6,#REF!)),""),IFERROR(_xlfn.XLOOKUP($A6,$S:$S,$V:$V),"")) | D6: =IF(IFERROR(_xlfn.XLOOKUP($A6,$S:$S,$W:$W),"")="",IFERROR(IF(SUMIF(#REF!,$A6,#REF!)=0,"",SUMIF(#REF!,$A6,#REF!)),""),IFERROR(_xlfn.XLOOKUP($A6,$S:$S,$W:$W),"")) | E6: =IFERROR(C6/B6,"") | G6: ILO-Medical Note | H6: =IF(IFERROR(_xlfn.XLOOKUP($G6,$S:$S,$X:$X),"")="",IFERROR(IF(SUMIF(#REF!,$G6,#REF!)=0,"",SUMIF(#REF!,$G6,#REF!)),""),IFERROR(_xlfn.XLOOKUP($G6,$S:$S,$X:$X),"")) | I6: =IF(IFERROR(_xlfn.XLOOKUP($G6,$S:$S,$V:$V),"")="",IFERROR(IF(SUMIF(#REF!,$G6,#REF!)=0,"",SUMIF(#REF!,$G6,#REF!)),""),IFERROR(_xlfn.XLOOKUP($G6,$S:$S,$V:$V),"")) | J6: =IF(IFERROR(_xlfn.XLOOKUP($G6,$S:$S,$W:$W),"")="",IFERROR(IF(SUMIF(#REF!,$G6,#REF!)=0,"",SUMIF(#REF!,$G6,#REF!)),""),IFERROR(_xlfn.XLOOKUP($G6,$S:$S,$W:$W),"")) | K6: =IFERROR(I6/H6,"") | M6: BTG-Medical Note | N6: =IF(IFERROR(_xlfn.XLOOKUP($M6,$S:$S,$X:$X),"")="",IFERROR(IF(SUMIF(#REF!,$M6,#REF!)=0,"",SUMIF(#REF!,$M6,#REF!)),""),IFERROR(_xlfn.XLOOKUP($M6,$S:$S,$X:$X),"")) -> 5.48 | O6: =IF(IFERROR(_xlfn.XLOOKUP($M6,$S:$S,$V:$V),"")="",IFERROR(IF(SUMIF(#REF!,$M6,#REF!)=0,"",SUMIF(#REF!,$M6,#REF!)),""),IFERROR(_xlfn.XLOOKUP($M6,$S:$S,$V:$V),"")) -> 51 | P6: =IF(IFERROR(_xlfn.XLOOKUP($M6,$S:$S,$W:$W),"")="",IFERROR(IF(SUMIF(#REF!,$M6,#REF!)=0,"",SUMIF(#REF!,$M6,#REF!)),""),IFERROR(_xlfn.XLOOKUP($M6,$S:$S,$W:$W),"")) -> 0 | Q6: =IFERROR(O6/N6,"") -> 9.3065693 | S6: =_xlfn.CONCAT(T6,"-",U6) -> BTG-Medical Note | T6: BTG | U6: Medical Note | V6: 51 | W6: 0 | X6: 5.48 | Y6: 9.3065693 | Z6: 0
A7: BCD-Non-Billable | B7: =IF(IFERROR(_xlfn.XLOOKUP($A7,$S:$S,$X:$X),"")="",IFERROR(IF(SUMIF(#REF!,$A7,#REF!)=0,"",SUMIF(#REF!,$A7,#REF!)),""),IFERROR(_xlfn.XLOOKUP($A7,$S:$S,$X:$X),"")) | C7: =IF(IFERROR(_xlfn.XLOOKUP($A7,$S:$S,$V:$V),"")="",IFERROR(IF(SUMIF(#REF!,$A7,#REF!)=0,"",SUMIF(#REF!,$A7,#REF!)),""),IFERROR(_xlfn.XLOOKUP($A7,$S:$S,$V:$V),"")) | D7: =IF(IFERROR(_xlfn.XLOOKUP($A7,$S:$S,$W:$W),"")="",IFERROR(IF(SUMIF(#REF!,$A7,#REF!)=0,"",SUMIF(#REF!,$A7,#REF!)),""),IFERROR(_xlfn.XLOOKUP($A7,$S:$S,$W:$W),"")) | E7: =IFERROR(C7/B7,"") | G7: ILO-Non-Billable | H7: =IF(IFERROR(_xlfn.XLOOKUP($G7,$S:$S,$X:$X),"")="",IFERROR(IF(SUMIF(#REF!,$G7,#REF!)=0,"",SUMIF(#REF!,$G7,#REF!)),""),IFERROR(_xlfn.XLOOKUP($G7,$S:$S,$X:$X),"")) -> 22.7259 | I7: =IF(IFERROR(_xlfn.XLOOKUP($G7,$S:$S,$V:$V),"")="",IFERROR(IF(SUMIF(#REF!,$G7,#REF!)=0,"",SUMIF(#REF!,$G7,#REF!)),""),IFERROR(_xlfn.XLOOKUP($G7,$S:$S,$V:$V),"")) -> 0 | J7: =IF(IFERROR(_xlfn.XLOOKUP($G7,$S:$S,$W:$W),"")="",IFERROR(IF(SUMIF(#REF!,$G7,#REF!)=0,"",SUMIF(#REF!,$G7,#REF!)),""),IFERROR(_xlfn.XLOOKUP($G7,$S:$S,$W:$W),"")) -> 0 | K7: =IFERROR(I7/H7,"") -> 0 | M7: BTG-Non-Billable | N7: =IF(IFERROR(_xlfn.XLOOKUP($M7,$S:$S,$X:$X),"")="",IFERROR(IF(SUMIF(#REF!,$M7,#REF!)=0,"",SUMIF(#REF!,$M7,#REF!)),""),IFERROR(_xlfn.XLOOKUP($M7,$S:$S,$X:$X),"")) -> 2.6569 | O7: =IF(IFERROR(_xlfn.XLOOKUP($M7,$S:$S,$V:$V),"")="",IFERROR(IF(SUMIF(#REF!,$M7,#REF!)=0,"",SUMIF(#REF!,$M7,#REF!)),""),IFERROR(_xlfn.XLOOKUP($M7,$S:$S,$V:$V),"")) -> 0 | P7: =IF(IFERROR(_xlfn.XLOOKUP($M7,$S:$S,$W:$W),"")="",IFERROR(IF(SUMIF(#REF!,$M7,#REF!)=0,"",SUMIF(#REF!,$M7,#REF!)),""),IFERROR(_xlfn.XLOOKUP($M7,$S:$S,$W:$W),"")) -> 0 | Q7: =IFERROR(O7/N7,"") -> 0 | S7: =_xlfn.CONCAT(T7,"-",U7) -> ILO-Rework | T7: ILO | U7: Rework | V7: 63 | W7: 0 | X7: 6.6064 | Y7: 9.5362073 | Z7: 0
A8: BCD-Patient Call | B8: =IF(IFERROR(_xlfn.XLOOKUP($A8,$S:$S,$X:$X),"")="",IFERROR(IF(SUMIF(#REF!,$A8,#REF!)=0,"",SUMIF(#REF!,$A8,#REF!)),""),IFERROR(_xlfn.XLOOKUP($A8,$S:$S,$X:$X),"")) | C8: =IF(IFERROR(_xlfn.XLOOKUP($A8,$S:$S,$V:$V),"")="",IFERROR(IF(SUMIF(#REF!,$A8,#REF!)=0,"",SUMIF(#REF!,$A8,#REF!)),""),IFERROR(_xlfn.XLOOKUP($A8,$S:$S,$V:$V),"")) | D8: =IF(IFERROR(_xlfn.XLOOKUP($A8,$S:$S,$W:$W),"")="",IFERROR(IF(SUMIF(#REF!,$A8,#REF!)=0,"",SUMIF(#REF!,$A8,#REF!)),""),IFERROR(_xlfn.XLOOKUP($A8,$S:$S,$W:$W),"")) | E8: =IFERROR(C8/B8,"") | G8: ILO-Patient Call | H8: =IF(IFERROR(_xlfn.XLOOKUP($G8,$S:$S,$X:$X),"")="",IFERROR(IF(SUMIF(#REF!,$G8,#REF!)=0,"",SUMIF(#REF!,$G8,#REF!)),""),IFERROR(_xlfn.XLOOKUP($G8,$S:$S,$X:$X),"")) -> 0.0011 | I8: =IF(IFERROR(_xlfn.XLOOKUP($G8,$S:$S,$V:$V),"")="",IFERROR(IF(SUMIF(#REF!,$G8,#REF!)=0,"",SUMIF(#REF!,$G8,#REF!)),""),IFERROR(_xlfn.XLOOKUP($G8,$S:$S,$V:$V),"")) -> 0 | J8: =IF(IFERROR(_xlfn.XLOOKUP($G8,$S:$S,$W:$W),"")="",IFERROR(IF(SUMIF(#REF!,$G8,#REF!)=0,"",SUMIF(#REF!,$G8,#REF!)),""),IFERROR(_xlfn.XLOOKUP($G8,$S:$S,$W:$W),"")) -> 0 | K8: =IFERROR(I8/H8,"") -> 0 | M8: BTG-Patient Call | N8: =IF(IFERROR(_xlfn.XLOOKUP($M8,$S:$S,$X:$X),"")="",IFERROR(IF(SUMIF(#REF!,$M8,#REF!)=0,"",SUMIF(#REF!,$M8,#REF!)),""),IFERROR(_xlfn.XLOOKUP($M8,$S:$S,$X:$X),"")) -> 25.8116 | O8: =IF(IFERROR(_xlfn.XLOOKUP($M8,$S:$S,$V:$V),"")="",IFERROR(IF(SUMIF(#REF!,$M8,#REF!)=0,"",SUMIF(#REF!,$M8,#REF!)),""),IFERROR(_xlfn.XLOOKUP($M8,$S:$S,$V:$V),"")) -> 346 | P8: =IF(IFERROR(_xlfn.XLOOKUP($M8,$S:$S,$W:$W),"")="",IFERROR(IF(SUMIF(#REF!,$M8,#REF!)=0,"",SUMIF(#REF!,$M8,#REF!)),""),IFERROR(_xlfn.XLOOKUP($M8,$S:$S,$W:$W),"")) -> 0 | Q8: =IFERROR(O8/N8,"") -> 13.404826 | S8: =_xlfn.CONCAT(T8,"-",U8) -> ILO-VSA | T8: ILO | U8: VSA | V8: 45 | W8: 18 | X8: 21.9614 | Y8: 2.0490497 | Z8: 0.81961988
A9: BCD-Aging | B9: =IF(IFERROR(_xlfn.XLOOKUP($A9,$S:$S,$X:$X),"")="",IFERROR(IF(SUMIF(#REF!,$A9,#REF!)=0,"",SUMIF(#REF!,$A9,#REF!)),""),IFERROR(_xlfn.XLOOKUP($A9,$S:$S,$X:$X),"")) | C9: =IF(IFERROR(_xlfn.XLOOKUP($A9,$S:$S,$V:$V),"")="",IFERROR(IF(SUMIF(#REF!,$A9,#REF!)=0,"",SUMIF(#REF!,$A9,#REF!)),""),IFERROR(_xlfn.XLOOKUP($A9,$S:$S,$V:$V),"")) | D9: =IF(IFERROR(_xlfn.XLOOKUP($A9,$S:$S,$W:$W),"")="",IFERROR(IF(SUMIF(#REF!,$A9,#REF!)=0,"",SUMIF(#REF!,$A9,#REF!)),""),IFERROR(_xlfn.XLOOKUP($A9,$S:$S,$W:$W),"")) | E9: =IFERROR(C9/B9,"") | G9: ILO-Aging | H9: =IF(IFERROR(_xlfn.XLOOKUP($G9,$S:$S,$X:$X),"")="",IFERROR(IF(SUMIF(#REF!,$G9,#REF!)=0,"",SUMIF(#REF!,$G9,#REF!)),""),IFERROR(_xlfn.XLOOKUP($G9,$S:$S,$X:$X),"")) | I9: =IF(IFERROR(_xlfn.XLOOKUP($G9,$S:$S,$V:$V),"")="",IFERROR(IF(SUMIF(#REF!,$G9,#REF!)=0,"",SUMIF(#REF!,$G9,#REF!)),""),IFERROR(_xlfn.XLOOKUP($G9,$S:$S,$V:$V),"")) | J9: =IF(IFERROR(_xlfn.XLOOKUP($G9,$S:$S,$W:$W),"")="",IFERROR(IF(SUMIF(#REF!,$G9,#REF!)=0,"",SUMIF(#REF!,$G9,#REF!)),""),IFERROR(_xlfn.XLOOKUP($G9,$S:$S,$W:$W),"")) | K9: =IFERROR(I9/H9,"") | M9: BTG-Aging | N9: =IF(IFERROR(_xlfn.XLOOKUP($M9,$S:$S,$X:$X),"")="",IFERROR(IF(SUMIF(#REF!,$M9,#REF!)=0,"",SUMIF(#REF!,$M9,#REF!)),""),IFERROR(_xlfn.XLOOKUP($M9,$S:$S,$X:$X),"")) | O9: =IF(IFERROR(_xlfn.XLOOKUP($M9,$S:$S,$V:$V),"")="",IFERROR(IF(SUMIF(#REF!,$M9,#REF!)=0,"",SUMIF(#REF!,$M9,#REF!)),""),IFERROR(_xlfn.XLOOKUP($M9,$S:$S,$V:$V),"")) | P9: =IF(IFERROR(_xlfn.XLOOKUP($M9,$S:$S,$W:$W),"")="",IFERROR(IF(SUMIF(#REF!,$M9,#REF!)=0,"",SUMIF(#REF!,$M9,#REF!)),""),IFERROR(_xlfn.XLOOKUP($M9,$S:$S,$W:$W),"")) | Q9: =IFERROR(O9/N9,"") | S9: =_xlfn.CONCAT(T9,"-",U9) -> ILO-Patient Call | T9: ILO | U9: Patient Call | V9: 0 | W9: 0 | X9: 0.0011 | Y9: 0 | Z9: 0
A10: BCD-Rework | B10: =IF(IFERROR(_xlfn.XLOOKUP($A10,$S:$S,$X:$X),"")="",IFERROR(IF(SUMIF(#REF!,$A10,#REF!)=0,"",SUMIF(#REF!,$A10,#REF!)),""),IFERROR(_xlfn.XLOOKUP($A10,$S:$S,$X:$X),"")) | C10: =IF(IFERROR(_xlfn.XLOOKUP($A10,$S:$S,$V:$V),"")="",IFERROR(IF(SUMIF(#REF!,$A10,#REF!)=0,"",SUMIF(#REF!,$A10,#REF!)),""),IFERROR(_xlfn.XLOOKUP($A10,$S:$S,$V:$V),"")) | D10: =IF(IFERROR(_xlfn.XLOOKUP($A10,$S:$S,$W:$W),"")="",IFERROR(IF(SUMIF(#REF!,$A10,#REF!)=0,"",SUMIF(#REF!,$A10,#REF!)),""),IFERROR(_xlfn.XLOOKUP($A10,$S:$S,$W:$W),"")) | E10: =IFERROR(C10/B10,"") | G10: ILO-Rework | H10: =IF(IFERROR(_xlfn.XLOOKUP($G10,$S:$S,$X:$X),"")="",IFERROR(IF(SUMIF(#REF!,$G10,#REF!)=0,"",SUMIF(#REF!,$G10,#REF!)),""),IFERROR(_xlfn.XLOOKUP($G10,$S:$S,$X:$X),"")) -> 6.6064 | I10: =IF(IFERROR(_xlfn.XLOOKUP($G10,$S:$S,$V:$V),"")="",IFERROR(IF(SUMIF(#REF!,$G10,#REF!)=0,"",SUMIF(#REF!,$G10,#REF!)),""),IFERROR(_xlfn.XLOOKUP($G10,$S:$S,$V:$V),"")) -> 63 | J10: =IF(IFERROR(_xlfn.XLOOKUP($G10,$S:$S,$W:$W),"")="",IFERROR(IF(SUMIF(#REF!,$G10,#REF!)=0,"",SUMIF(#REF!,$G10,#REF!)),""),IFERROR(_xlfn.XLOOKUP($G10,$S:$S,$W:$W),"")) -> 0 | K10: =IFERROR(I10/H10,"") -> 9.5362073 | M10: BTG-Rework | N10: =IF(IFERROR(_xlfn.XLOOKUP($M10,$S:$S,$X:$X),"")="",IFERROR(IF(SUMIF(#REF!,$M10,#REF!)=0,"",SUMIF(#REF!,$M10,#REF!)),""),IFERROR(_xlfn.XLOOKUP($M10,$S:$S,$X:$X),"")) | O10: =IF(IFERROR(_xlfn.XLOOKUP($M10,$S:$S,$V:$V),"")="",IFERROR(IF(SUMIF(#REF!,$M10,#REF!)=0,"",SUMIF(#REF!,$M10,#REF!)),""),IFERROR(_xlfn.XLOOKUP($M10,$S:$S,$V:$V),"")) | P10: =IF(IFERROR(_xlfn.XLOOKUP($M10,$S:$S,$W:$W),"")="",IFERROR(IF(SUMIF(#REF!,$M10,#REF!)=0,"",SUMIF(#REF!,$M10,#REF!)),""),IFERROR(_xlfn.XLOOKUP($M10,$S:$S,$W:$W),"")) | Q10: =IFERROR(O10/N10,"") | S10: =_xlfn.CONCAT(T10,"-",U10) -> ILO-BTLOAD | T10: ILO | U10: BTLOAD | V10: 217 | W10: 0 | X10: 16.7278 | Y10: 12.972417 | Z10: 0
A11: BCD- | B11: =IF(IFERROR(_xlfn.XLOOKUP($A11,$S:$S,$X:$X),"")="",IFERROR(IF(SUMIF(#REF!,$A11,#REF!)=0,"",SUMIF(#REF!,$A11,#REF!)),""),IFERROR(_xlfn.XLOOKUP($A11,$S:$S,$X:$X),"")) | C11: =IF(IFERROR(_xlfn.XLOOKUP($A11,$S:$S,$V:$V),"")="",IFERROR(IF(SUMIF(#REF!,$A11,#REF!)=0,"",SUMIF(#REF!,$A11,#REF!)),""),IFERROR(_xlfn.XLOOKUP($A11,$S:$S,$V:$V),"")) | D11: =IF(IFERROR(_xlfn.XLOOKUP($A11,$S:$S,$W:$W),"")="",IFERROR(IF(SUMIF(#REF!,$A11,#REF!)=0,"",SUMIF(#REF!,$A11,#REF!)),""),IFERROR(_xlfn.XLOOKUP($A11,$S:$S,$W:$W),"")) | E11: =IFERROR(C11/B11,"") | G11: ILO- | H11: =IF(IFERROR(_xlfn.XLOOKUP($G11,$S:$S,$X:$X),"")="",IFERROR(IF(SUMIF(#REF!,$G11,#REF!)=0,"",SUMIF(#REF!,$G11,#REF!)),""),IFERROR(_xlfn.XLOOKUP($G11,$S:$S,$X:$X),"")) | I11: =IF(IFERROR(_xlfn.XLOOKUP($G11,$S:$S,$V:$V),"")="",IFERROR(IF(SUMIF(#REF!,$G11,#REF!)=0,"",SUMIF(#REF!,$G11,#REF!)),""),IFERROR(_xlfn.XLOOKUP($G11,$S:$S,$V:$V),"")) | J11: =IF(IFERROR(_xlfn.XLOOKUP($G11,$S:$S,$W:$W),"")="",IFERROR(IF(SUMIF(#REF!,$G11,#REF!)=0,"",SUMIF(#REF!,$G11,#REF!)),""),IFERROR(_xlfn.XLOOKUP($G11,$S:$S,$W:$W),"")) | K11: =IFERROR(I11/H11,"") | M11: BTG- | N11: =IF(IFERROR(_xlfn.XLOOKUP($M11,$S:$S,$X:$X),"")="",IFERROR(IF(SUMIF(#REF!,$M11,#REF!)=0,"",SUMIF(#REF!,$M11,#REF!)),""),IFERROR(_xlfn.XLOOKUP($M11,$S:$S,$X:$X),"")) | O11: =IF(IFERROR(_xlfn.XLOOKUP($M11,$S:$S,$V:$V),"")="",IFERROR(IF(SUMIF(#REF!,$M11,#REF!)=0,"",SUMIF(#REF!,$M11,#REF!)),""),IFERROR(_xlfn.XLOOKUP($M11,$S:$S,$V:$V),"")) | P11: =IF(IFERROR(_xlfn.XLOOKUP($M11,$S:$S,$W:$W),"")="",IFERROR(IF(SUMIF(#REF!,$M11,#REF!)=0,"",SUMIF(#REF!,$M11,#REF!)),""),IFERROR(_xlfn.XLOOKUP($M11,$S:$S,$W:$W),"")) | Q11: =IFERROR(O11/N11,"") | S11: =_xlfn.CONCAT(T11,"-",U11) -> ILO-Non-Billable | T11: ILO | U11: Non-Billable | V11: 0 | W11: 0 | X11: 22.7259 | Y11: 0 | Z11: 0
S12: =_xlfn.CONCAT(T12,"-",U12) -> OTG-BTLOAD | T12: OTG | U12: BTLOAD | V12: 0 | W12: 0 | X12: 0.0569 | Y12: 0 | Z12: 0
S13: =_xlfn.CONCAT(T13,"-",U13) -> Grand Total- | T13: Grand Total | V13: 1218 | W13: 30 | X13: 138.3337 | Y13: 8.8047959 | Z13: 0.2168669
S14: =_xlfn.CONCAT(T14,"-",U14) -> -
S15: =_xlfn.CONCAT(T15,"-",U15) -> -
S16: =_xlfn.CONCAT(T16,"-",U16) -> -
S17: =_xlfn.CONCAT(T17,"-",U17) -> -
S18: =_xlfn.CONCAT(T18,"-",U18) -> -
S19: =_xlfn.CONCAT(T19,"-",U19) -> -
S20: =_xlfn.CONCAT(T20,"-",U20) -> -
S21: =_xlfn.CONCAT(T21,"-",U21) -> -
S22: =_xlfn.CONCAT(T22,"-",U22) -> -
S23: =_xlfn.CONCAT(T23,"-",U23) -> -
S24: =_xlfn.CONCAT(T24,"-",U24) -> -
S25: =_xlfn.CONCAT(T25,"-",U25) -> -
... S35: =_xlfn.CONCAT(T35,"-",U35) -> -

Sheet Completion
A1: OVERALL
A2: Campaign | B2: RECORDS ASSIGNED | C2: Headcount Assigned | D2: Hours Assigned | E2: Actual Log in hours | F2: RECORDS COMPLETED | G2: RECORDS REMAINING | H2: COMPLETION RATE | I2: RPH GOAL | J2: Sum of Points | K2: ACTUAL RPH/PPH | L2: HOURS NEEDED TO COMPLETE | M2: HC NEEDED TO COMPLETE | N2: SLA %
A3: Parachute | B3: =C3*I3*8 -> 0 | E3: =IF(SUM(E17,E31,E45)=0,"",SUM(E17,E31,E45)) -> 21.6264 | F3: =IF(SUM(F17,F31,F45)=0,"",SUM(F17,F31,F45)) -> 359 | G3: =IFERROR(B3-F3,"") -> -359 | H3: =IFERROR(F3/B3,"") | J3: =IF(SUM(J17,J31,J45)=0,"",SUM(J17,J31,J45)) -> 12 | K3: =IFERROR(F3/E3,"") -> 16.600081 | L3: =IFERROR(G3/K3,"") -> -21.6264 | M3: =IFERROR(L3/8,"") -> -2.7033
A4: VSA | B4: =C4*I4*8 -> 0 | E4: =IF(SUM(E18,E32,E46)=0,"",SUM(E18,E32,E46)) -> 21.9614 | F4: =IF(SUM(F18,F32,F46)=0,"",SUM(F18,F32,F46)) -> 45 | G4: =IFERROR(B4-F4,"") -> -45 | H4: =IFERROR(F4/B4,"") | J4: =IF(SUM(J18,J32,J46)=0,"",SUM(J18,J32,J46)) -> 18 | K4: =IFERROR(F4/E4,"") -> 2.0490497 | L4: =IFERROR(G4/K4,"") -> -21.9614 | M4: =IFERROR(L4/8,"") -> -2.745175
A5: Billtrain | B5: =C5*I5*8 -> 0 | E5: =IF(SUM(E19,E33,E47)=0,"",SUM(E19,E33,E47)) | F5: =IF(SUM(F19,F33,F47)=0,"",SUM(F19,F33,F47)) | G5: =IFERROR(B5-F5,"") | H5: =IFERROR(F5/B5,"") | J5: =IF(SUM(J19,J33,J47)=0,"",SUM(J19,J33,J47)) | K5: =IFERROR(F5/E5,"") | L5: =IFERROR(G5/K5,"") | M5: =IFERROR(L5/8,"")
A6: BTLOAD | B6: =C6*I6*8 -> 0 | E6: =IF(SUM(E20,E34,E48)=0,"",SUM(E20,E34,E48)) -> 31.4071 | F6: =IF(SUM(F20,F34,F48)=0,"",SUM(F20,F34,F48)) -> 354 | G6: =IFERROR(B6-F6,"") -> -354 | H6: =IFERROR(F6/B6,"") | J6: =IF(SUM(J20,J34,J48)=0,"",SUM(J20,J34,J48)) | K6: =IFERROR(F6/E6,"") -> 11.271337 | L6: =IFERROR(G6/K6,"") -> -31.4071 | M6: =IFERROR(L6/8,"") -> -3.9258875
A7: Medical Notes | B7: =C7*I7*8 -> 0 | E7: =IF(SUM(E21,E35,E49)=0,"",SUM(E21,E35,E49)) -> 5.48 | F7: =IF(SUM(F21,F35,F49)=0,"",SUM(F21,F35,F49)) -> 51 | G7: =IFERROR(B7-F7,"") -> -51 | H7: =IFERROR(F7/B7,"") | J7: =IF(SUM(J21,J35,J49)=0,"",SUM(J21,J35,J49)) | K7: =IFERROR(F7/E7,"") -> 9.3065693 | L7: =IFERROR(G7/K7,"") -> -5.48 | M7: =IFERROR(L7/8,"") -> -0.685
A8: Non-Billable | B8: =C8*I8*8 -> 0 | E8: =IF(SUM(E22,E36,E50)=0,"",SUM(E22,E36,E50)) -> 25.3828 | F8: =IF(SUM(F22,F36,F50)=0,"",SUM(F22,F36,F50)) | G8: =IFERROR(B8-F8,"") | H8: =IFERROR(F8/B8,"") | J8: =IF(SUM(J22,J36,J50)=0,"",SUM(J22,J36,J50)) | K8: =IFERROR(F8/E8,"") | L8: =IFERROR(G8/K8,"") | M8: =IFERROR(L8/8,"")
A9: Patient Calls | B9: =C9*I9*8 -> 0 | E9: =IF(SUM(E23,E37,E51)=0,"",SUM(E23,E37,E51)) -> 25.8127 | F9: =IF(SUM(F23,F37,F51)=0,"",SUM(F23,F37,F51)) -> 346 | G9: =IFERROR(B9-F9,"") -> -346 | H9: =IFERROR(F9/B9,"") | J9: =IF(SUM(J23,J37,J51)=0,"",SUM(J23,J37,J51)) | K9: =IFERROR(F9/E9,"") -> 13.404254 | L9: =IFERROR(G9/K9,"") -> -25.8127 | M9: =IFERROR(L9/8,"") -> -3.2265875
A10: Aging | B10: =C10*I10*8 -> 0 | E10: =IF(SUM(E24,E38,E52)=0,"",SUM(E24,E38,E52)) | F10: =IF(SUM(F24,F38,F52)=0,"",SUM(F24,F38,F52)) | G10: =IFERROR(B10-F10,"") | H10: =IFERROR(F10/B10,"") | J10: =IF(SUM(J24,J38,J52)=0,"",SUM(J24,J38,J52)) | K10: =IFERROR(F10/E10,"") | L10: =IFERROR(G10/K10,"") | M10: =IFERROR(L10/8,"")
A11: Rework | B11: =C11*I11*8 -> 0 | E11: =IF(SUM(E25,E39,E53)=0,"",SUM(E25,E39,E53)) -> 6.6064 | F11: =IF(SUM(F25,F39,F53)=0,"",SUM(F25,F39,F53)) -> 63 | G11: =IFERROR(B11-F11,"") -> -63 | H11: =IFERROR(F11/B11,"") | J11: =IF(SUM(J25,J39,J53)=0,"",SUM(J25,J39,J53)) | K11: =IFERROR(F11/E11,"") -> 9.5362073 | L11: =IFERROR(G11/K11,"") -> -6.6064 | M11: =IFERROR(L11/8,"") -> -0.8258
J12: =IF(SUM(J26,J40,J54)=0,"",SUM(J26,J40,J54)) | K12: =IFERROR(F12/E12,"")
A13: Total | B13: =C13*I13*8 -> #VALUE! | C13: =SUM(C3:C11) -> 0 | E13: =IF(SUM(E27,E41,E55)=0,"",SUM(E27,E41,E55)) -> 138.2768 | F13: =IF(SUM(F27,F41,F55)=0,"",SUM(F27,F41,F55)) -> 1218 | G13: =IFERROR(B13-F13,"") | H13: =IFERROR(F13/B13,"") | I13: =IFERROR(AVERAGE(I3:I11),"") | J13: =IF(SUM(J27,J41,J55)=0,"",SUM(J27,J41,J55)) -> 30 | K13: =IFERROR(AVERAGE(K27,K41,K55),"") -> 7.3202021 | L13: =IFERROR(G13/K13,"") | M13: =IFERROR(L13/8,"")
A15: BCD
A16: Campaign | B16: RECORDS ASSIGNED | C16: Headcount Assigned | D16: Hours Assigned | E16: Actual Log in hours | F16: RECORDS COMPLETED | G16: RECORDS REMAINING | H16: COMPLETION RATE | I16: RPH GOAL | J16: Sum of Points | K16: ACTUAL RPH | L16: HOURS NEEDED TO COMPLETE | M16: HC NEEDED TO COMPLETE | N16: SLA %
A17: Parachute | B17: =C17*I17*8 -> 0 | E17: =Pivot!B2 | F17: =Pivot!C2 | G17: =IFERROR(B17-F17,"") | H17: =IFERROR(F17/B17,"") | J17: =Pivot!D2 | K17: =IFERROR(F17/E17,"") | L17: =IFERROR(G17/K17,"") | M17: =IFERROR(L17/8,"")
A18: VSA | B18: =C18*I18*8 -> 0 | E18: =Pivot!B3 | F18: =Pivot!C3 | G18: =IFERROR(B18-F18,"") | H18: =IFERROR(F18/B18,"") | J18: =Pivot!D3 | K18: =IFERROR(F18/E18,"") | L18: =IFERROR(G18/K18,"") | M18: =IFERROR(L18/8,"")
A19: Billtrain | B19: =C19*I19*8 -> 0 | E19: =Pivot!B4 | F19: =Pivot!C4 | G19: =IFERROR(B19-F19,"") | H19: =IFERROR(F19/B19,"") | J19: =Pivot!D4 | K19: =IFERROR(F19/E19,"") | L19: =IFERROR(G19/K19,"") | M19: =IFERROR(L19/8,"")
A20: BTLOAD | B20: =C20*I20*8 -> 0 | E20: =Pivot!B5 | F20: =Pivot!C5 | G20: =IFERROR(B20-F20,"") | H20: =IFERROR(F20/B20,"") | J20: =Pivot!D5 | K20: =IFERROR(F20/E20,"") | L20: =IFERROR(G20/K20,"") | M20: =IFERROR(L20/8,"")
A21: Medical Notes | B21: =C21*I21*8 -> 0 | E21: =Pivot!B6 | F21: =Pivot!C6 | G21: =IFERROR(B21-F21,"") | H21: =IFERROR(F21/B21,"") | J21: =Pivot!D6 | K21: =IFERROR(F21/E21,"") | L21: =IFERROR(G21/K21,"") | M21: =IFERROR(L21/8,"")
A22: Non-Billable | B22: =C22*I22*8 -> 0 | E22: =Pivot!B7 | F22: =Pivot!C7 | G22: =IFERROR(B22-F22,"") | H22: =IFERROR(F22/B22,"") | J22: =Pivot!D7 | K22: =IFERROR(F22/E22,"") | L22: =IFERROR(G22/K22,"") | M22: =IFERROR(L22/8,"")
A23: Patient Calls | B23: =C23*I23*8 -> 0 | E23: =Pivot!B8 | F23: =Pivot!C8 | G23: =IFERROR(B23-F23,"") | H23: =IFERROR(F23/B23,"") | J23: =Pivot!D8 | K23: =IFERROR(F23/E23,"") | L23: =IFERROR(G23/K23,"") | M23: =IFERROR(L23/8,"")
A24: Aging | B24: =C24*I24*8 -> 0 | E24: =Pivot!B9 | F24: =Pivot!C9 | G24: =IFERROR(B24-F24,"") | H24: =IFERROR(F24/B24,"") | J24: =Pivot!D9 | K24: =IFERROR(F24/E24,"") | L24: =IFERROR(G24/K24,"") | M24: =IFERROR(L24/8,"")
A25: Rework | B25: =C25*I25*8 -> 0 | E25: =Pivot!B10 | F25: =Pivot!C10 | G25: =IFERROR(B25-F25,"") | H25: =IFERROR(F25/B25,"") | J25: =Pivot!D10 | K25: =IFERROR(F25/E25,"") | L25: =IFERROR(G25/K25,"") | M25: =IFERROR(L25/8,"")
E26: =Pivot!B11 | F26: =Pivot!C11 | J26: =Pivot!D11 | K26: =IFERROR(F26/E26,"")
A27: Total | B27: =C27*I27*8 -> #VALUE! | C27: =SUM(C17:C25) -> 0 | E27: =SUM(E17:E26) -> 0 | F27: =SUM(F17:F26) -> 0 | G27: =IFERROR(B27-F27,"") | H27: =IFERROR(F27/B27,"") | I27: =IFERROR(AVERAGE(I17:I25),"") | J27: =SUM(J17:J26) -> 0 | K27: =IFERROR(AVERAGE(K17:K26),"") | L27: =IFERROR(G27/K27,"") | M27: =IFERROR(L27/8,"")
A29: ILO
A30: Campaign | B30: RECORDS ASSIGNED | C30: Headcount | E30: Actual Log in hours | F30: RECORDS COMPLETED | G30: RECORDS REMAINING | H30: COMPLETION RATE | I30: RPH GOAL | J30: Sum of Points | K30: ACTUAL RPH | L30: HOURS NEEDED TO COMPLETE | M30: HC NEEDED TO COMPLETE | N30: SLA %
A31: Parachute | B31: =C31*I31*8 -> 0 | E31: =Pivot!H2 | F31: =Pivot!I2 | G31: =IFERROR(B31-F31,"") | H31: =IFERROR(F31/B31,"") | J31: =Pivot!J2 | K31: =IFERROR(F31/E31,"") | L31: =IFERROR(G31/F31,"") | M31: =IFERROR(H31/G31,"") | N31: =IFERROR(I31/H31,"")
A32: VSA | B32: =C32*I32*8 -> 0 | E32: =Pivot!H3 -> 21.9614 | F32: =Pivot!I3 -> 45 | G32: =IFERROR(B32-F32,"") -> -45 | H32: =IFERROR(F32/B32,"") | J32: =Pivot!J3 -> 18 | K32: =IFERROR(F32/E32,"") -> 2.0490497 | L32: =IFERROR(G32/K32,"") -> -21.9614 | M32: =IFERROR(L32/8,"") -> -2.745175
A33: Billtrain | B33: =C33*I33*8 -> 0 | E33: =Pivot!H4 | F33: =Pivot!I4 | G33: =IFERROR(B33-F33,"") | H33: =IFERROR(F33/B33,"") | J33: =Pivot!J4 | K33: =IFERROR(F33/E33,"") | L33: =IFERROR(G33/K33,"") | M33: =IFERROR(L33/8,"")
A34: BTLOAD | B34: =C34*I34*8 -> 0 | E34: =Pivot!H5 -> 16.7278 | F34: =Pivot!I5 -> 217 | G34: =IFERROR(B34-F34,"") -> -217 | H34: =IFERROR(F34/B34,"") | J34: =Pivot!J5 -> 0 | K34: =IFERROR(F34/E34,"") -> 12.972417 | L34: =IFERROR(G34/K34,"") -> -16.7278 | M34: =IFERROR(L34/8,"") -> -2.090975
A35: Medical Notes | B35: =C35*I35*8 -> 0 | E35: =Pivot!H6 | F35: =Pivot!I6 | G35: =IFERROR(B35-F35,"") | H35: =IFERROR(F35/B35,"") | J35: =Pivot!J6 | K35: =IFERROR(F35/E35,"") | L35: =IFERROR(G35/K35,"") | M35: =IFERROR(L35/8,"")
A36: Non-Billable | B36: =C36*I36*8 -> 0 | E36: =Pivot!H7 -> 22.7259 | F36: =Pivot!I7 -> 0 | G36: =IFERROR(B36-F36,"") -> 0 | H36: =IFERROR(F36/B36,"") | J36: =Pivot!J7 -> 0 | K36: =IFERROR(F36/E36,"") -> 0 | L36: =IFERROR(G36/K36,"") | M36: =IFERROR(L36/8,"")
A37: Patient Calls | B37: =C37*I37*8 -> 0 | E37: =Pivot!H8 -> 0.0011 | F37: =Pivot!I8 -> 0 | G37: =IFERROR(B37-F37,"") -> 0 | H37: =IFERROR(F37/B37,"") | J37: =Pivot!J8 -> 0 | K37: =IFERROR(F37/E37,"") -> 0 | L37: =IFERROR(G37/K37,"") | M37: =IFERROR(L37/8,"")
A38: Aging | B38: =C38*I38*8 -> 0 | E38: =Pivot!H9 | F38: =Pivot!I9 | G38: =IFERROR(B38-F38,"") | H38: =IFERROR(F38/B38,"") | J38: =Pivot!J9 | K38: =IFERROR(F38/E38,"") | L38: =IFERROR(G38/K38,"") | M38: =IFERROR(L38/8,"")
A39: Rework | B39: =C39*I39*8 -> 0 | E39: =Pivot!H10 -> 6.6064 | F39: =Pivot!I10 -> 63 | G39: =IFERROR(B39-F39,"") -> -63 | H39: =IFERROR(F39/B39,"") | J39: =Pivot!J10 -> 0 | K39: =IFERROR(F39/E39,"") -> 9.5362073 | L39: =IFERROR(G39/K39,"") -> -6.6064 | M39: =IFERROR(L39/8,"") -> -0.8258
E40: =Pivot!H11 | F40: =Pivot!I11 | J40: =Pivot!J11 | K40: =IFERROR(F40/E40,"")
A41: Total | B41: =C41*I41*8 -> #VALUE! | C41: =SUM(C31:C39) -> 0 | E41: =SUM(E31:E40) -> 68.0226 | F41: =SUM(F31:F40) -> 325 | G41: =IFERROR(B41-F41,"") | H41: =IFERROR(F41/B41,"") | I41: =IFERROR(AVERAGE(I31:I39),"") | J41: =SUM(J31:J40) -> 18 | K41: =IFERROR(AVERAGE(K31:K40),"") -> 4.9115348 | L41: =IFERROR(G41/K41,"") | M41: =IFERROR(L41/8,"")
A43: BTG
...

Sheet Sheet1
