Workbook

Sheet Pivot Table
A1: Record Count | B1: Days Grouping
A2: Campaign | B2: 3 or less | C2: #N/A | D2: Grand Total
A3: Portal Quipt All Calls | B3: 3 | C3: 1 | D3: 4
A4: Portal Quipt-Edocument | B4: 56 | C4: 11 | D4: 67
A5: Portal Quipt-Manual | C5: 29 | D5: 29
A6: Portal Quipt-PTCall | B6: 14 | C6: 1 | D6: 15
A7: Grand Total | B7: 73 | C7: 42 | D7: 115
F9: Campaign | G9: All
A11: Campaign | B11: Complete Count | F11: Touch Count | G11: Count of unqid
A12: Portal Quipt All Calls | B12: 3 | F12: 1 | G12: 67
A13: Portal Quipt-Edocument | B13: 53 | F13: 2 | G13: 3
A14: Portal Quipt-PTCall | B14: 14 | F14: Grand Total | G14: 70
A15: Grand Total | B15: 70

Sheet Quipt Prod Data
A1: CallID | B1: Campaign | C1: Direction | D1: From | E1: To | F1: AgentID | G1: AgentEmail | H1: StartTime | I1: Duration | J1: Result | K1: LeadID | L1: ExternalLeadID | M1: PubID | N1: SubID | O1: TalkTime | P1: WrapUpDuration | Q1: CompletedDate | R1: SubStatus | S1: Days Grouping
A2: 14744348 | B2: Portal Quipt All Calls | C2: Inbound | F2: hb43886 | G2: Agent0001@company.com | H2: 45917.448 | I2: 472 | J2: IB_Successful Inquiry | K2: 1056071180 | L2: QPT000928 | O2: 461 | P2: 60 | Q2: 45917.455 | R2: =IF(_xlfn.XLOOKUP(L2,'RAW DATA'!A:A,'RAW DATA'!B:B)=0,"",_xlfn.XLOOKUP(L2,'RAW DATA'!A:A,'RAW DATA'!B:B)) -> - | S2: =IF(_xlfn.XLOOKUP(L2,'RAW DATA'!A:A,'RAW DATA'!C:C)=0,"",_xlfn.XLOOKUP(L2,'RAW DATA'!A:A,'RAW DATA'!C:C)) -> 3 or less
A3: 15394230 | B3: Portal Quipt All Calls | C3: Inbound | F3: hb43886 | G3: Agent0001@company.com | H3: 45917.579 | I3: 365 | J3: IB_Successful Inquiry | K3: 1056129481 | O3: 353 | P3: 50 | Q3: 45917.584 | R3: =IF(_xlfn.XLOOKUP(L3,'RAW DATA'!A:A,'RAW DATA'!B:B)=0,"",_xlfn.XLOOKUP(L3,'RAW DATA'!A:A,'RAW DATA'!B:B)) -> #N/A | S3: =IF(_xlfn.XLOOKUP(L3,'RAW DATA'!A:A,'RAW DATA'!C:C)=0,"",_xlfn.XLOOKUP(L3,'RAW DATA'!A:A,'RAW DATA'!C:C)) -> #N/A
A4: 15489479 | B4: Portal Quipt All Calls | C4: Outbound | F4: hb43886 | G4: Agent0001@company.com | H4: 45917.597 | I4: 222 | J4: SPOKE with NURSE | K4: 1056148771 | L4: QPT000634 | O4: 222 | P4: 60 | R4: =IF(_xlfn.XLOOKUP(L4,'RAW DATA'!A:A,'RAW DATA'!B:B)=0,"",_xlfn.XLOOKUP(L4,'RAW DATA'!A:A,'RAW DATA'!B:B)) -> Wrong Doctor | S4: =IF(_xlfn.XLOOKUP(L4,'RAW DATA'!A:A,'RAW DATA'!C:C)=0,"",_xlfn.XLOOKUP(L4,'RAW DATA'!A:A,'RAW DATA'!C:C)) -> 3 or less
A5: 15524204 | B5: Portal Quipt All Calls | C5: Outbound | F5: hb43886 | G5: Agent0001@company.com | H5: 45917.604 | I5: 329 | J5: New Doctor | K5: 1056148778 | L5: QPT000758 | O5: 329 | P5: 60 | R5: =IF(_xlfn.XLOOKUP(L5,'RAW DATA'!A:A,'RAW DATA'!B:B)=0,"",_xlfn.XLOOKUP(L5,'RAW DATA'!A:A,'RAW DATA'!B:B)) -> - | S5: =IF(_xlfn.XLOOKUP(L5,'RAW DATA'!A:A,'RAW DATA'!C:C)=0,"",_xlfn.XLOOKUP(L5,'RAW DATA'!A:A,'RAW DATA'!C:C)) -> 3 or less
A6: 14690348 | B6: Portal Quipt-Edocument | C6: Outbound | F6: hb50855 | G6: Agent0002@company.com | H6: 45917.439 | I6: 18 | J6: VerfiedO2Requirement | K6: 1056068173 | L6: QPT001020 | O6: 18 | P6: 3 | R6: =IF(_xlfn.XLOOKUP(L6,'RAW DATA'!A:A,'RAW DATA'!B:B)=0,"",_xlfn.XLOOKUP(L6,'RAW DATA'!A:A,'RAW DATA'!B:B)) -> Medical Records Missing | S6: =IF(_xlfn.XLOOKUP(L6,'RAW DATA'!A:A,'RAW DATA'!C:C)=0,"",_xlfn.XLOOKUP(L6,'RAW DATA'!A:A,'RAW DATA'!C:C)) -> 3 or less
A7: 14692060 | B7: Portal Quipt-Edocument | C7: Outbound | F7: hb50855 | G7: Agent0002@company.com | H7: 45917.439 | I7: 26 | J7: VerfiedO2Requirement | K7: 1056068245 | L7: QPT000863 | O7: 26 | P7: 3 | R7: =IF(_xlfn.XLOOKUP(L7,'RAW DATA'!A:A,'RAW DATA'!B:B)=0,"",_xlfn.XLOOKUP(L7,'RAW DATA'!A:A,'RAW DATA'!B:B)) -> EDocument | S7: =IF(_xlfn.XLOOKUP(L7,'RAW DATA'!A:A,'RAW DATA'!C:C)=0,"",_xlfn.XLOOKUP(L7,'RAW DATA'!A:A,'RAW DATA'!C:C)) -> 3 or less
A8: 14694932 | B8: Portal Quipt-Edocument | C8: Outbound | F8: hb50855 | G8: Agent0002@company.com | H8: 45917.439 | I8: 0 | J8: Dialer - Busy | O8: 0 | R8: =IF(_xlfn.XLOOKUP(L8,'RAW DATA'!A:A,'RAW DATA'!B:B)=0,"",_xlfn.XLOOKUP(L8,'RAW DATA'!A:A,'RAW DATA'!B:B)) -> #N/A | S8: =IF(_xlfn.XLOOKUP(L8,'RAW DATA'!A:A,'RAW DATA'!C:C)=0,"",_xlfn.XLOOKUP(L8,'RAW DATA'!A:A,'RAW DATA'!C:C)) -> #N/A
A9: 14696465 | B9: Portal Quipt-Edocument | C9: Outbound | F9: hb50855 | G9: Agent0002@company.com | H9: 45917.44 | I9: 10 | J9: VerfiedO2Requirement | K9: 1056068340 | L9: QPT000789 | O9: 10 | P9: 4 | R9: =IF(_xlfn.XLOOKUP(L9,'RAW DATA'!A:A,'RAW DATA'!B:B)=0,"",_xlfn.XLOOKUP(L9,'RAW DATA'!A:A,'RAW DATA'!B:B)) -> - | S9: =IF(_xlfn.XLOOKUP(L9,'RAW DATA'!A:A,'RAW DATA'!C:C)=0,"",_xlfn.XLOOKUP(L9,'RAW DATA'!A:A,'RAW DATA'!C:C)) -> 3 or less
A10: 14698177 | B10: Portal Quipt-Edocument | C10: Outbound | F10: hb50855 | G10: Agent0002@company.com | H10: 45917.44 | I10: 14 | J10: VerfiedO2Requirement | K10: 1056068414 | L10: QPT000788 | O10: 14 | P10: 3 | R10: =IF(_xlfn.XLOOKUP(L10,'RAW DATA'!A:A,'RAW DATA'!B:B)=0,"",_xlfn.XLOOKUP(L10,'RAW DATA'!A:A,'RAW DATA'!B:B)) -> Medical Records Need Review | S10: =IF(_xlfn.XLOOKUP(L10,'RAW DATA'!A:A,'RAW DATA'!C:C)=0,"",_xlfn.XLOOKUP(L10,'RAW DATA'!A:A,'RAW DATA'!C:C)) -> 3 or less
A11: 14699815 | B11: Portal Quipt-Edocument | C11: Outbound | F11: hb50855 | G11: Agent0002@company.com | H11: 45917.44 | I11: 18 | J11: VerfiedO2Requirement | K11: 1056068483 | L11: QPT000787 | O11: 18 | P11: 3 | R11: =IF(_xlfn.XLOOKUP(L11,'RAW DATA'!A:A,'RAW DATA'!B:B)=0,"",_xlfn.XLOOKUP(L11,'RAW DATA'!A:A,'RAW DATA'!B:B)) -> - | S11: =IF(_xlfn.XLOOKUP(L11,'RAW DATA'!A:A,'RAW DATA'!C:C)=0,"",_xlfn.XLOOKUP(L11,'RAW DATA'!A:A,'RAW DATA'!C:C)) -> 3 or less
A12: 14701957 | B12: Portal Quipt-Edocument | C12: Outbound | F12: hb50855 | G12: Agent0002@company.com | H12: 45917.441 | I12: 22 | J12: VerfiedO2Requirement | K12: 1056068570 | L12: QPT000786 | O12: 22 | P12: 3 | R12: =IF(_xlfn.XLOOKUP(L12,'RAW DATA'!A:A,'RAW DATA'!B:B)=0,"",_xlfn.XLOOKUP(L12,'RAW DATA'!A:A,'RAW DATA'!B:B)) -> EDocument | S12: =IF(_xlfn.XLOOKUP(L12,'RAW DATA'!A:A,'RAW DATA'!C:C)=0,"",_xlfn.XLOOKUP(L12,'RAW DATA'!A:A,'RAW DATA'!C:C)) -> 3 or less
A13: 14704269 | B13: Portal Quipt-Edocument | C13: Outbound | F13: hb50855 | G13: Agent0002@company.com | H13: 45917.441 | I13: 21 | J13: VerfiedO2Requirement | K13: 1056068666 | L13: QPT000785 | O13: 21 | P13: 3 | R13: =IF(_xlfn.XLOOKUP(L13,'RAW DATA'!A:A,'RAW DATA'!B:B)=0,"",_xlfn.XLOOKUP(L13,'RAW DATA'!A:A,'RAW DATA'!B:B)) -> EDocument | S13: =IF(_xlfn.XLOOKUP(L13,'RAW DATA'!A:A,'RAW DATA'!C:C)=0,"",_xlfn.XLOOKUP(L13,'RAW DATA'!A:A,'RAW DATA'!C:C)) -> 3 or less
A14: 14707064 | B14: Portal Quipt-Edocument | C14: Outbound | F14: hb50855 | G14: Agent0002@company.com | H14: 45917.442 | I14: 16 | J14: VerfiedO2Requirement | K14: 1056068745 | L14: QPT000784 | O14: 16 | P14: 3 | R14: =IF(_xlfn.XLOOKUP(L14,'RAW DATA'!A:A,'RAW DATA'!B:B)=0,"",_xlfn.XLOOKUP(L14,'RAW DATA'!A:A,'RAW DATA'!B:B)) -> EDocument | S14: =IF(_xlfn.XLOOKUP(L14,'RAW DATA'!A:A,'RAW DATA'!C:C)=0,"",_xlfn.XLOOKUP(L14,'RAW DATA'!A:A,'RAW DATA'!C:C)) -> 3 or less
A15: 14708987 | B15: Portal Quipt-Edocument | C15: Outbound | F15: hb50855 | G15: Agent0002@company.com | H15: 45917.442 | I15: 60 | J15: Dialer - No Answer | O15: 60 | R15: =IF(_xlfn.XLOOKUP(L15,'RAW DATA'!A:A,'RAW DATA'!B:B)=0,"",_xlfn.XLOOKUP(L15,'RAW DATA'!A:A,'RAW DATA'!B:B)) -> #N/A | S15: =IF(_xlfn.XLOOKUP(L15,'RAW DATA'!A:A,'RAW DATA'!C:C)=0,"",_xlfn.XLOOKUP(L15,'RAW DATA'!A:A,'RAW DATA'!C:C)) -> #N/A
A16: 14713293 | B16: Portal Quipt-Edocument | C16: Outbound | F16: hb50855 | G16: Agent0002@company.com | H16: 45917.443 | I16: 36 | J16: VerfiedO2Requirement | K16: 1056068961 | L16: QPT000782 | O16: 36 | P16: 4 | R16: =IF(_xlfn.XLOOKUP(L16,'RAW DATA'!A:A,'RAW DATA'!B:B)=0,"",_xlfn.XLOOKUP(L16,'RAW DATA'!A:A,'RAW DATA'!B:B)) -> - | S16: =IF(_xlfn.XLOOKUP(L16,'RAW DATA'!A:A,'RAW DATA'!C:C)=0,"",_xlfn.XLOOKUP(L16,'RAW DATA'!A:A,'RAW DATA'!C:C)) -> 3 or less
A17: 14716248 | B17: Portal Quipt-Edocument | C17: Outbound | F17: hb50855 | G17: Agent0002@company.com | H17: 45917.443 | I17: 60 | J17: Dialer - No Answer | O17: 60 | R17: =IF(_xlfn.XLOOKUP(L17,'RAW DATA'!A:A,'RAW DATA'!B:B)=0,"",_xlfn.XLOOKUP(L17,'RAW DATA'!A:A,'RAW DATA'!B:B)) -> #N/A | S17: =IF(_xlfn.XLOOKUP(L17,'RAW DATA'!A:A,'RAW DATA'!C:C)=0,"",_xlfn.XLOOKUP(L17,'RAW DATA'!A:A,'RAW DATA'!C:C)) -> #N/A
A18: 14721432 | B18: Portal Quipt-Edocument | C18: Outbound | F18: hb50855 | G18: Agent0002@company.com | H18: 45917.444 | I18: 21 | J18: VerfiedO2Requirement | K18: 1056069221 | L18: QPT000780 | O18: 21 | P18: 6 | R18: =IF(_xlfn.XLOOKUP(L18,'RAW DATA'!A:A,'RAW DATA'!B:B)=0,"",_xlfn.XLOOKUP(L18,'RAW DATA'!A:A,'RAW DATA'!B:B)) -> - | S18: =IF(_xlfn.XLOOKUP(L18,'RAW DATA'!A:A,'RAW DATA'!C:C)=0,"",_xlfn.XLOOKUP(L18,'RAW DATA'!A:A,'RAW DATA'!C:C)) -> 3 or less
A19: 14723951 | B19: Portal Quipt-Edocument | C19: Outbound | F19: hb50855 | G19: Agent0002@company.com | H19: 45917.445 | I19: 13 | J19: VerfiedO2Requirement | K19: 1056069339 | L19: QPT000779 | O19: 13 | R19: =IF(_xlfn.XLOOKUP(L19,'RAW DATA'!A:A,'RAW DATA'!B:B)=0,"",_xlfn.XLOOKUP(L19,'RAW DATA'!A:A,'RAW DATA'!B:B)) -> - | S19: =IF(_xlfn.XLOOKUP(L19,'RAW DATA'!A:A,'RAW DATA'!C:C)=0,"",_xlfn.XLOOKUP(L19,'RAW DATA'!A:A,'RAW DATA'!C:C)) -> 3 or less
A20: 14726576 | B20: Portal Quipt-Edocument | C20: Outbound | F20: hb50855 | G20: Agent0002@company.com | H20: 45917.445 | I20: 20 | J20: VerfiedO2Requirement | K20: 1056069417 | L20: QPT000778 | O20: 20 | P20: 3 | R20: =IF(_xlfn.XLOOKUP(L20,'RAW DATA'!A:A,'RAW DATA'!B:B)=0,"",_xlfn.XLOOKUP(L20,'RAW DATA'!A:A,'RAW DATA'!B:B)) -> - | S20: =IF(_xlfn.XLOOKUP(L20,'RAW DATA'!A:A,'RAW DATA'!C:C)=0,"",_xlfn.XLOOKUP(L20,'RAW DATA'!A:A,'RAW DATA'!C:C)) -> 3 or less
A21: 14728620 | B21: Portal Quipt-Edocument | C21: Outbound | F21: hb50855 | G21: Agent0002@company.com | H21: 45917.446 | I21: 12 | J21: VerfiedO2Requirement | K21: 1056069475 | L21: QPT000777 | O21: 12 | P21: 3 | R21: =IF(_xlfn.XLOOKUP(L21,'RAW DATA'!A:A,'RAW DATA'!B:B)=0,"",_xlfn.XLOOKUP(L21,'RAW DATA'!A:A,'RAW DATA'!B:B)) -> EDocument | S21: =IF(_xlfn.XLOOKUP(L21,'RAW DATA'!A:A,'RAW DATA'!C:C)=0,"",_xlfn.XLOOKUP(L21,'RAW DATA'!A:A,'RAW DATA'!C:C)) -> 3 or less
A22: 14730542 | B22: Portal Quipt-Edocument | C22: Outbound | F22: hb50855 | G22: Agent0002@company.com | H22: 45917.446 | I22: 33 | J22: VerfiedO2Requirement | K22: 1056069606 | L22: QPT000776 | O22: 33 | P22: 4 | R22: =IF(_xlfn.XLOOKUP(L22,'RAW DATA'!A:A,'RAW DATA'!B:B)=0,"",_xlfn.XLOOKUP(L22,'RAW DATA'!A:A,'RAW DATA'!B:B)) -> - | S22: =IF(_xlfn.XLOOKUP(L22,'RAW DATA'!A:A,'RAW DATA'!C:C)=0,"",_xlfn.XLOOKUP(L22,'RAW DATA'!A:A,'RAW DATA'!C:C)) -> 3 or less
A23: 14733721 | B23: Portal Quipt-Edocument | C23: Outbound | F23: hb50855 | G23: Agent0002@company.com | H23: 45917.447 | I23: 60 | J23: Dialer - No Answer | O23: 60 | R23: =IF(_xlfn.XLOOKUP(L23,'RAW DATA'!A:A,'RAW DATA'!B:B)=0,"",_xlfn.XLOOKUP(L23,'RAW DATA'!A:A,'RAW DATA'!B:B)) -> #N/A | S23: =IF(_xlfn.XLOOKUP(L23,'RAW DATA'!A:A,'RAW DATA'!C:C)=0,"",_xlfn.XLOOKUP(L23,'RAW DATA'!A:A,'RAW DATA'!C:C)) -> #N/A
A24: 14738324 | B24: Portal Quipt-Edocument | C24: Outbound | F24: hb50855 | G24: Agent0002@company.com | H24: 45917.447 | I24: 51 | J24: VerfiedO2Requirement | K24: 1056069834 | L24: QPT000774 | O24: 51 | P24: 3 | R24: =IF(_xlfn.XLOOKUP(L24,'RAW DATA'!A:A,'RAW DATA'!B:B)=0,"",_xlfn.XLOOKUP(L24,'RAW DATA'!A:A,'RAW DATA'!B:B)) -> - | S24: =IF(_xlfn.XLOOKUP(L24,'RAW DATA'!A:A,'RAW DATA'!C:C)=0,"",_xlfn.XLOOKUP(L24,'RAW DATA'!A:A,'RAW DATA'!C:C)) -> 3 or less
A25: 14742754 | B25: Portal Quipt-Edocument | C25: Outbound | F25: hb50855 | G25: Agent0002@company.com | H25: 45917.448 | I25: 11 | J25: VerfiedO2Requirement | K25: 1056069964 | L25: QPTeving data. Wait a few seconds and try to cut or copy again | O25: 11 | P25: 4 | R25: =IF(_xlfn.XLOOKUP(L25,'RAW DATA'!A:A,'RAW DATA'!B:B)=0,"",_xlfn.XLOOKUP(L25,'RAW DATA'!A:A,'RAW DATA'!B:B)) -> #N/A | S25: =IF(_xlfn.XLOOKUP(L25,'RAW DATA'!A:A,'RAW DATA'!C:C)=0,"",_xlfn.XLOOKUP(L25,'RAW DATA'!A:A,'RAW DATA'!C:C)) -> #N/A
A26: 14744589 | B26: Portal Quipt-Edocument | C26: Outbound | F26: hb50855 | G26: Agent0002@company.com | H26: 45917.448 | I26: 15 | J26: VerfiedO2Requirement | K26: 1056070029 | L26: QPT000772 | O26: 15 | P26: 4 | R26: =IF(_xlfn.XLOOKUP(L26,'RAW DATA'!A:A,'RAW DATA'!B:B)=0,"",_xlfn.XLOOKUP(L26,'RAW DATA'!A:A,'RAW DATA'!B:B)) -> EDocument | S26: =IF(_xlfn.XLOOKUP(L26,'RAW DATA'!A:A,'RAW DATA'!C:C)=0,"",_xlfn.XLOOKUP(L26,'RAW DATA'!A:A,'RAW DATA'!C:C)) -> 3 or less
A27: 14748333 | B27: Portal Quipt-Edocument | C27: Outbound | F27: hb50855 | G27: Agent0002@company.com | H27: 45917.449 | I27: 75 | J27: VerfiedO2Requirement | K27: 1056070289 | L27: QPT000771 | O27: 75 | P27: 3 | R27: =IF(_xlfn.XLOOKUP(L27,'RAW DATA'!A:A,'RAW DATA'!B:B)=0,"",_xlfn.XLOOKUP(L27,'RAW DATA'!A:A,'RAW DATA'!B:B)) -> - | S27: =IF(_xlfn.XLOOKUP(L27,'RAW DATA'!A:A,'RAW DATA'!C:C)=0,"",_xlfn.XLOOKUP(L27,'RAW DATA'!A:A,'RAW DATA'!C:C)) -> 3 or less
A28: 14755307 | B28: Portal Quipt-Edocument | C28: Outbound | F28: hb50855 | G28: Agent0002@company.com | H28: 45917.45 | I28: 72 | J28: VerfiedO2Requirement | K28: 1056070394 | L28: QPT000770 | O28: 72 | P28: 4 | R28: =IF(_xlfn.XLOOKUP(L28,'RAW DATA'!A:A,'RAW DATA'!B:B)=0,"",_xlfn.XLOOKUP(L28,'RAW DATA'!A:A,'RAW DATA'!B:B)) -> - | S28: =IF(_xlfn.XLOOKUP(L28,'RAW DATA'!A:A,'RAW DATA'!C:C)=0,"",_xlfn.XLOOKUP(L28,'RAW DATA'!A:A,'RAW DATA'!C:C)) -> 3 or less
A29: 14761923 | B29: Portal Quipt-Edocument | C29: Outbound | F29: hb50855 | G29: Agent0002@company.com | H29: 45917.451 | I29: 83 | J29: VerfiedO2Requirement | O29: 83 | P29: 3 | R29: =IF(_xlfn.XLOOKUP(L29,'RAW DATA'!A:A,'RAW DATA'!B:B)=0,"",_xlfn.XLOOKUP(L29,'RAW DATA'!A:A,'RAW DATA'!B:B)) -> #N/A | S29: =IF(_xlfn.XLOOKUP(L29,'RAW DATA'!A:A,'RAW DATA'!C:C)=0,"",_xlfn.XLOOKUP(L29,'RAW DATA'!A:A,'RAW DATA'!C:C)) -> #N/A
A30: 14768766 | B30: Portal Quipt-Edocument | C30: Outbound | F30: hb50855 | G30: Agent0002@company.com | H30: 45917.453 | I30: 40 | J30: VerfiedO2Requirement | K30: 1056070848 | L30: QPT000768 | O30: 40 | P30: 3 | R30: =IF(_xlfn.XLOOKUP(L30,'RAW DATA'!A:A,'RAW DATA'!B:B)=0,"",_xlfn.XLOOKUP(L30,'RAW DATA'!A:A,'RAW DATA'!B:B)) -> - | S30: =IF(_xlfn.XLOOKUP(L30,'RAW DATA'!A:A,'RAW DATA'!C:C)=0,"",_xlfn.XLOOKUP(L30,'RAW DATA'!A:A,'RAW DATA'!C:C)) -> 3 or less
A31: 14772858 | B31: Portal Quipt-Edocument | C31: Outbound | F31: hb50855 | G31: Agent0002@company.com | H31: 45917.453 | I31: 17 | J31: VerfiedO2Requirement | K31: 1056071001 | L31: QPT000767 | O31: 17 | P31: 4 | R31: =IF(_xlfn.XLOOKUP(L31,'RAW DATA'!A:A,'RAW DATA'!B:B)=0,"",_xlfn.XLOOKUP(L31,'RAW DATA'!A:A,'RAW DATA'!B:B)) -> - | S31: =IF(_xlfn.XLOOKUP(L31,'RAW DATA'!A:A,'RAW DATA'!C:C)=0,"",_xlfn.XLOOKUP(L31,'RAW DATA'!A:A,'RAW DATA'!C:C)) -> 3 or less
A32: 14775100 | B32: Portal Quipt-Edocument | C32: Outbound | F32: hb50855 | G32: Agent0002@company.com | H32: 45917.454 | I32: 81 | J32: VerfiedO2Requirement | K32: 1056071089 | L32: QPTeving data. Wait a few seconds and try to cut or copy again | O32: 81 | P32: 29 | R32: =IF(_xlfn.XLOOKUP(L32,'RAW DATA'!A:A,'RAW DATA'!B:B)=0,"",_xlfn.XLOOKUP(L32,'RAW DATA'!A:A,'RAW DATA'!B:B)) -> #N/A | S32: =IF(_xlfn.XLOOKUP(L32,'RAW DATA'!A:A,'RAW DATA'!C:C)=0,"",_xlfn.XLOOKUP(L32,'RAW DATA'!A:A,'RAW DATA'!C:C)) -> #N/A
A33: 14782009 | B33: Portal Quipt-Edocument | C33: Outbound | F33: hb50855 | G33: Agent0002@company.com | H33: 45917.455 | I33: 22 | J33: VerfiedO2Requirement | K33: 1056071348 | L33: QPT000765 | O33: 22 | P33: 2 | R33: =IF(_xlfn.XLOOKUP(L33,'RAW DATA'!A:A,'RAW DATA'!B:B)=0,"",_xlfn.XLOOKUP(L33,'RAW DATA'!A:A,'RAW DATA'!B:B)) -> EDocument | S33: =IF(_xlfn.XLOOKUP(L33,'RAW DATA'!A:A,'RAW DATA'!C:C)=0,"",_xlfn.XLOOKUP(L33,'RAW DATA'!A:A,'RAW DATA'!C:C)) -> 3 or less
A34: 14785470 | B34: Portal Quipt-Edocument | C34: Outbound | F34: hb50855 | G34: Agent0002@company.com | H34: 45917.456 | I34: 14 | J34: VerfiedO2Requirement | K34: 1056071431 | L34: QPTeving data. Wait a few seconds and try to cut or copy again | O34: 13 | P34: 4 | R34: =IF(_xlfn.XLOOKUP(L34,'RAW DATA'!A:A,'RAW DATA'!B:B)=0,"",_xlfn.XLOOKUP(L34,'RAW DATA'!A:A,'RAW DATA'!B:B)) -> #N/A | S34: =IF(_xlfn.XLOOKUP(L34,'RAW DATA'!A:A,'RAW DATA'!C:C)=0,"",_xlfn.XLOOKUP(L34,'RAW DATA'!A:A,'RAW DATA'!C:C)) -> #N/A
A35: 14787451 | B35: Portal Quipt-Edocument | C35: Outbound | F35: hb50855 | G35: Agent0002@company.com | H35: 45917.456 | I35: 13 | J35: VerfiedO2Requirement | K35: 1056071495 | L35: QPT000762 | O35: 13 | P35: 3 | R35: =IF(_xlfn.XLOOKUP(L35,'RAW DATA'!A:A,'RAW DATA'!B:B)=0,"",_xlfn.XLOOKUP(L35,'RAW DATA'!A:A,'RAW DATA'!B:B)) -> EDocument | S35: =IF(_xlfn.XLOOKUP(L35,'RAW DATA'!A:A,'RAW DATA'!C:C)=0,"",_xlfn.XLOOKUP(L35,'RAW DATA'!A:A,'RAW DATA'!C:C)) -> 3 or less
A36: 14789671 | B36: Portal Quipt-Edocument | C36: Outbound | F36: hb50855 | G36: Agent0002@company.com | H36: 45917.456 | I36: 56 | J36: VerfiedO2Requirement | K36: 1056071570 | L36: QPT000761 | O36: 56 | P36: 3 | R36: =IF(_xlfn.XLOOKUP(L36,'RAW DATA'!A:A,'RAW DATA'!B:B)=0,"",_xlfn.XLOOKUP(L36,'RAW DATA'!A:A,'RAW DATA'!B:B)) -> - | S36: =IF(_xlfn.XLOOKUP(L36,'RAW DATA'!A:A,'RAW DATA'!C:C)=0,"",_xlfn.XLOOKUP(L36,'RAW DATA'!A:A,'RAW DATA'!C:C)) -> 3 or less
A37: 14794273 | B37: Portal Quipt-Edocument | C37: Outbound | F37: hb50855 | G37: Agent0002@company.com | H37: 45917.457 | I37: 60 | J37: Dialer - No Answer | K37: 1056071752 | L37: QPTeving data. Wait a few seconds and try to cut or copy again | O37: 60 | R37: =IF(_xlfn.XLOOKUP(L37,'RAW DATA'!A:A,'RAW DATA'!B:B)=0,"",_xlfn.XLOOKUP(L37,'RAW DATA'!A:A,'RAW DATA'!B:B)) -> #N/A | S37: =IF(_xlfn.XLOOKUP(L37,'RAW DATA'!A:A,'RAW DATA'!C:C)=0,"",_xlfn.XLOOKUP(L37,'RAW DATA'!A:A,'RAW DATA'!C:C)) -> #N/A
A38: 14814911 | B38: Portal Quipt-Edocument | C38: Outbound | F38: hb50855 | G38: Agent0002@company.com | H38: 45917.461 | I38: 15 | J38: VerfiedO2Requirement | K38: 1056072471 | L38: QPT000759 | O38: 15 | P38: 2 | R38: =IF(_xlfn.XLOOKUP(L38,'RAW DATA'!A:A,'RAW DATA'!B:B)=0,"",_xlfn.XLOOKUP(L38,'RAW DATA'!A:A,'RAW DATA'!B:B)) -> - | S38: =IF(_xlfn.XLOOKUP(L38,'RAW DATA'!A:A,'RAW DATA'!C:C)=0,"",_xlfn.XLOOKUP(L38,'RAW DATA'!A:A,'RAW DATA'!C:C)) -> 3 or less
A39: 14816112 | B39: Portal Quipt-Edocument | C39: Outbound | F39: hb50855 | G39: Agent0002@company.com | H39: 45917.461 | I39: 12 | J39: VerfiedO2Requirement | K39: 1056072520 | L39: QPT000758 | O39: 12 | P39: 4 | R39: =IF(_xlfn.XLOOKUP(L39,'RAW DATA'!A:A,'RAW DATA'!B:B)=0,"",_xlfn.XLOOKUP(L39,'RAW DATA'!A:A,'RAW DATA'!B:B)) -> - | S39: =IF(_xlfn.XLOOKUP(L39,'RAW DATA'!A:A,'RAW DATA'!C:C)=0,"",_xlfn.XLOOKUP(L39,'RAW DATA'!A:A,'RAW DATA'!C:C)) -> 3 or less
A40: 14817269 | B40: Portal Quipt-Edocument | C40: Outbound | F40: hb50855 | G40: Agent0002@company.com | H40: 45917.462 | I40: 12 | J40: VerfiedO2Requirement | K40: 1056072565 | L40: QPT000757 | O40: 12 | P40: 3 | R40: =IF(_xlfn.XLOOKUP(L40,'RAW DATA'!A:A,'RAW DATA'!B:B)=0,"",_xlfn.XLOOKUP(L40,'RAW DATA'!A:A,'RAW DATA'!B:B)) -> EDocument | S40: =IF(_xlfn.XLOOKUP(L40,'RAW DATA'!A:A,'RAW DATA'!C:C)=0,"",_xlfn.XLOOKUP(L40,'RAW DATA'!A:A,'RAW DATA'!C:C)) -> 3 or less
...

Sheet RAW DATA
A1: unqid | B1: SubStatus | C1: Days Grouping | D1: Campaign | E1: Row Number | F1: Touch Count
A2: QPT001108 | B2: - | C2: 3 or less | D2: =_xlfn.IFNA(_xlfn.XLOOKUP(Data[[#This Row],[unqid]],'Quipt Prod Data'!L:L,'Quipt Prod Data'!B:B),"") | E2: =_xlfn.IFNA(_xlfn.XMATCH(Data[[#This Row],[unqid]],'Quipt Prod Data'!L:L,0),"") | F2: =IF(COUNTIF('Quipt Prod Data'!L:L,Data[[#This Row],[unqid]])=0,"",COUNTIF('Quipt Prod Data'!L:L,Data[[#This Row],[unqid]]))
A3: QPT001107 | B3: - | C3: 3 or less | D3: =_xlfn.IFNA(_xlfn.XLOOKUP(Data[[#This Row],[unqid]],'Quipt Prod Data'!L:L,'Quipt Prod Data'!B:B),"") | E3: =_xlfn.IFNA(_xlfn.XMATCH(Data[[#This Row],[unqid]],'Quipt Prod Data'!L:L,0),"") | F3: =IF(COUNTIF('Quipt Prod Data'!L:L,Data[[#This Row],[unqid]])=0,"",COUNTIF('Quipt Prod Data'!L:L,Data[[#This Row],[unqid]]))
A4: QPT001106 | B4: Medical Records Missing | C4: 3 or less | D4: =_xlfn.IFNA(_xlfn.XLOOKUP(Data[[#This Row],[unqid]],'Quipt Prod Data'!L:L,'Quipt Prod Data'!B:B),"") | E4: =_xlfn.IFNA(_xlfn.XMATCH(Data[[#This Row],[unqid]],'Quipt Prod Data'!L:L,0),"") | F4: =IF(COUNTIF('Quipt Prod Data'!L:L,Data[[#This Row],[unqid]])=0,"",COUNTIF('Quipt Prod Data'!L:L,Data[[#This Row],[unqid]]))
A5: QPT001105 | B5: Medical Records Missing | C5: 3 or less | D5: =_xlfn.IFNA(_xlfn.XLOOKUP(Data[[#This Row],[unqid]],'Quipt Prod Data'!L:L,'Quipt Prod Data'!B:B),"") | E5: =_xlfn.IFNA(_xlfn.XMATCH(Data[[#This Row],[unqid]],'Quipt Prod Data'!L:L,0),"") | F5: =IF(COUNTIF('Quipt Prod Data'!L:L,Data[[#This Row],[unqid]])=0,"",COUNTIF('Quipt Prod Data'!L:L,Data[[#This Row],[unqid]]))
A6: QPT001104 | B6: - | C6: 3 or less | D6: =_xlfn.IFNA(_xlfn.XLOOKUP(Data[[#This Row],[unqid]],'Quipt Prod Data'!L:L,'Quipt Prod Data'!B:B),"") | E6: =_xlfn.IFNA(_xlfn.XMATCH(Data[[#This Row],[unqid]],'Quipt Prod Data'!L:L,0),"") | F6: =IF(COUNTIF('Quipt Prod Data'!L:L,Data[[#This Row],[unqid]])=0,"",COUNTIF('Quipt Prod Data'!L:L,Data[[#This Row],[unqid]]))
A7: QPT001103 | B7: Medical Records Need Review | C7: 3 or less | D7: =_xlfn.IFNA(_xlfn.XLOOKUP(Data[[#This Row],[unqid]],'Quipt Prod Data'!L:L,'Quipt Prod Data'!B:B),"") | E7: =_xlfn.IFNA(_xlfn.XMATCH(Data[[#This Row],[unqid]],'Quipt Prod Data'!L:L,0),"") | F7: =IF(COUNTIF('Quipt Prod Data'!L:L,Data[[#This Row],[unqid]])=0,"",COUNTIF('Quipt Prod Data'!L:L,Data[[#This Row],[unqid]]))
A8: QPT001102 | B8: Bad Fax Number | C8: 3 or less | D8: =_xlfn.IFNA(_xlfn.XLOOKUP(Data[[#This Row],[unqid]],'Quipt Prod Data'!L:L,'Quipt Prod Data'!B:B),"") | E8: =_xlfn.IFNA(_xlfn.XMATCH(Data[[#This Row],[unqid]],'Quipt Prod Data'!L:L,0),"") | F8: =IF(COUNTIF('Quipt Prod Data'!L:L,Data[[#This Row],[unqid]])=0,"",COUNTIF('Quipt Prod Data'!L:L,Data[[#This Row],[unqid]]))
A9: QPT001101 | B9: - | C9: 3 or less | D9: =_xlfn.IFNA(_xlfn.XLOOKUP(Data[[#This Row],[unqid]],'Quipt Prod Data'!L:L,'Quipt Prod Data'!B:B),"") | E9: =_xlfn.IFNA(_xlfn.XMATCH(Data[[#This Row],[unqid]],'Quipt Prod Data'!L:L,0),"") | F9: =IF(COUNTIF('Quipt Prod Data'!L:L,Data[[#This Row],[unqid]])=0,"",COUNTIF('Quipt Prod Data'!L:L,Data[[#This Row],[unqid]]))
A10: QPT001100 | B10: Not a Patient at this Location | C10: 3 or less | D10: =_xlfn.IFNA(_xlfn.XLOOKUP(Data[[#This Row],[unqid]],'Quipt Prod Data'!L:L,'Quipt Prod Data'!B:B),"") -> Portal Quipt-PTCall | E10: =_xlfn.IFNA(_xlfn.XMATCH(Data[[#This Row],[unqid]],'Quipt Prod Data'!L:L,0),"") -> 105 | F10: =IF(COUNTIF('Quipt Prod Data'!L:L,Data[[#This Row],[unqid]])=0,"",COUNTIF('Quipt Prod Data'!L:L,Data[[#This Row],[unqid]])) -> 1
A11: QPT001099 | B11: Bad Fax Number | C11: 3 or less | D11: =_xlfn.IFNA(_xlfn.XLOOKUP(Data[[#This Row],[unqid]],'Quipt Prod Data'!L:L,'Quipt Prod Data'!B:B),"") | E11: =_xlfn.IFNA(_xlfn.XMATCH(Data[[#This Row],[unqid]],'Quipt Prod Data'!L:L,0),"") | F11: =IF(COUNTIF('Quipt Prod Data'!L:L,Data[[#This Row],[unqid]])=0,"",COUNTIF('Quipt Prod Data'!L:L,Data[[#This Row],[unqid]]))
A12: QPT001098 | B12: - | C12: 3 or less | D12: =_xlfn.IFNA(_xlfn.XLOOKUP(Data[[#This Row],[unqid]],'Quipt Prod Data'!L:L,'Quipt Prod Data'!B:B),"") | E12: =_xlfn.IFNA(_xlfn.XMATCH(Data[[#This Row],[unqid]],'Quipt Prod Data'!L:L,0),"") | F12: =IF(COUNTIF('Quipt Prod Data'!L:L,Data[[#This Row],[unqid]])=0,"",COUNTIF('Quipt Prod Data'!L:L,Data[[#This Row],[unqid]]))
A13: QPT001097 | B13: - | C13: 3 or less | D13: =_xlfn.IFNA(_xlfn.XLOOKUP(Data[[#This Row],[unqid]],'Quipt Prod Data'!L:L,'Quipt Prod Data'!B:B),"") | E13: =_xlfn.IFNA(_xlfn.XMATCH(Data[[#This Row],[unqid]],'Quipt Prod Data'!L:L,0),"") | F13: =IF(COUNTIF('Quipt Prod Data'!L:L,Data[[#This Row],[unqid]])=0,"",COUNTIF('Quipt Prod Data'!L:L,Data[[#This Row],[unqid]]))
... A1109: QPT000001 | B1109: Client Removal Request | C1109: 91 to 120 | D1109: =_xlfn.IFNA(_xlfn.XLOOKUP(Data[[#This Row],[unqid]],'Quipt Prod Data'!L:L,'Quipt Prod Data'!B:B),"") | E1109: =_xlfn.IFNA(_xlfn.XMATCH(Data[[#This Row],[unqid]],'Quipt Prod Data'!L:L,0),"") | F1109: =IF(COUNTIF('Quipt Prod Data'!L:L,Data[[#This Row],[unqid]])=0,"",COUNTIF('Quipt Prod Data'!L:L,Data[[#This Row],[unqid]]))
